Workbook

Sheet Sheet2
A1: THÔNG TIN KHO | B1: ID ST TƯƠNG ỨNG | C1: CHAT ID | D1: Tên Siêu thị
A2: KRC | B2: A101 | C2: -4776256360 | D2: KFM_BDU_DAN - 27 Tân Lập
A3: KRC | B3: A102 | C3: -4810931245 | D3: KFM_HCM_TDU - 128A Kha Vạn Cân
A4: KRC | B4: A103 | C4: -4976500983 | D4: KFM_HCM_NBE - 222 Lê Văn Lương
A5: KRC | B5: A104 | C5: -1002552114547 | D5: KFM_HCM_NBE - 5/3D Huỳnh Tấn Phát
A6: KRC | B6: A105 | C6: -4907500481 | D6: KFM_HCM_TDU - 02 Lê Lợi
A7: KRC | B7: A106 | C7: -4831520955 | D7: KFM_HCM_PNH - T1-5 TMDV Orchard Garden
A8: KRC | B8: A107 | C8: -1003881507373 | D8: KFM_HCM_TDU - 05 Đường D3 Phước Long
A9: KRC | B9: A108 | C9: -4956823565 | D9: KFM_HCM_TDU - 38E Cây Keo
A10: KRC | B10: A109 | C10: -4920037539 | D10: KFM_HCM_Q07 - 106 Trần Trọng Cung
A11: KRC | B11: A110 | C11: -4832567003 | D11: KFM_HCM_Q10 - Jasmine 1 Hà Đô Centrosa
A12: KRC | B12: A111 | C12: -4964161256 | D12: KFM_HCM_TDU - BA-S03 New City
A13: KRC | B13: A112 | C13: -4880441469 | D13: KFM_HCM_Q1 - 93 Cô Giang
... A89: KRC | B89: A196 | C89: -5260328433 | D89: KFM_HCM_TBI - 56 Đường A4
B90: A197 | C90: -1004396051291 | D90: KFM_HCM_TDU - T05 Tháp Tilia Empire City
A91: KRC | B91: A198 | C91: -5586208104 | D91: KFM_HCM_Q07 - A1.03 Sunrise City View
A92: KRC | B92: A199 | C92: -5203032435 | D92: KFM_HCM_TBI - 76 Bàu Cát
A93: DC, KRC | B93: A200 | C93: -5576406617 | D93: KFM_HCM_Q12 - H36 Khu Nhà Ở Thới An Đường Lê Thị Riêng
A94: KRC | B94: A201 | C94: -1004405937281 | D94: KFM_HCM_GVA - 32B Đường Số 1 An Hội Đông
A95: KRC | B95: A202 | C95: -5013502390 | D95: KFM_HCM_BCH - 32A Đường Số 10 Bình Hưng
A96: KRC | B96: A203 | C96: -4993266266 | D96: KFM_HCM_Q12 - 135 Tân Thới Nhất 17
A97: KRC | B97: A204 | C97: -1004332992942 | D97: KFM_HCM_TDU - 67A Nguyễn Duy Trinh Long Trường
A98: KRC | B98: A205 | C98: -5487815548 | D98: KFM_HCM_GVA - 81/2 Đường 59 An Hội Tây
A99: KRC | B99: A207 | C99: -5552370383 | D99: KFM_HCM_TDU - SH-1C 2 Đường A5 KDC Palm Residence
B100: A208 | C100: -1004369961071 | D100: KFM_HCM_TDU - BS08 Vinhomes Grand Park
A101: KRC | B101: A209 | C101: -1004469963017 | D101: KFM_BDU_DAN - 145B Lê Trọng Tấn
A102: KRC | B102: A210 | C102: -1004413869891 | D102: KFM_HCM_TBI - 289 Hồng Lạc
A103: KRC | B103: A212 | C103: -5315774877 | D103: KFM_HCM_TDU - 146 Đường D1 Phước Long
A104: KRC | B104: A214 | C104: -1003707250405 | D104: KFM_BDU_TAN - 13 Vĩnh Phú 41
B105: A217 | C105: -1004334608188 | D105: KFM_HCM_TDU - 129 Hoàng Diệu 2
A106: KRC | B106: A218 | C106: -1004322601078 | D106: KFM_HCM_Q05 - 87 Nguyễn Duy Dương
B107: A219 | C107: -1004410100037 | D107: KFM_HCM_Q06 - TMDV 1-08 Chung Cư D-Homme
A108: DC, KRC | B108: A220 | C108: -5158042169 | D108: KFM_HCM_Q07 - 116 Đường Số 8 KDC Nam Long
A109: KRC | B109: A221 | C109: -5493948931 | D109: KFM_HCM_BTA - 235 Đường Số 6 An Lạc
A110: KRC | B110: A223 | C110: -1004424998343 | D110: KFM_HCM_PNH - 29 Đặng Văn Ngữ
A111: KRC | B111: A224 | C111: -1003888540638 | D111: KFM_HCM_GVA - 8 Nguyễn Văn Dung
A112: KRC | B112: A225 | C112: -1004375842803 | D112: KFM_HCM_TDU - 96K Đường Số 12 Tam Bình
B113: A229 | C113: -1004312253338 | D113: KFM_HCM_TPH - 58 Nguyễn Hữu Tiến
B114: A231 | C114: -1004339440131 | D114: KFM_HCM_BTA - 1M Đường A8 Bình Hưng Hòa B
B115: A232 | C115: -1004392333450 | D115: KFM_HCM_TDU - 376 Nguyễn Thị Định
...

Sheet Sheet1
A1: ST | B1: ID Mart
A2: KFM_BDU_DAN - 27 Tân Lập | B2: A101 | C2: =_xlfn.XLOOKUP(A2,Sheet2!D:D,Sheet2!B:B) -> A101
A3: KFM_HCM_TDU - 128A Kha Vạn Cân | B3: A102 | C3: =_xlfn.XLOOKUP(A3,Sheet2!D:D,Sheet2!B:B) -> A102
A4: KFM_HCM_NBE - 222 Lê Văn Lương | B4: A103 | C4: =_xlfn.XLOOKUP(A4,Sheet2!D:D,Sheet2!B:B) -> A103
A5: KFM_HCM_NBE - 5/3D Huỳnh Tấn Phát | B5: A104 | C5: =_xlfn.XLOOKUP(A5,Sheet2!D:D,Sheet2!B:B) -> A104
A6: KFM_HCM_TDU - 02 Lê Lợi | B6: A105 | C6: =_xlfn.XLOOKUP(A6,Sheet2!D:D,Sheet2!B:B) -> A105
A7: KFM_HCM_PNH - T1-5 TMDV Orchard Garden | B7: A106 | C7: =_xlfn.XLOOKUP(A7,Sheet2!D:D,Sheet2!B:B) -> A106
A8: KFM_HCM_TDU - 05 Đường D3 Phước Long | B8: A107 | C8: =_xlfn.XLOOKUP(A8,Sheet2!D:D,Sheet2!B:B) -> A107
A9: KFM_HCM_TDU - 38E Cây Keo | B9: A108 | C9: =_xlfn.XLOOKUP(A9,Sheet2!D:D,Sheet2!B:B) -> A108
A10: KFM_HCM_Q07 - 106 Trần Trọng Cung | B10: A109 | C10: =_xlfn.XLOOKUP(A10,Sheet2!D:D,Sheet2!B:B) -> A109
A11: KFM_HCM_Q10 - Jasmine 1 Hà Đô Centrosa | B11: A110 | C11: =_xlfn.XLOOKUP(A11,Sheet2!D:D,Sheet2!B:B) -> A110
A12: KFM_HCM_TDU - BA-S03 New City | B12: A111 | C12: =_xlfn.XLOOKUP(A12,Sheet2!D:D,Sheet2!B:B) -> A111
A13: KFM_HCM_Q1 - 93 Cô Giang | B13: A112 | C13: =_xlfn.XLOOKUP(A13,Sheet2!D:D,Sheet2!B:B) -> A112
... A225: KFM_HCM_BCH - D-2.01A Westgate An Gia | B225: WGA | C225: =_xlfn.XLOOKUP(A225,Sheet2!D:D,Sheet2!B:B) -> WGA
