Workbook

Sheet Chênh lệch ST tháng 08
F1: =5.635+5.08+0.47 -> 11.185 | G1: =F1-I26314 -> 11.185 | J1: =4.08+4.24+4.22 -> 12.54
B2: c | E2: , | H2: =SUBTOTAL(9,H4:H2084) -> 15490.6 | I2: =SUBTOTAL(9,I4:I2084) -> 13152.002 | J2: =SUBTOTAL(9,J4:J2084) -> 2338.598 | K2: =SUBTOTAL(9,K4:K76990) -> 0 | N2: =SUBTOTAL(9,N4:N2084) -> 122.039 | O2: =SUBTOTAL(9,O4:O2084) -> 108.577 | P2: =SUBTOTAL(9,P4:P2084) -> 2107.982 | Q2: =J2-N2-O2-P2 -> 0 | W2: Nơi nhận | AB2: DC phản hồi | AD2: KFM THÔNG TIN | AI2: =SUBTOTAL(9,AI4:AI153632) -> #N/A | AJ2: =SUBTOTAL(9,AJ4:AJ153632) -> #N/A | AK2: =SUBTOTAL(9,AK4:AK153632) -> #N/A | AL2: =SUBTOTAL(9,AL4:AL153632) -> #N/A | AM2: =SUBTOTAL(9,AM4:AM153632) -> #N/A | AN2: =SUBTOTAL(9,AN4:AN153632) -> #N/A
A3: Người xử lý | B3: Ngày chuyển hàng | C3: Chi nhánh nhận | D3: ID ST | E3: Mã hàng | F3: Tên Hàng | G3: ĐVT | H3: Số lượng chuyển | I3: Số lượng nhận | J3: Chênh lệch | K3: PT chuyển hàng | L3: Column 50 | M3: TO | N3: Hạo hụt tự nhiên | O3: SL trả tồn về ST | P3: SL chênh lệch CXD | Q3: PT Trả tồn về ST | R3: PT trả tồn về DC | S3: PT DC pick dư | T3: NOTE | U3: Trạng thái | V3: Lỗi | W3: Hao hụt | X3: Siêu thị | Y3: Kho rau | Z3: Xử lý | AA3: Link hình ảnh | AB3: DC xác nhận | AC3: NOTE 2 | AD3: KFM phản hồi | AE3: NOTE 3 | AF3: CLV2 | AG3: Loại hàng | AH3: % Hao hụt | AI3: Giá nhập ( -VAT) | AJ3: Tổng GT | AK3: Tổng hao hụt | AL3: Tổng ST | AM3: Tổng kho rau | AN3: Tổng chưa xác định | AO3: GSM phụ trách | AP3: RSM phụ trách | AQ3: Khu vực | AR3: Thọ Note | AS3: Lịch đi hàng | AT3: Cột 46 | AU3: CLV4 | AV3: Column 48 | AW3: Column 49 | AX3: Column 50 2
B4: 46235 | C4: KFM_HCM_Q09 - 367 Nguyễn Văn Tăng | D4: =VLOOKUP(C4,'DS ST'!A:B,2,0) -> NVT | E4: 1100992 | F4: DƯA LƯỚI VỎ XANH RUỘT CAM | G4: KG | H4: 10.1 | I4: 10.06 | J4: =H4-I4 -> 0.04 | K4: PT1598490 | L4: =K4&E4 -> PT15984901100992 | M4: TO227271 | N4: 0.04 | P4: =H4-I4-N4-O4 -> 0 | T4: hình kdb | U4: Thiếu Item trong kiện | V4: Hao hụt | W4: =IF(VALUE(N4)<=0,"",IF(TRIM(V4)="Hao hụt","Hao hụt","Hao hụt")) -> Hao hụt | X4: =IF(AND(N(O4)>0,OR(V4="DC giao bù",V4="VT giao sai điểm",V4="ST nhập thiếu",V4="DC pick sai",V4="ST kiểm sai QT",V4="ST thông tin sai")),"Siêu thị","") | Y4: =IF(N(P4)<=0,"",IF(OR(T4="Hình KDB",T4="Hình tele",ISNUMBER(SEARCH("Hình KDB",T4)),ISNUMBER(SEARCH("Hình tele",T4)),ISNUMBER(SEARCH("sai code",T4)),ISNUMBER(SEARCH("Thiếu kiện",U4))),"Kho rau",IF(AND(T4<>"Hình KDB",T4<>"Hình tele"),"Chưa xác định",IF(N(O4)>0,IF(OR(T4="Hình KDB",T4="Hình tele",ISNUMBER(SEARCH("Hình KDB",T4)),ISNUMBER(SEARCH("Hình tele",T4)),ISNUMBER(SEARCH("sai code",T4)),ISNUMBER(SEARCH("Thiếu kiện",U4))),"Kho rau","Chưa xác định"),IF(OR(T4="Hình KDB",T4="Hình tele",ISNUMBER(SEARCH("Hình KDB",T4)),ISNUMBER(SEARCH("Hình tele",T4)),ISNUMBER(SEARCH("sai code",T4)),ISNUMBER(SEARCH("Thiếu kiện",U4))),"Kho rau",IF(V4="Chưa xác định","Chưa xác định",IF(OR(V4="DC giao thiếu",V4="TX giao thiếu kiện",V4="Hàng không đạt CL"),"Kho rau",""))))))) | Z4: Hoàn Thành | AF4: {=xlookup($E:$E,'CLV2'!$A:$A,'CLV2'!E:E)} -> 2.FRUITS | AG4: =if(G4="KG","KG","Pack") -> KG | AH4: =J4/H4 -> 0.003960396 | AI4: {=XLOOKUP(E4,'Đơn giá'!A:A,'Đơn giá'!D:D)} -> 37000 | AJ4: =AI4*J4 -> 1480 | AK4: =IF($W:$W="Hao hụt", AI4*N4, 0) -> 1480 | AL4: =IF($X:$X="Siêu thị", AI4*O4, 0) -> 0 | AM4: =IF($Y:$Y="Kho rau", AI4*P4, 0) -> 0 | AN4: =IF($Y:$Y="Chưa xác định", AI4*P4, 0) -> 0 | AO4: {=XLOOKUP($D:$D,'DS ST'!$J:$J,'DS ST'!K:K)} -> SC002203 - Nguyễn Thị Ngọc Bích | AP4: {=XLOOKUP($D:$D,'DS ST'!$J:$J,'DS ST'!L:L)} -> Nguyễn Thị Cà | AQ4: {=XLOOKUP($D:$D,'DS ST'!$J:$J,'DS ST'!M:M)} -> HCM 005 | AT4: {=xlookup($E:$E,'CLV2'!$A:$A,'CLV2'!$F:$F)} -> 3.LOCAL FRUITS | AU4: {=xlookup($E:$E,'CLV2'!$A:$A,'CLV2'!$G:$G)} -> 4.Dưa Lưới
B5: 46235 | C5: KFM_HCM_Q09 - 367 Nguyễn Văn Tăng | D5: =VLOOKUP(C5,'DS ST'!A:B,2,0) -> NVT | E5: 1101302 | F5: CHUỐI GIÀ GIỐNG NAM MỸ | G5: KG | H5: 8 | I5: 7.98 | J5: =H5-I5 -> 0.02 | K5: PT1598490 | L5: =K5&E5 -> PT15984901101302 | M5: TO227271 | N5: 0.02 | P5: =H5-I5-N5-O5 -> 0 | T5: hình kdb | U5: Thiếu Item trong kiện | V5: Hao hụt | W5: =IF(VALUE(N5)<=0,"",IF(TRIM(V5)="Hao hụt","Hao hụt","Hao hụt")) -> Hao hụt | X5: =IF(AND(N(O5)>0,OR(V5="DC giao bù",V5="VT giao sai điểm",V5="ST nhập thiếu",V5="DC pick sai",V5="ST kiểm sai QT",V5="ST thông tin sai")),"Siêu thị","") | Y5: =IF(N(P5)<=0,"",IF(OR(T5="Hình KDB",T5="Hình tele",ISNUMBER(SEARCH("Hình KDB",T5)),ISNUMBER(SEARCH("Hình tele",T5)),ISNUMBER(SEARCH("sai code",T5)),ISNUMBER(SEARCH("Thiếu kiện",U5))),"Kho rau",IF(AND(T5<>"Hình KDB",T5<>"Hình tele"),"Chưa xác định",IF(N(O5)>0,IF(OR(T5="Hình KDB",T5="Hình tele",ISNUMBER(SEARCH("Hình KDB",T5)),ISNUMBER(SEARCH("Hình tele",T5)),ISNUMBER(SEARCH("sai code",T5)),ISNUMBER(SEARCH("Thiếu kiện",U5))),"Kho rau","Chưa xác định"),IF(OR(T5="Hình KDB",T5="Hình tele",ISNUMBER(SEARCH("Hình KDB",T5)),ISNUMBER(SEARCH("Hình tele",T5)),ISNUMBER(SEARCH("sai code",T5)),ISNUMBER(SEARCH("Thiếu kiện",U5))),"Kho rau",IF(V5="Chưa xác định","Chưa xác định",IF(OR(V5="DC giao thiếu",V5="TX giao thiếu kiện",V5="Hàng không đạt CL"),"Kho rau",""))))))) | Z5: Hoàn Thành | AF5: {=xlookup($E:$E,'CLV2'!$A:$A,'CLV2'!E:E)} -> 2.FRUITS | AG5: =if(G5="KG","KG","Pack") -> KG | AH5: =J5/H5 -> 0.0025 | AI5: {=XLOOKUP(E5,'Đơn giá'!A:A,'Đơn giá'!D:D)} -> 17500 | AJ5: =AI5*J5 -> 350 | AK5: =IF($W:$W="Hao hụt", AI5*N5, 0) -> 350 | AL5: =IF($X:$X="Siêu thị", AI5*O5, 0) -> 0 | AM5: =IF($Y:$Y="Kho rau", AI5*P5, 0) -> 0 | AN5: =IF($Y:$Y="Chưa xác định", AI5*P5, 0) -> 0 | AO5: {=XLOOKUP($D:$D,'DS ST'!$J:$J,'DS ST'!K:K)} -> SC002203 - Nguyễn Thị Ngọc Bích | AP5: {=XLOOKUP($D:$D,'DS ST'!$J:$J,'DS ST'!L:L)} -> Nguyễn Thị Cà | AQ5: {=XLOOKUP($D:$D,'DS ST'!$J:$J,'DS ST'!M:M)} -> HCM 005 | AT5: {=xlookup($E:$E,'CLV2'!$A:$A,'CLV2'!$F:$F)} -> 3.LOCAL FRUITS | AU5: {=xlookup($E:$E,'CLV2'!$A:$A,'CLV2'!$G:$G)} -> 4.Chuối
B6: 46235 | C6: KFM_HCM_BTA - 46 Nguyễn Thị Tú | D6: =VLOOKUP(C6,'DS ST'!A:B,2,0) -> NTU | E6: SP001932 | F6: BON - BÁNH DONUT 80G | G6: CÁI | H6: 1 | I6: 0 | J6: =H6-I6 -> 1 | K6: PT1598563 | L6: =K6&E6 -> PT1598563SP001932 | M6: TO227296 | O6: 1 | P6: =H6-I6-N6-O6 -> 0 | Q6: PT1610050 | U6: Thiếu Item trong kiện | V6: ST nhập thiếu | W6: =IF(VALUE(N6)<=0,"",IF(TRIM(V6)="Hao hụt","Hao hụt","Hao hụt")) | X6: =IF(AND(N(O6)>0,OR(V6="DC giao bù",V6="VT giao sai điểm",V6="ST nhập thiếu",V6="DC pick sai",V6="ST kiểm sai QT",V6="ST thông tin sai")),"Siêu thị","") -> Siêu thị | Z6: Hoàn Thành | AF6: {=xlookup($E:$E,'CLV2'!$A:$A,'CLV2'!E:E)} -> 2.BAKERY | AG6: =if(G6="KG","KG","Pack") -> Pack | AH6: =J6/H6 -> 1 | AI6: {=XLOOKUP(E6,'Đơn giá'!A:A,'Đơn giá'!D:D)} -> 10299 | AJ6: =AI6*J6 -> 10299 | AK6: =IF($W:$W="Hao hụt", AI6*N6, 0) -> 0 | AL6: =IF($X:$X="Siêu thị", AI6*O6, 0) -> 10299 | AM6: =IF($Y:$Y="Kho rau", AI6*P6, 0) -> 0 | AN6: =IF($Y:$Y="Chưa xác định", AI6*P6, 0) -> 0 | AO6: {=XLOOKUP($D:$D,'DS ST'!$J:$J,'DS ST'!K:K)} -> SC013823 - Lê Văn Ninh | AP6: {=XLOOKUP($D:$D,'DS ST'!$J:$J,'DS ST'!L:L)} -> Võ Thị Huệ | AQ6: {=XLOOKUP($D:$D,'DS ST'!$J:$J,'DS ST'!M:M)} -> HCM 012 | AT6: {=xlookup($E:$E,'CLV2'!$A:$A,'CLV2'!$F:$F)} -> 3.BREADS | AU6: {=xlookup($E:$E,'CLV2'!$A:$A,'CLV2'!$G:$G)} -> 4.BÁNH TƯƠI DATE NGẮN
B7: 46235 | C7: KFM_HCM_BTA - 46 Nguyễn Thị Tú | D7: =VLOOKUP(C7,'DS ST'!A:B,2,0) -> NTU | E7: SP001572 | F7: BON - BÁNH SANDWICH LÚA MẠCH 200G | G7: GÓI | H7: 1 | I7: 0 | J7: =H7-I7 -> 1 | K7: PT1598563 | L7: =K7&E7 -> PT1598563SP001572 | M7: TO227296 | O7: 1 | P7: =H7-I7-N7-O7 -> 0 | Q7: PT1610050 | U7: Thiếu Item trong kiện | V7: ST nhập thiếu | W7: =IF(VALUE(N7)<=0,"",IF(TRIM(V7)="Hao hụt","Hao hụt","Hao hụt")) | X7: =IF(AND(N(O7)>0,OR(V7="DC giao bù",V7="VT giao sai điểm",V7="ST nhập thiếu",V7="DC pick sai",V7="ST kiểm sai QT",V7="ST thông tin sai")),"Siêu thị","") -> Siêu thị | Z7: Hoàn Thành | AF7: {=xlookup($E:$E,'CLV2'!$A:$A,'CLV2'!E:E)} -> 2.BAKERY | AG7: =if(G7="KG","KG","Pack") -> Pack | AH7: =J7/H7 -> 1 | AI7: {=XLOOKUP(E7,'Đơn giá'!A:A,'Đơn giá'!D:D)} -> 21493 | AJ7: =AI7*J7 -> 21493 | AK7: =IF($W:$W="Hao hụt", AI7*N7, 0) -> 0 | AL7: =IF($X:$X="Siêu thị", AI7*O7, 0) -> 21493 | AM7: =IF($Y:$Y="Kho rau", AI7*P7, 0) -> 0 | AN7: =IF($Y:$Y="Chưa xác định", AI7*P7, 0) -> 0 | AO7: {=XLOOKUP($D:$D,'DS ST'!$J:$J,'DS ST'!K:K)} -> SC013823 - Lê Văn Ninh | AP7: {=XLOOKUP($D:$D,'DS ST'!$J:$J,'DS ST'!L:L)} -> Võ Thị Huệ | AQ7: {=XLOOKUP($D:$D,'DS ST'!$J:$J,'DS ST'!M:M)} -> HCM 012 | AT7: {=xlookup($E:$E,'CLV2'!$A:$A,'CLV2'!$F:$F)} -> 3.BREADS | AU7: {=xlookup($E:$E,'CLV2'!$A:$A,'CLV2'!$G:$G)} -> 4.BÁNH TƯƠI DATE NGẮN
B8: 46235 | C8: KFM_HCM_BTA - 46 Nguyễn Thị Tú | D8: =VLOOKUP(C8,'DS ST'!A:B,2,0) -> NTU | E8: 8936109824228 | F8: SAINT HONORE - BÁNH MÌ TRUYỀN THỐNG MINI 200G (40G x 5 CÁI) | G8: GÓI | H8: 2 | I8: 0 | J8: =H8-I8 -> 2 | K8: PT1598563 | L8: =K8&E8 -> PT15985638936109824228 | M8: TO227296 | O8: 2 | P8: =H8-I8-N8-O8 -> 0 | Q8: PT1610050 | U8: Thiếu Item trong kiện | V8: ST nhập thiếu | W8: =IF(VALUE(N8)<=0,"",IF(TRIM(V8)="Hao hụt","Hao hụt","Hao hụt")) | X8: =IF(AND(N(O8)>0,OR(V8="DC giao bù",V8="VT giao sai điểm",V8="ST nhập thiếu",V8="DC pick sai",V8="ST kiểm sai QT",V8="ST thông tin sai")),"Siêu thị","") -> Siêu thị | Z8: Hoàn Thành | AF8: {=xlookup($E:$E,'CLV2'!$A:$A,'CLV2'!E:E)} -> 2.BAKERY | AG8: =if(G8="KG","KG","Pack") -> Pack | AH8: =J8/H8 -> 1 | AI8: {=XLOOKUP(E8,'Đơn giá'!A:A,'Đơn giá'!D:D)} -> 10500 | AJ8: =AI8*J8 -> 21000 | AK8: =IF($W:$W="Hao hụt", AI8*N8, 0) -> 0 | AL8: =IF($X:$X="Siêu thị", AI8*O8, 0) -> 21000 | AM8: =IF($Y:$Y="Kho rau", AI8*P8, 0) -> 0 | AN8: =IF($Y:$Y="Chưa xác định", AI8*P8, 0) -> 0 | AO8: {=XLOOKUP($D:$D,'DS ST'!$J:$J,'DS ST'!K:K)} -> SC013823 - Lê Văn Ninh | AP8: {=XLOOKUP($D:$D,'DS ST'!$J:$J,'DS ST'!L:L)} -> Võ Thị Huệ | AQ8: {=XLOOKUP($D:$D,'DS ST'!$J:$J,'DS ST'!M:M)} -> HCM 012 | AT8: {=xlookup($E:$E,'CLV2'!$A:$A,'CLV2'!$F:$F)} -> 3.BREADS | AU8: {=xlookup($E:$E,'CLV2'!$A:$A,'CLV2'!$G:$G)} -> 4.BÁNH TƯƠI DATE NGẮN
B9: 46235 | C9: KFM_HCM_BTA - 46 Nguyễn Thị Tú | D9: =VLOOKUP(C9,'DS ST'!A:B,2,0) -> NTU | E9: SP001587 | F9: BON - BÁNH CROISSANT BƠ TỎI 120G (20G x 6 CÁI) | G9: HỘP | H9: 2 | I9: 0 | J9: =H9-I9 -> 2 | K9: PT1598563 | L9: =K9&E9 -> PT1598563SP001587 | M9: TO227296 | O9: 2 | P9: =H9-I9-N9-O9 -> 0 | Q9: PT1610050 | U9: Thiếu Item trong kiện | V9: ST nhập thiếu | W9: =IF(VALUE(N9)<=0,"",IF(TRIM(V9)="Hao hụt","Hao hụt","Hao hụt")) | X9: =IF(AND(N(O9)>0,OR(V9="DC giao bù",V9="VT giao sai điểm",V9="ST nhập thiếu",V9="DC pick sai",V9="ST kiểm sai QT",V9="ST thông tin sai")),"Siêu thị","") -> Siêu thị | Z9: Hoàn Thành | AF9: {=xlookup($E:$E,'CLV2'!$A:$A,'CLV2'!E:E)} -> 2.BAKERY | AG9: =if(G9="KG","KG","Pack") -> Pack | AH9: =J9/H9 -> 1 | AI9: {=XLOOKUP(E9,'Đơn giá'!A:A,'Đơn giá'!D:D)} -> 15329 | AJ9: =AI9*J9 -> 30658 | AK9: =IF($W:$W="Hao hụt", AI9*N9, 0) -> 0 | AL9: =IF($X:$X="Siêu thị", AI9*O9, 0) -> 30658 | AM9: =IF($Y:$Y="Kho rau", AI9*P9, 0) -> 0 | AN9: =IF($Y:$Y="Chưa xác định", AI9*P9, 0) -> 0 | AO9: {=XLOOKUP($D:$D,'DS ST'!$J:$J,'DS ST'!K:K)} -> SC013823 - Lê Văn Ninh | AP9: {=XLOOKUP($D:$D,'DS ST'!$J:$J,'DS ST'!L:L)} -> Võ Thị Huệ | AQ9: {=XLOOKUP($D:$D,'DS ST'!$J:$J,'DS ST'!M:M)} -> HCM 012 | AT9: {=xlookup($E:$E,'CLV2'!$A:$A,'CLV2'!$F:$F)} -> 3.BREADS | AU9: {=xlookup($E:$E,'CLV2'!$A:$A,'CLV2'!$G:$G)} -> 4.BÁNH TƯƠI DATE NGẮN
B10: 46235 | C10: KFM_HCM_BCH - 511 Quốc Lộ 50 | D10: =VLOOKUP(C10,'DS ST'!A:B,2,0) -> Q50 | E10: 1100992 | F10: DƯA LƯỚI VỎ XANH RUỘT CAM | G10: KG | H10: 10.1 | I10: 10 | J10: =H10-I10 -> 0.1 | K10: PT1598561 | L10: =K10&E10 -> PT15985611100992 | M10: TO227245 | N10: 0.1 | P10: =H10-I10-N10-O10 -> 0 | T10: hình kdb | U10: Thiếu Item trong kiện | V10: Hao hụt | W10: =IF(VALUE(N10)<=0,"",IF(TRIM(V10)="Hao hụt","Hao hụt","Hao hụt")) -> Hao hụt | X10: =IF(AND(N(O10)>0,OR(V10="DC giao bù",V10="VT giao sai điểm",V10="ST nhập thiếu",V10="DC pick sai",V10="ST kiểm sai QT",V10="ST thông tin sai")),"Siêu thị","") | Y10: =IF(N(P10)<=0,"",IF(OR(T10="Hình KDB",T10="Hình tele",ISNUMBER(SEARCH("Hình KDB",T10)),ISNUMBER(SEARCH("Hình tele",T10)),ISNUMBER(SEARCH("sai code",T10)),ISNUMBER(SEARCH("Thiếu kiện",U10))),"Kho rau",IF(AND(T10<>"Hình KDB",T10<>"Hình tele"),"Chưa xác định",IF(N(O10)>0,IF(OR(T10="Hình KDB",T10="Hình tele",ISNUMBER(SEARCH("Hình KDB",T10)),ISNUMBER(SEARCH("Hình tele",T10)),ISNUMBER(SEARCH("sai code",T10)),ISNUMBER(SEARCH("Thiếu kiện",U10))),"Kho rau","Chưa xác định"),IF(OR(T10="Hình KDB",T10="Hình tele",ISNUMBER(SEARCH("Hình KDB",T10)),ISNUMBER(SEARCH("Hình tele",T10)),ISNUMBER(SEARCH("sai code",T10)),ISNUMBER(SEARCH("Thiếu kiện",U10))),"Kho rau",IF(V10="Chưa xác định","Chưa xác định",IF(OR(V10="DC giao thiếu",V10="TX giao thiếu kiện",V10="Hàng không đạt CL"),"Kho rau",""))))))) | Z10: Hoàn Thành | AF10: {=xlookup($E:$E,'CLV2'!$A:$A,'CLV2'!E:E)} -> 2.FRUITS | AG10: =if(G10="KG","KG","Pack") -> KG | AH10: =J10/H10 -> 0.0099009901 | AI10: {=XLOOKUP(E10,'Đơn giá'!A:A,'Đơn giá'!D:D)} -> 37000 | AJ10: =AI10*J10 -> 3700 | AK10: =IF($W:$W="Hao hụt", AI10*N10, 0) -> 3700 | AL10: =IF($X:$X="Siêu thị", AI10*O10, 0) -> 0 | AM10: =IF($Y:$Y="Kho rau", AI10*P10, 0) -> 0 | AN10: =IF($Y:$Y="Chưa xác định", AI10*P10, 0) -> 0 | AO10: {=XLOOKUP($D:$D,'DS ST'!$J:$J,'DS ST'!K:K)} -> SC005255 - Hồng Trọng Nghĩa | AP10: {=XLOOKUP($D:$D,'DS ST'!$J:$J,'DS ST'!L:L)} -> Võ Thị Huệ | AQ10: {=XLOOKUP($D:$D,'DS ST'!$J:$J,'DS ST'!M:M)} -> HCM 022 | AT10: {=xlookup($E:$E,'CLV2'!$A:$A,'CLV2'!$F:$F)} -> 3.LOCAL FRUITS | AU10: {=xlookup($E:$E,'CLV2'!$A:$A,'CLV2'!$G:$G)} -> 4.Dưa Lưới
B11: 46235 | C11: KFM_HCM_Q07 - 116 Đường Số 8 KDC Nam Long | D11: =VLOOKUP(C11,'DS ST'!A:B,2,0) -> A220 | E11: 1101812 | F11: DƯA HẤU GIỐNG MỸ | G11: KG | H11: 15.4 | I11: 15.18 | J11: =H11-I11 -> 0.22 | K11: PT1598558 | L11: =K11&E11 -> PT15985581101812 | M11: TO227204 | N11: 0.22 | P11: =H11-I11-N11-O11 -> 0 | T11: hình kdb | U11: Thiếu Item trong kiện | V11: Hao hụt | W11: =IF(VALUE(N11)<=0,"",IF(TRIM(V11)="Hao hụt","Hao hụt","Hao hụt")) -> Hao hụt | X11: =IF(AND(N(O11)>0,OR(V11="DC giao bù",V11="VT giao sai điểm",V11="ST nhập thiếu",V11="DC pick sai",V11="ST kiểm sai QT",V11="ST thông tin sai")),"Siêu thị","") | Y11: =IF(N(P11)<=0,"",IF(OR(T11="Hình KDB",T11="Hình tele",ISNUMBER(SEARCH("Hình KDB",T11)),ISNUMBER(SEARCH("Hình tele",T11)),ISNUMBER(SEARCH("sai code",T11)),ISNUMBER(SEARCH("Thiếu kiện",U11))),"Kho rau",IF(AND(T11<>"Hình KDB",T11<>"Hình tele"),"Chưa xác định",IF(N(O11)>0,IF(OR(T11="Hình KDB",T11="Hình tele",ISNUMBER(SEARCH("Hình KDB",T11)),ISNUMBER(SEARCH("Hình tele",T11)),ISNUMBER(SEARCH("sai code",T11)),ISNUMBER(SEARCH("Thiếu kiện",U11))),"Kho rau","Chưa xác định"),IF(OR(T11="Hình KDB",T11="Hình tele",ISNUMBER(SEARCH("Hình KDB",T11)),ISNUMBER(SEARCH("Hình tele",T11)),ISNUMBER(SEARCH("sai code",T11)),ISNUMBER(SEARCH("Thiếu kiện",U11))),"Kho rau",IF(V11="Chưa xác định","Chưa xác định",IF(OR(V11="DC giao thiếu",V11="TX giao thiếu kiện",V11="Hàng không đạt CL"),"Kho rau",""))))))) | Z11: Hoàn Thành | AF11: {=xlookup($E:$E,'CLV2'!$A:$A,'CLV2'!E:E)} -> 2.FRUITS | AG11: =if(G11="KG","KG","Pack") -> KG | AH11: =J11/H11 -> 0.014285714 | AI11: {=XLOOKUP(E11,'Đơn giá'!A:A,'Đơn giá'!D:D)} -> 23000 | AJ11: =AI11*J11 -> 5060 | AK11: =IF($W:$W="Hao hụt", AI11*N11, 0) -> 5060 | AL11: =IF($X:$X="Siêu thị", AI11*O11, 0) -> 0 | AM11: =IF($Y:$Y="Kho rau", AI11*P11, 0) -> 0 | AN11: =IF($Y:$Y="Chưa xác định", AI11*P11, 0) -> 0 | AO11: {=XLOOKUP($D:$D,'DS ST'!$J:$J,'DS ST'!K:K)} -> #N/A | AP11: {=XLOOKUP($D:$D,'DS ST'!$J:$J,'DS ST'!L:L)} -> #N/A | AQ11: {=XLOOKUP($D:$D,'DS ST'!$J:$J,'DS ST'!M:M)} -> #N/A | AT11: {=xlookup($E:$E,'CLV2'!$A:$A,'CLV2'!$F:$F)} -> 3.LOCAL FRUITS | AU11: {=xlookup($E:$E,'CLV2'!$A:$A,'CLV2'!$G:$G)} -> 4.Dưa Hấu
B12: 46235 | C12: KFM_HCM_TDU - 222 Lê Văn Thịnh | D12: =VLOOKUP(C12,'DS ST'!A:B,2,0) -> LVH | E12: 11695 | F12: HÀNH TÂY TÍM ĐÀ LẠT 500G | G12: PACK | H12: 1 | I12: 0 | J12: =H12-I12 -> 1 | K12: PT1598557 | L12: =K12&E12 -> PT159855711695 | M12: TO227389 | P12: =H12-I12-N12-O12 -> 1 | U12: Thiếu Item trong kiện | V12: DC giao thiếu | W12: =IF(VALUE(N12)<=0,"",IF(TRIM(V12)="Hao hụt","Hao hụt","Hao hụt")) | X12: =IF(AND(N(O12)>0,OR(V12="DC giao bù",V12="VT giao sai điểm",V12="ST nhập thiếu",V12="DC pick sai",V12="ST kiểm sai QT",V12="ST thông tin sai")),"Siêu thị","") | Y12: Kho rau | Z12: Hoàn Thành | AF12: {=xlookup($E:$E,'CLV2'!$A:$A,'CLV2'!E:E)} -> 2.VEGETABLES | AG12: =if(G12="KG","KG","Pack") -> Pack | AH12: =J12/H12 -> 1 | AI12: {=XLOOKUP(E12,'Đơn giá'!A:A,'Đơn giá'!D:D)} -> 17893 | AJ12: =AI12*J12 -> 17893 | AK12: =IF($W:$W="Hao hụt", AI12*N12, 0) -> 0 | AL12: =IF($X:$X="Siêu thị", AI12*O12, 0) -> 0 | AM12: =IF($Y:$Y="Kho rau", AI12*P12, 0) -> 17893 | AN12: =IF($Y:$Y="Chưa xác định", AI12*P12, 0) -> 0 | AO12: {=XLOOKUP($D:$D,'DS ST'!$J:$J,'DS ST'!K:K)} -> SC010667 - Đào Hồng Hiện | AP12: {=XLOOKUP($D:$D,'DS ST'!$J:$J,'DS ST'!L:L)} -> Nguyễn Thị Cà | AQ12: {=XLOOKUP($D:$D,'DS ST'!$J:$J,'DS ST'!M:M)} -> HCM 035 | AT12: {=xlookup($E:$E,'CLV2'!$A:$A,'CLV2'!$F:$F)} -> 3.ROOT VEGGIES | AU12: {=xlookup($E:$E,'CLV2'!$A:$A,'CLV2'!$G:$G)} -> 4.Hành Tây
A13: Như | B13: 46235 | C13: KFM_HCM_BCH - A7-8 Valora Mizuki | D13: =VLOOKUP(C13,'DS ST'!A:B,2,0) -> MZ2 | E13: 8936076270318 | F13: SAVOURE - BÁNH HÌNH CUA NHỎ (CROISSANT MINI) 135G | G13: CÁI | H13: 6 | I13: 5 | J13: =H13-I13 -> 1 | K13: PT1598555 | L13: =K13&E13 -> PT15985558936076270318 | M13: TO227289 | P13: =H13-I13-N13-O13 -> 1 | T13: hình kdb | U13: Thiếu Item trong kiện | V13: DC giao thiếu | W13: =IF(VALUE(N13)<=0,"",IF(TRIM(V13)="Hao hụt","Hao hụt","Hao hụt")) | X13: =IF(AND(N(O13)>0,OR(V13="DC giao bù",V13="VT giao sai điểm",V13="ST nhập thiếu",V13="DC pick sai",V13="ST kiểm sai QT",V13="ST thông tin sai")),"Siêu thị","") | Y13: =IF(N(P13)<=0,"",IF(OR(T13="Hình KDB",T13="Hình tele",ISNUMBER(SEARCH("Hình KDB",T13)),ISNUMBER(SEARCH("Hình tele",T13)),ISNUMBER(SEARCH("sai code",T13)),ISNUMBER(SEARCH("Thiếu kiện",U13))),"Kho rau",IF(AND(T13<>"Hình KDB",T13<>"Hình tele"),"Chưa xác định",IF(N(O13)>0,IF(OR(T13="Hình KDB",T13="Hình tele",ISNUMBER(SEARCH("Hình KDB",T13)),ISNUMBER(SEARCH("Hình tele",T13)),ISNUMBER(SEARCH("sai code",T13)),ISNUMBER(SEARCH("Thiếu kiện",U13))),"Kho rau","Chưa xác định"),IF(OR(T13="Hình KDB",T13="Hình tele",ISNUMBER(SEARCH("Hình KDB",T13)),ISNUMBER(SEARCH("Hình tele",T13)),ISNUMBER(SEARCH("sai code",T13)),ISNUMBER(SEARCH("Thiếu kiện",U13))),"Kho rau",IF(V13="Chưa xác định","Chưa xác định",IF(OR(V13="DC giao thiếu",V13="TX giao thiếu kiện",V13="Hàng không đạt CL"),"Kho rau",""))))))) -> Kho rau | Z13: Hoàn Thành | AB13: Đồng ý claim | AF13: {=xlookup($E:$E,'CLV2'!$A:$A,'CLV2'!E:E)} -> 2.BAKERY | AG13: =if(G13="KG","KG","Pack") -> Pack | AH13: =J13/H13 -> 0.16666667 | AI13: {=XLOOKUP(E13,'Đơn giá'!A:A,'Đơn giá'!D:D)} -> 11865 | AJ13: =AI13*J13 -> 11865 | AK13: =IF($W:$W="Hao hụt", AI13*N13, 0) -> 0 | AL13: =IF($X:$X="Siêu thị", AI13*O13, 0) -> 0 | AM13: =IF($Y:$Y="Kho rau", AI13*P13, 0) -> 11865 | AN13: =IF($Y:$Y="Chưa xác định", AI13*P13, 0) -> 0 | AO13: {=XLOOKUP($D:$D,'DS ST'!$J:$J,'DS ST'!K:K)} -> SC005255 - Hồng Trọng Nghĩa | AP13: {=XLOOKUP($D:$D,'DS ST'!$J:$J,'DS ST'!L:L)} -> Võ Thị Huệ | AQ13: {=XLOOKUP($D:$D,'DS ST'!$J:$J,'DS ST'!M:M)} -> HCM 022 | AT13: {=xlookup($E:$E,'CLV2'!$A:$A,'CLV2'!$F:$F)} -> 3.BREADS | AU13: {=xlookup($E:$E,'CLV2'!$A:$A,'CLV2'!$G:$G)} -> 4.BÁNH TƯƠI DATE NGẮN
B14: 46235 | C14: KFM_HCM_Q06 - 229A Tân Hòa Đông | D14: =VLOOKUP(C14,'DS ST'!A:B,2,0) -> THD | E14: 11670 | F14: MĂNG TÂY SIZE LỚN 250G | G14: GÓI | H14: 1 | I14: 0 | J14: =H14-I14 -> 1 | K14: PT1598554 | L14: =K14&E14 -> PT159855411670 | M14: TO227304 | P14: =H14-I14-N14-O14 -> 1 | R14: x | U14: Thiếu Item trong kiện | V14: DC giao thiếu | W14: =IF(VALUE(N14)<=0,"",IF(TRIM(V14)="Hao hụt","Hao hụt","Hao hụt")) | X14: =IF(AND(N(O14)>0,OR(V14="DC giao bù",V14="VT giao sai điểm",V14="ST nhập thiếu",V14="DC pick sai",V14="ST kiểm sai QT",V14="ST thông tin sai")),"Siêu thị","") | Y14: Kho rau | Z14: Hoàn Thành | AF14: {=xlookup($E:$E,'CLV2'!$A:$A,'CLV2'!E:E)} -> 2.VEGETABLES | AG14: =if(G14="KG","KG","Pack") -> Pack | AH14: =J14/H14 -> 1 | AI14: {=XLOOKUP(E14,'Đơn giá'!A:A,'Đơn giá'!D:D)} -> 28230 | AJ14: =AI14*J14 -> 28230 | AK14: =IF($W:$W="Hao hụt", AI14*N14, 0) -> 0 | AL14: =IF($X:$X="Siêu thị", AI14*O14, 0) -> 0 | AM14: =IF($Y:$Y="Kho rau", AI14*P14, 0) -> 28230 | AN14: =IF($Y:$Y="Chưa xác định", AI14*P14, 0) -> 0 | AO14: {=XLOOKUP($D:$D,'DS ST'!$J:$J,'DS ST'!K:K)} -> SC008805 - Nguyễn Thị Ngọc Giàu | AP14: {=XLOOKUP($D:$D,'DS ST'!$J:$J,'DS ST'!L:L)} -> Võ Thị Huệ | AQ14: {=XLOOKUP($D:$D,'DS ST'!$J:$J,'DS ST'!M:M)} -> HCM 031 | AT14: {=xlookup($E:$E,'CLV2'!$A:$A,'CLV2'!$F:$F)} -> 3.LEAFY VEGGIES | AU14: {=xlookup($E:$E,'CLV2'!$A:$A,'CLV2'!$G:$G)} -> 4.Rau Ăn Thân, Lá Khác
B15: 46235 | C15: KFM_HCM_Q06 - 123 Lý Chiêu Hoàng | D15: =VLOOKUP(C15,'DS ST'!A:B,2,0) -> A121 | E15: 1101366 | F15: BÔNG CẢI XANH ĐÀ LẠT (KG) | G15: KG | H15: 4.3 | I15: 4.24 | J15: =H15-I15 -> 0.06 | K15: PT1598553 | L15: =K15&E15 -> PT15985531101366 | M15: TO227298 | N15: 0.06 | P15: =H15-I15-N15-O15 -> 0 | T15: hình kdb | U15: Thiếu Item trong kiện | V15: Hao hụt | W15: =IF(VALUE(N15)<=0,"",IF(TRIM(V15)="Hao hụt","Hao hụt","Hao hụt")) -> Hao hụt | X15: =IF(AND(N(O15)>0,OR(V15="DC giao bù",V15="VT giao sai điểm",V15="ST nhập thiếu",V15="DC pick sai",V15="ST kiểm sai QT",V15="ST thông tin sai")),"Siêu thị","") | Y15: =IF(N(P15)<=0,"",IF(OR(T15="Hình KDB",T15="Hình tele",ISNUMBER(SEARCH("Hình KDB",T15)),ISNUMBER(SEARCH("Hình tele",T15)),ISNUMBER(SEARCH("sai code",T15)),ISNUMBER(SEARCH("Thiếu kiện",U15))),"Kho rau",IF(AND(T15<>"Hình KDB",T15<>"Hình tele"),"Chưa xác định",IF(N(O15)>0,IF(OR(T15="Hình KDB",T15="Hình tele",ISNUMBER(SEARCH("Hình KDB",T15)),ISNUMBER(SEARCH("Hình tele",T15)),ISNUMBER(SEARCH("sai code",T15)),ISNUMBER(SEARCH("Thiếu kiện",U15))),"Kho rau","Chưa xác định"),IF(OR(T15="Hình KDB",T15="Hình tele",ISNUMBER(SEARCH("Hình KDB",T15)),ISNUMBER(SEARCH("Hình tele",T15)),ISNUMBER(SEARCH("sai code",T15)),ISNUMBER(SEARCH("Thiếu kiện",U15))),"Kho rau",IF(V15="Chưa xác định","Chưa xác định",IF(OR(V15="DC giao thiếu",V15="TX giao thiếu kiện",V15="Hàng không đạt CL"),"Kho rau",""))))))) | Z15: Hoàn Thành | AF15: {=xlookup($E:$E,'CLV2'!$A:$A,'CLV2'!E:E)} -> 2.VEGETABLES | AG15: =if(G15="KG","KG","Pack") -> KG | AH15: =J15/H15 -> 0.013953488 | AI15: {=XLOOKUP(E15,'Đơn giá'!A:A,'Đơn giá'!D:D)} -> 55000 | AJ15: =AI15*J15 -> 3300 | AK15: =IF($W:$W="Hao hụt", AI15*N15, 0) -> 3300 | AL15: =IF($X:$X="Siêu thị", AI15*O15, 0) -> 0 | AM15: =IF($Y:$Y="Kho rau", AI15*P15, 0) -> 0 | AN15: =IF($Y:$Y="Chưa xác định", AI15*P15, 0) -> 0 | AO15: {=XLOOKUP($D:$D,'DS ST'!$J:$J,'DS ST'!K:K)} -> SC003242 - Võ Văn Phi Hùng | AP15: {=XLOOKUP($D:$D,'DS ST'!$J:$J,'DS ST'!L:L)} -> Võ Thị Huệ | AQ15: {=XLOOKUP($D:$D,'DS ST'!$J:$J,'DS ST'!M:M)} -> HCM 029 | AT15: {=xlookup($E:$E,'CLV2'!$A:$A,'CLV2'!$F:$F)} -> 3.LEAFY VEGGIES | AU15: {=xlookup($E:$E,'CLV2'!$A:$A,'CLV2'!$G:$G)} -> 4.Rau Ăn Bông
B16: 46235 | C16: KFM_HCM_TDU - SH-1C 2 Đường A5 KDC Palm Residence | D16: =VLOOKUP(C16,'DS ST'!A:B,2,0) -> A207 | E16: 1100992 | F16: DƯA LƯỚI VỎ XANH RUỘT CAM | G16: KG | H16: 10.2 | I16: 9.96 | J16: =H16-I16 -> 0.24 | K16: PT1598552 | L16: =K16&E16 -> PT15985521100992 | M16: TO227196 | N16: 0.24 | P16: =H16-I16-N16-O16 -> 0 | T16: hình kdb | U16: Thiếu Item trong kiện | V16: Hao hụt | W16: =IF(VALUE(N16)<=0,"",IF(TRIM(V16)="Hao hụt","Hao hụt","Hao hụt")) -> Hao hụt | X16: =IF(AND(N(O16)>0,OR(V16="DC giao bù",V16="VT giao sai điểm",V16="ST nhập thiếu",V16="DC pick sai",V16="ST kiểm sai QT",V16="ST thông tin sai")),"Siêu thị","") | Y16: =IF(N(P16)<=0,"",IF(OR(T16="Hình KDB",T16="Hình tele",ISNUMBER(SEARCH("Hình KDB",T16)),ISNUMBER(SEARCH("Hình tele",T16)),ISNUMBER(SEARCH("sai code",T16)),ISNUMBER(SEARCH("Thiếu kiện",U16))),"Kho rau",IF(AND(T16<>"Hình KDB",T16<>"Hình tele"),"Chưa xác định",IF(N(O16)>0,IF(OR(T16="Hình KDB",T16="Hình tele",ISNUMBER(SEARCH("Hình KDB",T16)),ISNUMBER(SEARCH("Hình tele",T16)),ISNUMBER(SEARCH("sai code",T16)),ISNUMBER(SEARCH("Thiếu kiện",U16))),"Kho rau","Chưa xác định"),IF(OR(T16="Hình KDB",T16="Hình tele",ISNUMBER(SEARCH("Hình KDB",T16)),ISNUMBER(SEARCH("Hình tele",T16)),ISNUMBER(SEARCH("sai code",T16)),ISNUMBER(SEARCH("Thiếu kiện",U16))),"Kho rau",IF(V16="Chưa xác định","Chưa xác định",IF(OR(V16="DC giao thiếu",V16="TX giao thiếu kiện",V16="Hàng không đạt CL"),"Kho rau",""))))))) | Z16: Hoàn Thành | AF16: {=xlookup($E:$E,'CLV2'!$A:$A,'CLV2'!E:E)} -> 2.FRUITS | AG16: =if(G16="KG","KG","Pack") -> KG | AH16: =J16/H16 -> 0.023529412 | AI16: {=XLOOKUP(E16,'Đơn giá'!A:A,'Đơn giá'!D:D)} -> 37000 | AJ16: =AI16*J16 -> 8880 | AK16: =IF($W:$W="Hao hụt", AI16*N16, 0) -> 8880 | AL16: =IF($X:$X="Siêu thị", AI16*O16, 0) -> 0 | AM16: =IF($Y:$Y="Kho rau", AI16*P16, 0) -> 0 | AN16: =IF($Y:$Y="Chưa xác định", AI16*P16, 0) -> 0 | AO16: {=XLOOKUP($D:$D,'DS ST'!$J:$J,'DS ST'!K:K)} -> SC010667 - Đào Hồng Hiện | AP16: {=XLOOKUP($D:$D,'DS ST'!$J:$J,'DS ST'!L:L)} -> Nguyễn Thị Cà | AQ16: {=XLOOKUP($D:$D,'DS ST'!$J:$J,'DS ST'!M:M)} -> HCM 035 | AT16: {=xlookup($E:$E,'CLV2'!$A:$A,'CLV2'!$F:$F)} -> 3.LOCAL FRUITS | AU16: {=xlookup($E:$E,'CLV2'!$A:$A,'CLV2'!$G:$G)} -> 4.Dưa Lưới
B17: 46235 | C17: KFM_HCM_TDU - SH-1C 2 Đường A5 KDC Palm Residence | D17: =VLOOKUP(C17,'DS ST'!A:B,2,0) -> A207 | E17: 1101077 | F17: CHANH DÂY | G17: KG | H17: 3 | I17: 2.78 | J17: =H17-I17 -> 0.22 | K17: PT1598552 | L17: =K17&E17 -> PT15985521101077 | M17: TO227196 | P17: =H17-I17-N17-O17 -> 0.22 | T17: hình kdb | U17: Thiếu Item trong kiện | V17: DC giao thiếu | W17: =IF(VALUE(N17)<=0,"",IF(TRIM(V17)="Hao hụt","Hao hụt","Hao hụt")) | X17: =IF(AND(N(O17)>0,OR(V17="DC giao bù",V17="VT giao sai điểm",V17="ST nhập thiếu",V17="DC pick sai",V17="ST kiểm sai QT",V17="ST thông tin sai")),"Siêu thị","") | Y17: =IF(N(P17)<=0,"",IF(OR(T17="Hình KDB",T17="Hình tele",ISNUMBER(SEARCH("Hình KDB",T17)),ISNUMBER(SEARCH("Hình tele",T17)),ISNUMBER(SEARCH("sai code",T17)),ISNUMBER(SEARCH("Thiếu kiện",U17))),"Kho rau",IF(AND(T17<>"Hình KDB",T17<>"Hình tele"),"Chưa xác định",IF(N(O17)>0,IF(OR(T17="Hình KDB",T17="Hình tele",ISNUMBER(SEARCH("Hình KDB",T17)),ISNUMBER(SEARCH("Hình tele",T17)),ISNUMBER(SEARCH("sai code",T17)),ISNUMBER(SEARCH("Thiếu kiện",U17))),"Kho rau","Chưa xác định"),IF(OR(T17="Hình KDB",T17="Hình tele",ISNUMBER(SEARCH("Hình KDB",T17)),ISNUMBER(SEARCH("Hình tele",T17)),ISNUMBER(SEARCH("sai code",T17)),ISNUMBER(SEARCH("Thiếu kiện",U17))),"Kho rau",IF(V17="Chưa xác định","Chưa xác định",IF(OR(V17="DC giao thiếu",V17="TX giao thiếu kiện",V17="Hàng không đạt CL"),"Kho rau",""))))))) -> Kho rau | Z17: Hoàn Thành | AF17: {=xlookup($E:$E,'CLV2'!$A:$A,'CLV2'!E:E)} -> 2.FRUITS | AG17: =if(G17="KG","KG","Pack") -> KG | AH17: =J17/H17 -> 0.073333333 | AI17: {=XLOOKUP(E17,'Đơn giá'!A:A,'Đơn giá'!D:D)} -> 45000 | AJ17: =AI17*J17 -> 9900 | AK17: =IF($W:$W="Hao hụt", AI17*N17, 0) -> 0 | AL17: =IF($X:$X="Siêu thị", AI17*O17, 0) -> 0 | AM17: =IF($Y:$Y="Kho rau", AI17*P17, 0) -> 9900 | AN17: =IF($Y:$Y="Chưa xác định", AI17*P17, 0) -> 0 | AO17: {=XLOOKUP($D:$D,'DS ST'!$J:$J,'DS ST'!K:K)} -> SC010667 - Đào Hồng Hiện | AP17: {=XLOOKUP($D:$D,'DS ST'!$J:$J,'DS ST'!L:L)} -> Nguyễn Thị Cà | AQ17: {=XLOOKUP($D:$D,'DS ST'!$J:$J,'DS ST'!M:M)} -> HCM 035 | AT17: {=xlookup($E:$E,'CLV2'!$A:$A,'CLV2'!$F:$F)} -> 3.LOCAL FRUITS | AU17: {=xlookup($E:$E,'CLV2'!$A:$A,'CLV2'!$G:$G)} -> 4.Trái Cây Đa Dạng
B18: 46235 | C18: KFM_HCM_TDU - SH-1C 2 Đường A5 KDC Palm Residence | D18: =VLOOKUP(C18,'DS ST'!A:B,2,0) -> A207 | E18: 1101079 | F18: BƠ 034 | G18: KG | H18: 9.2 | I18: 9.06 | J18: =H18-I18 -> 0.14 | K18: PT1598552 | L18: =K18&E18 -> PT15985521101079 | M18: TO227196 | N18: 0.14 | P18: =H18-I18-N18-O18 -> 0 | T18: hình kdb | U18: Thiếu Item trong kiện | V18: Hao hụt | W18: =IF(VALUE(N18)<=0,"",IF(TRIM(V18)="Hao hụt","Hao hụt","Hao hụt")) -> Hao hụt | X18: =IF(AND(N(O18)>0,OR(V18="DC giao bù",V18="VT giao sai điểm",V18="ST nhập thiếu",V18="DC pick sai",V18="ST kiểm sai QT",V18="ST thông tin sai")),"Siêu thị","") | Y18: =IF(N(P18)<=0,"",IF(OR(T18="Hình KDB",T18="Hình tele",ISNUMBER(SEARCH("Hình KDB",T18)),ISNUMBER(SEARCH("Hình tele",T18)),ISNUMBER(SEARCH("sai code",T18)),ISNUMBER(SEARCH("Thiếu kiện",U18))),"Kho rau",IF(AND(T18<>"Hình KDB",T18<>"Hình tele"),"Chưa xác định",IF(N(O18)>0,IF(OR(T18="Hình KDB",T18="Hình tele",ISNUMBER(SEARCH("Hình KDB",T18)),ISNUMBER(SEARCH("Hình tele",T18)),ISNUMBER(SEARCH("sai code",T18)),ISNUMBER(SEARCH("Thiếu kiện",U18))),"Kho rau","Chưa xác định"),IF(OR(T18="Hình KDB",T18="Hình tele",ISNUMBER(SEARCH("Hình KDB",T18)),ISNUMBER(SEARCH("Hình tele",T18)),ISNUMBER(SEARCH("sai code",T18)),ISNUMBER(SEARCH("Thiếu kiện",U18))),"Kho rau",IF(V18="Chưa xác định","Chưa xác định",IF(OR(V18="DC giao thiếu",V18="TX giao thiếu kiện",V18="Hàng không đạt CL"),"Kho rau",""))))))) | Z18: Hoàn Thành | AF18: {=xlookup($E:$E,'CLV2'!$A:$A,'CLV2'!E:E)} -> 2.FRUITS | AG18: =if(G18="KG","KG","Pack") -> KG | AH18: =J18/H18 -> 0.015217391 | AI18: {=XLOOKUP(E18,'Đơn giá'!A:A,'Đơn giá'!D:D)} -> 69416 | AJ18: =AI18*J18 -> 9718.24 | AK18: =IF($W:$W="Hao hụt", AI18*N18, 0) -> 9718.24 | AL18: =IF($X:$X="Siêu thị", AI18*O18, 0) -> 0 | AM18: =IF($Y:$Y="Kho rau", AI18*P18, 0) -> 0 | AN18: =IF($Y:$Y="Chưa xác định", AI18*P18, 0) -> 0 | AO18: {=XLOOKUP($D:$D,'DS ST'!$J:$J,'DS ST'!K:K)} -> SC010667 - Đào Hồng Hiện | AP18: {=XLOOKUP($D:$D,'DS ST'!$J:$J,'DS ST'!L:L)} -> Nguyễn Thị Cà | AQ18: {=XLOOKUP($D:$D,'DS ST'!$J:$J,'DS ST'!M:M)} -> HCM 035 | AT18: {=xlookup($E:$E,'CLV2'!$A:$A,'CLV2'!$F:$F)} -> 3.LOCAL FRUITS | AU18: {=xlookup($E:$E,'CLV2'!$A:$A,'CLV2'!$G:$G)} -> 4.Bơ
B19: 46235 | C19: KFM_HCM_TDU - SH-1C 2 Đường A5 KDC Palm Residence | D19: =VLOOKUP(C19,'DS ST'!A:B,2,0) -> A207 | E19: 1101366 | F19: BÔNG CẢI XANH ĐÀ LẠT (KG) | G19: KG | H19: 4.1 | I19: 4.06 | J19: =H19-I19 -> 0.04 | K19: PT1598552 | L19: =K19&E19 -> PT15985521101366 | M19: TO227196 | N19: 0.04 | P19: =H19-I19-N19-O19 -> 0 | T19: hình kdb | U19: Thiếu Item trong kiện | V19: Hao hụt | W19: =IF(VALUE(N19)<=0,"",IF(TRIM(V19)="Hao hụt","Hao hụt","Hao hụt")) -> Hao hụt | X19: =IF(AND(N(O19)>0,OR(V19="DC giao bù",V19="VT giao sai điểm",V19="ST nhập thiếu",V19="DC pick sai",V19="ST kiểm sai QT",V19="ST thông tin sai")),"Siêu thị","") | Y19: =IF(N(P19)<=0,"",IF(OR(T19="Hình KDB",T19="Hình tele",ISNUMBER(SEARCH("Hình KDB",T19)),ISNUMBER(SEARCH("Hình tele",T19)),ISNUMBER(SEARCH("sai code",T19)),ISNUMBER(SEARCH("Thiếu kiện",U19))),"Kho rau",IF(AND(T19<>"Hình KDB",T19<>"Hình tele"),"Chưa xác định",IF(N(O19)>0,IF(OR(T19="Hình KDB",T19="Hình tele",ISNUMBER(SEARCH("Hình KDB",T19)),ISNUMBER(SEARCH("Hình tele",T19)),ISNUMBER(SEARCH("sai code",T19)),ISNUMBER(SEARCH("Thiếu kiện",U19))),"Kho rau","Chưa xác định"),IF(OR(T19="Hình KDB",T19="Hình tele",ISNUMBER(SEARCH("Hình KDB",T19)),ISNUMBER(SEARCH("Hình tele",T19)),ISNUMBER(SEARCH("sai code",T19)),ISNUMBER(SEARCH("Thiếu kiện",U19))),"Kho rau",IF(V19="Chưa xác định","Chưa xác định",IF(OR(V19="DC giao thiếu",V19="TX giao thiếu kiện",V19="Hàng không đạt CL"),"Kho rau",""))))))) | Z19: Hoàn Thành | AF19: {=xlookup($E:$E,'CLV2'!$A:$A,'CLV2'!E:E)} -> 2.VEGETABLES | AG19: =if(G19="KG","KG","Pack") -> KG | AH19: =J19/H19 -> 0.0097560976 | AI19: {=XLOOKUP(E19,'Đơn giá'!A:A,'Đơn giá'!D:D)} -> 55000 | AJ19: =AI19*J19 -> 2200 | AK19: =IF($W:$W="Hao hụt", AI19*N19, 0) -> 2200 | AL19: =IF($X:$X="Siêu thị", AI19*O19, 0) -> 0 | AM19: =IF($Y:$Y="Kho rau", AI19*P19, 0) -> 0 | AN19: =IF($Y:$Y="Chưa xác định", AI19*P19, 0) -> 0 | AO19: {=XLOOKUP($D:$D,'DS ST'!$J:$J,'DS ST'!K:K)} -> SC010667 - Đào Hồng Hiện | AP19: {=XLOOKUP($D:$D,'DS ST'!$J:$J,'DS ST'!L:L)} -> Nguyễn Thị Cà | AQ19: {=XLOOKUP($D:$D,'DS ST'!$J:$J,'DS ST'!M:M)} -> HCM 035 | AT19: {=xlookup($E:$E,'CLV2'!$A:$A,'CLV2'!$F:$F)} -> 3.LEAFY VEGGIES | AU19: {=xlookup($E:$E,'CLV2'!$A:$A,'CLV2'!$G:$G)} -> 4.Rau Ăn Bông
B20: 46235 | C20: KFM_HCM_GVA - 372 Dương Quảng Hàm | D20: =VLOOKUP(C20,'DS ST'!A:B,2,0) -> DQH | E20: 11020 | F20: CHANH VÀNG NỘI ĐỊA TRUNG 140G up | G20: QUẢ | H20: 4 | I20: 2 | J20: =H20-I20 -> 2 | K20: PT1598543 | L20: =K20&E20 -> PT159854311020 | M20: TO227542 | P20: =H20-I20-N20-O20 -> 2 | U20: Thiếu Item trong kiện | V20: DC giao thiếu | W20: =IF(VALUE(N20)<=0,"",IF(TRIM(V20)="Hao hụt","Hao hụt","Hao hụt")) | X20: =IF(AND(N(O20)>0,OR(V20="DC giao bù",V20="VT giao sai điểm",V20="ST nhập thiếu",V20="DC pick sai",V20="ST kiểm sai QT",V20="ST thông tin sai")),"Siêu thị","") | Y20: Kho rau | Z20: Hoàn Thành | AF20: {=xlookup($E:$E,'CLV2'!$A:$A,'CLV2'!E:E)} -> 2.VEGETABLES | AG20: =if(G20="KG","KG","Pack") -> Pack | AH20: =J20/H20 -> 0.5 | AI20: {=XLOOKUP(E20,'Đơn giá'!A:A,'Đơn giá'!D:D)} -> 17000 | AJ20: =AI20*J20 -> 34000 | AK20: =IF($W:$W="Hao hụt", AI20*N20, 0) -> 0 | AL20: =IF($X:$X="Siêu thị", AI20*O20, 0) -> 0 | AM20: =IF($Y:$Y="Kho rau", AI20*P20, 0) -> 34000 | AN20: =IF($Y:$Y="Chưa xác định", AI20*P20, 0) -> 0 | AO20: {=XLOOKUP($D:$D,'DS ST'!$J:$J,'DS ST'!K:K)} -> SC006189 - Huỳnh Ngọc Phương | AP20: {=XLOOKUP($D:$D,'DS ST'!$J:$J,'DS ST'!L:L)} -> Nguyễn Thị Cà | AQ20: {=XLOOKUP($D:$D,'DS ST'!$J:$J,'DS ST'!M:M)} -> HCM 033 | AT20: {=xlookup($E:$E,'CLV2'!$A:$A,'CLV2'!$F:$F)} -> 3.HERBS | AU20: {=xlookup($E:$E,'CLV2'!$A:$A,'CLV2'!$G:$G)} -> 4.Chanh, Ớt
B21: 46235 | C21: KFM_HCM_GVA - 372 Dương Quảng Hàm | D21: =VLOOKUP(C21,'DS ST'!A:B,2,0) -> DQH | E21: 1101077 | F21: CHANH DÂY | G21: KG | H21: 3 | I21: 2.92 | J21: =H21-I21 -> 0.08 | K21: PT1598543 | L21: =K21&E21 -> PT15985431101077 | M21: TO227542 | N21: 0.08 | P21: =H21-I21-N21-O21 -> 0 | T21: hình kdb | U21: Thiếu Item trong kiện | V21: Hao hụt | W21: =IF(VALUE(N21)<=0,"",IF(TRIM(V21)="Hao hụt","Hao hụt","Hao hụt")) -> Hao hụt | X21: =IF(AND(N(O21)>0,OR(V21="DC giao bù",V21="VT giao sai điểm",V21="ST nhập thiếu",V21="DC pick sai",V21="ST kiểm sai QT",V21="ST thông tin sai")),"Siêu thị","") | Y21: =IF(N(P21)<=0,"",IF(OR(T21="Hình KDB",T21="Hình tele",ISNUMBER(SEARCH("Hình KDB",T21)),ISNUMBER(SEARCH("Hình tele",T21)),ISNUMBER(SEARCH("sai code",T21)),ISNUMBER(SEARCH("Thiếu kiện",U21))),"Kho rau",IF(AND(T21<>"Hình KDB",T21<>"Hình tele"),"Chưa xác định",IF(N(O21)>0,IF(OR(T21="Hình KDB",T21="Hình tele",ISNUMBER(SEARCH("Hình KDB",T21)),ISNUMBER(SEARCH("Hình tele",T21)),ISNUMBER(SEARCH("sai code",T21)),ISNUMBER(SEARCH("Thiếu kiện",U21))),"Kho rau","Chưa xác định"),IF(OR(T21="Hình KDB",T21="Hình tele",ISNUMBER(SEARCH("Hình KDB",T21)),ISNUMBER(SEARCH("Hình tele",T21)),ISNUMBER(SEARCH("sai code",T21)),ISNUMBER(SEARCH("Thiếu kiện",U21))),"Kho rau",IF(V21="Chưa xác định","Chưa xác định",IF(OR(V21="DC giao thiếu",V21="TX giao thiếu kiện",V21="Hàng không đạt CL"),"Kho rau",""))))))) | Z21: Hoàn Thành | AF21: {=xlookup($E:$E,'CLV2'!$A:$A,'CLV2'!E:E)} -> 2.FRUITS | AG21: =if(G21="KG","KG","Pack") -> KG | AH21: =J21/H21 -> 0.026666667 | AI21: {=XLOOKUP(E21,'Đơn giá'!A:A,'Đơn giá'!D:D)} -> 45000 | AJ21: =AI21*J21 -> 3600 | AK21: =IF($W:$W="Hao hụt", AI21*N21, 0) -> 3600 | AL21: =IF($X:$X="Siêu thị", AI21*O21, 0) -> 0 | AM21: =IF($Y:$Y="Kho rau", AI21*P21, 0) -> 0 | AN21: =IF($Y:$Y="Chưa xác định", AI21*P21, 0) -> 0 | AO21: {=XLOOKUP($D:$D,'DS ST'!$J:$J,'DS ST'!K:K)} -> SC006189 - Huỳnh Ngọc Phương | AP21: {=XLOOKUP($D:$D,'DS ST'!$J:$J,'DS ST'!L:L)} -> Nguyễn Thị Cà | AQ21: {=XLOOKUP($D:$D,'DS ST'!$J:$J,'DS ST'!M:M)} -> HCM 033 | AT21: {=xlookup($E:$E,'CLV2'!$A:$A,'CLV2'!$F:$F)} -> 3.LOCAL FRUITS | AU21: {=xlookup($E:$E,'CLV2'!$A:$A,'CLV2'!$G:$G)} -> 4.Trái Cây Đa Dạng
B22: 46235 | C22: KFM_HCM_GVA - 372 Dương Quảng Hàm | D22: =VLOOKUP(C22,'DS ST'!A:B,2,0) -> DQH | E22: 1101366 | F22: BÔNG CẢI XANH ĐÀ LẠT (KG) | G22: KG | H22: 8.3 | I22: 8.18 | J22: =H22-I22 -> 0.12 | K22: PT1598543 | L22: =K22&E22 -> PT15985431101366 | M22: TO227542 | N22: 0.12 | P22: =H22-I22-N22-O22 -> 0 | T22: hình kdb | U22: Thiếu Item trong kiện | V22: Hao hụt | W22: =IF(VALUE(N22)<=0,"",IF(TRIM(V22)="Hao hụt","Hao hụt","Hao hụt")) -> Hao hụt | X22: =IF(AND(N(O22)>0,OR(V22="DC giao bù",V22="VT giao sai điểm",V22="ST nhập thiếu",V22="DC pick sai",V22="ST kiểm sai QT",V22="ST thông tin sai")),"Siêu thị","") | Y22: =IF(N(P22)<=0,"",IF(OR(T22="Hình KDB",T22="Hình tele",ISNUMBER(SEARCH("Hình KDB",T22)),ISNUMBER(SEARCH("Hình tele",T22)),ISNUMBER(SEARCH("sai code",T22)),ISNUMBER(SEARCH("Thiếu kiện",U22))),"Kho rau",IF(AND(T22<>"Hình KDB",T22<>"Hình tele"),"Chưa xác định",IF(N(O22)>0,IF(OR(T22="Hình KDB",T22="Hình tele",ISNUMBER(SEARCH("Hình KDB",T22)),ISNUMBER(SEARCH("Hình tele",T22)),ISNUMBER(SEARCH("sai code",T22)),ISNUMBER(SEARCH("Thiếu kiện",U22))),"Kho rau","Chưa xác định"),IF(OR(T22="Hình KDB",T22="Hình tele",ISNUMBER(SEARCH("Hình KDB",T22)),ISNUMBER(SEARCH("Hình tele",T22)),ISNUMBER(SEARCH("sai code",T22)),ISNUMBER(SEARCH("Thiếu kiện",U22))),"Kho rau",IF(V22="Chưa xác định","Chưa xác định",IF(OR(V22="DC giao thiếu",V22="TX giao thiếu kiện",V22="Hàng không đạt CL"),"Kho rau",""))))))) | Z22: Hoàn Thành | AF22: {=xlookup($E:$E,'CLV2'!$A:$A,'CLV2'!E:E)} -> 2.VEGETABLES | AG22: =if(G22="KG","KG","Pack") -> KG | AH22: =J22/H22 -> 0.014457831 | AI22: {=XLOOKUP(E22,'Đơn giá'!A:A,'Đơn giá'!D:D)} -> 55000 | AJ22: =AI22*J22 -> 6600 | AK22: =IF($W:$W="Hao hụt", AI22*N22, 0) -> 6600 | AL22: =IF($X:$X="Siêu thị", AI22*O22, 0) -> 0 | AM22: =IF($Y:$Y="Kho rau", AI22*P22, 0) -> 0 | AN22: =IF($Y:$Y="Chưa xác định", AI22*P22, 0) -> 0 | AO22: {=XLOOKUP($D:$D,'DS ST'!$J:$J,'DS ST'!K:K)} -> SC006189 - Huỳnh Ngọc Phương | AP22: {=XLOOKUP($D:$D,'DS ST'!$J:$J,'DS ST'!L:L)} -> Nguyễn Thị Cà | AQ22: {=XLOOKUP($D:$D,'DS ST'!$J:$J,'DS ST'!M:M)} -> HCM 033 | AT22: {=xlookup($E:$E,'CLV2'!$A:$A,'CLV2'!$F:$F)} -> 3.LEAFY VEGGIES | AU22: {=xlookup($E:$E,'CLV2'!$A:$A,'CLV2'!$G:$G)} -> 4.Rau Ăn Bông
B23: 46235 | C23: KFM_HCM_Q07 - 1016/21 Chung Cư Sky Garden 2-R1-2 | D23: =VLOOKUP(C23,'DS ST'!A:B,2,0) -> A177 | E23: 10793 | F23: DIẾP CÁ (DẤP CÁ) VIETGAP 100G | G23: GÓI | H23: 2 | I23: 0 | J23: =H23-I23 -> 2 | K23: PT1598541 | L23: =K23&E23 -> PT159854110793 | M23: TO227323 | P23: =H23-I23-N23-O23 -> 2 | U23: Thiếu Item trong kiện | V23: DC giao thiếu | W23: =IF(VALUE(N23)<=0,"",IF(TRIM(V23)="Hao hụt","Hao hụt","Hao hụt")) | X23: =IF(AND(N(O23)>0,OR(V23="DC giao bù",V23="VT giao sai điểm",V23="ST nhập thiếu",V23="DC pick sai",V23="ST kiểm sai QT",V23="ST thông tin sai")),"Siêu thị","") | Y23: Kho rau | Z23: Hoàn Thành | AF23: {=xlookup($E:$E,'CLV2'!$A:$A,'CLV2'!E:E)} -> 2.VEGETABLES | AG23: =if(G23="KG","KG","Pack") -> Pack | AH23: =J23/H23 -> 1 | AI23: {=XLOOKUP(E23,'Đơn giá'!A:A,'Đơn giá'!D:D)} -> 5500 | AJ23: =AI23*J23 -> 11000 | AK23: =IF($W:$W="Hao hụt", AI23*N23, 0) -> 0 | AL23: =IF($X:$X="Siêu thị", AI23*O23, 0) -> 0 | AM23: =IF($Y:$Y="Kho rau", AI23*P23, 0) -> 11000 | AN23: =IF($Y:$Y="Chưa xác định", AI23*P23, 0) -> 0 | AO23: {=XLOOKUP($D:$D,'DS ST'!$J:$J,'DS ST'!K:K)} -> SC005377 - Nguyễn Minh Thắng | AP23: {=XLOOKUP($D:$D,'DS ST'!$J:$J,'DS ST'!L:L)} -> Võ Thị Huệ | AQ23: {=XLOOKUP($D:$D,'DS ST'!$J:$J,'DS ST'!M:M)} -> HCM 001 | AT23: {=xlookup($E:$E,'CLV2'!$A:$A,'CLV2'!$F:$F)} -> 3.HERBS | AU23: {=xlookup($E:$E,'CLV2'!$A:$A,'CLV2'!$G:$G)} -> 4.Rau Thơm, Rau Nêm
B24: 46235 | C24: KFM_HCM_Q07 - 1016/21 Chung Cư Sky Garden 2-R1-2 | D24: =VLOOKUP(C24,'DS ST'!A:B,2,0) -> A177 | E24: 1101992 | F24: XOÀI TỨ QUÝ | G24: KG | H24: 2 | I24: 1.6 | J24: =H24-I24 -> 0.4 | K24: PT1598541 | L24: =K24&E24 -> PT15985411101992 | M24: TO227323 | P24: =H24-I24-N24-O24 -> 0.4 | T24: hình kdb | U24: Thiếu Item trong kiện | V24: DC giao thiếu | W24: =IF(VALUE(N24)<=0,"",IF(TRIM(V24)="Hao hụt","Hao hụt","Hao hụt")) | X24: =IF(AND(N(O24)>0,OR(V24="DC giao bù",V24="VT giao sai điểm",V24="ST nhập thiếu",V24="DC pick sai",V24="ST kiểm sai QT",V24="ST thông tin sai")),"Siêu thị","") | Y24: =IF(N(P24)<=0,"",IF(OR(T24="Hình KDB",T24="Hình tele",ISNUMBER(SEARCH("Hình KDB",T24)),ISNUMBER(SEARCH("Hình tele",T24)),ISNUMBER(SEARCH("sai code",T24)),ISNUMBER(SEARCH("Thiếu kiện",U24))),"Kho rau",IF(AND(T24<>"Hình KDB",T24<>"Hình tele"),"Chưa xác định",IF(N(O24)>0,IF(OR(T24="Hình KDB",T24="Hình tele",ISNUMBER(SEARCH("Hình KDB",T24)),ISNUMBER(SEARCH("Hình tele",T24)),ISNUMBER(SEARCH("sai code",T24)),ISNUMBER(SEARCH("Thiếu kiện",U24))),"Kho rau","Chưa xác định"),IF(OR(T24="Hình KDB",T24="Hình tele",ISNUMBER(SEARCH("Hình KDB",T24)),ISNUMBER(SEARCH("Hình tele",T24)),ISNUMBER(SEARCH("sai code",T24)),ISNUMBER(SEARCH("Thiếu kiện",U24))),"Kho rau",IF(V24="Chưa xác định","Chưa xác định",IF(OR(V24="DC giao thiếu",V24="TX giao thiếu kiện",V24="Hàng không đạt CL"),"Kho rau",""))))))) -> Kho rau | Z24: Hoàn Thành | AF24: {=xlookup($E:$E,'CLV2'!$A:$A,'CLV2'!E:E)} -> 2.FRUITS | AG24: =if(G24="KG","KG","Pack") -> KG | AH24: =J24/H24 -> 0.2 | AI24: {=XLOOKUP(E24,'Đơn giá'!A:A,'Đơn giá'!D:D)} -> 37000 | AJ24: =AI24*J24 -> 14800 | AK24: =IF($W:$W="Hao hụt", AI24*N24, 0) -> 0 | AL24: =IF($X:$X="Siêu thị", AI24*O24, 0) -> 0 | AM24: =IF($Y:$Y="Kho rau", AI24*P24, 0) -> 14800 | AN24: =IF($Y:$Y="Chưa xác định", AI24*P24, 0) -> 0 | AO24: {=XLOOKUP($D:$D,'DS ST'!$J:$J,'DS ST'!K:K)} -> SC005377 - Nguyễn Minh Thắng | AP24: {=XLOOKUP($D:$D,'DS ST'!$J:$J,'DS ST'!L:L)} -> Võ Thị Huệ | AQ24: {=XLOOKUP($D:$D,'DS ST'!$J:$J,'DS ST'!M:M)} -> HCM 001 | AT24: {=xlookup($E:$E,'CLV2'!$A:$A,'CLV2'!$F:$F)} -> 3.LOCAL FRUITS | AU24: {=xlookup($E:$E,'CLV2'!$A:$A,'CLV2'!$G:$G)} -> 4.Xoài
B25: 46235 | C25: KFM_HCM_GVA - 8 Nguyễn Văn Dung | D25: =VLOOKUP(C25,'DS ST'!A:B,2,0) -> A224 | E25: 11373 | F25: RAU THƠM HỖN HỢP VIETGAP 100G | G25: GÓI | H25: 2 | I25: 1 | J25: =H25-I25 -> 1 | K25: PT1598539 | L25: =K25&E25 -> PT159853911373 | M25: TO227292 | P25: =H25-I25-N25-O25 -> 1 | T25: hình kdb | U25: Thiếu Item trong kiện | V25: DC giao thiếu | W25: =IF(VALUE(N25)<=0,"",IF(TRIM(V25)="Hao hụt","Hao hụt","Hao hụt")) | X25: =IF(AND(N(O25)>0,OR(V25="DC giao bù",V25="VT giao sai điểm",V25="ST nhập thiếu",V25="DC pick sai",V25="ST kiểm sai QT",V25="ST thông tin sai")),"Siêu thị","") | Y25: =IF(N(P25)<=0,"",IF(OR(T25="Hình KDB",T25="Hình tele",ISNUMBER(SEARCH("Hình KDB",T25)),ISNUMBER(SEARCH("Hình tele",T25)),ISNUMBER(SEARCH("sai code",T25)),ISNUMBER(SEARCH("Thiếu kiện",U25))),"Kho rau",IF(AND(T25<>"Hình KDB",T25<>"Hình tele"),"Chưa xác định",IF(N(O25)>0,IF(OR(T25="Hình KDB",T25="Hình tele",ISNUMBER(SEARCH("Hình KDB",T25)),ISNUMBER(SEARCH("Hình tele",T25)),ISNUMBER(SEARCH("sai code",T25)),ISNUMBER(SEARCH("Thiếu kiện",U25))),"Kho rau","Chưa xác định"),IF(OR(T25="Hình KDB",T25="Hình tele",ISNUMBER(SEARCH("Hình KDB",T25)),ISNUMBER(SEARCH("Hình tele",T25)),ISNUMBER(SEARCH("sai code",T25)),ISNUMBER(SEARCH("Thiếu kiện",U25))),"Kho rau",IF(V25="Chưa xác định","Chưa xác định",IF(OR(V25="DC giao thiếu",V25="TX giao thiếu kiện",V25="Hàng không đạt CL"),"Kho rau",""))))))) -> Kho rau | Z25: Hoàn Thành | AF25: {=xlookup($E:$E,'CLV2'!$A:$A,'CLV2'!E:E)} -> 2.VEGETABLES | AG25: =if(G25="KG","KG","Pack") -> Pack | AH25: =J25/H25 -> 0.5 | AI25: {=XLOOKUP(E25,'Đơn giá'!A:A,'Đơn giá'!D:D)} -> 8500 | AJ25: =AI25*J25 -> 8500 | AK25: =IF($W:$W="Hao hụt", AI25*N25, 0) -> 0 | AL25: =IF($X:$X="Siêu thị", AI25*O25, 0) -> 0 | AM25: =IF($Y:$Y="Kho rau", AI25*P25, 0) -> 8500 | AN25: =IF($Y:$Y="Chưa xác định", AI25*P25, 0) -> 0 | AO25: {=XLOOKUP($D:$D,'DS ST'!$J:$J,'DS ST'!K:K)} | AP25: {=XLOOKUP($D:$D,'DS ST'!$J:$J,'DS ST'!L:L)} | AQ25: {=XLOOKUP($D:$D,'DS ST'!$J:$J,'DS ST'!M:M)} | AT25: {=xlookup($E:$E,'CLV2'!$A:$A,'CLV2'!$F:$F)} -> 3.HERBS | AU25: {=xlookup($E:$E,'CLV2'!$A:$A,'CLV2'!$G:$G)} -> 4.Rau Thơm, Rau Nêm
B26: 46235 | C26: KFM_BDU_DAN - 01-06 TMDV Him Lam Phú Đông | D26: =VLOOKUP(C26,'DS ST'!A:B,2,0) -> HPD | E26: 1101992 | F26: XOÀI TỨ QUÝ | G26: KG | H26: 3 | I26: 2.98 | J26: =H26-I26 -> 0.02 | K26: PT1598531 | L26: =K26&E26 -> PT15985311101992 | M26: TO227307 | N26: 0.02 | P26: =H26-I26-N26-O26 -> 0 | T26: hình kdb | U26: Thiếu Item trong kiện | V26: Hao hụt | W26: =IF(VALUE(N26)<=0,"",IF(TRIM(V26)="Hao hụt","Hao hụt","Hao hụt")) -> Hao hụt | X26: =IF(AND(N(O26)>0,OR(V26="DC giao bù",V26="VT giao sai điểm",V26="ST nhập thiếu",V26="DC pick sai",V26="ST kiểm sai QT",V26="ST thông tin sai")),"Siêu thị","") | Y26: =IF(N(P26)<=0,"",IF(OR(T26="Hình KDB",T26="Hình tele",ISNUMBER(SEARCH("Hình KDB",T26)),ISNUMBER(SEARCH("Hình tele",T26)),ISNUMBER(SEARCH("sai code",T26)),ISNUMBER(SEARCH("Thiếu kiện",U26))),"Kho rau",IF(AND(T26<>"Hình KDB",T26<>"Hình tele"),"Chưa xác định",IF(N(O26)>0,IF(OR(T26="Hình KDB",T26="Hình tele",ISNUMBER(SEARCH("Hình KDB",T26)),ISNUMBER(SEARCH("Hình tele",T26)),ISNUMBER(SEARCH("sai code",T26)),ISNUMBER(SEARCH("Thiếu kiện",U26))),"Kho rau","Chưa xác định"),IF(OR(T26="Hình KDB",T26="Hình tele",ISNUMBER(SEARCH("Hình KDB",T26)),ISNUMBER(SEARCH("Hình tele",T26)),ISNUMBER(SEARCH("sai code",T26)),ISNUMBER(SEARCH("Thiếu kiện",U26))),"Kho rau",IF(V26="Chưa xác định","Chưa xác định",IF(OR(V26="DC giao thiếu",V26="TX giao thiếu kiện",V26="Hàng không đạt CL"),"Kho rau",""))))))) | Z26: Hoàn Thành | AF26: {=xlookup($E:$E,'CLV2'!$A:$A,'CLV2'!E:E)} -> 2.FRUITS | AG26: =if(G26="KG","KG","Pack") -> KG | AH26: =J26/H26 -> 0.0066666667 | AI26: {=XLOOKUP(E26,'Đơn giá'!A:A,'Đơn giá'!D:D)} -> 37000 | AJ26: =AI26*J26 -> 740 | AK26: =IF($W:$W="Hao hụt", AI26*N26, 0) -> 740 | AL26: =IF($X:$X="Siêu thị", AI26*O26, 0) -> 0 | AM26: =IF($Y:$Y="Kho rau", AI26*P26, 0) -> 0 | AN26: =IF($Y:$Y="Chưa xác định", AI26*P26, 0) -> 0 | AO26: {=XLOOKUP($D:$D,'DS ST'!$J:$J,'DS ST'!K:K)} -> SC011505 - Lê Ngọc Phát | AP26: {=XLOOKUP($D:$D,'DS ST'!$J:$J,'DS ST'!L:L)} -> Nguyễn Thị Cà | AQ26: {=XLOOKUP($D:$D,'DS ST'!$J:$J,'DS ST'!M:M)} -> HCM 027 | AT26: {=xlookup($E:$E,'CLV2'!$A:$A,'CLV2'!$F:$F)} -> 3.LOCAL FRUITS | AU26: {=xlookup($E:$E,'CLV2'!$A:$A,'CLV2'!$G:$G)} -> 4.Xoài
B27: 46235 | C27: KFM_HCM_TPH - RS4 Richstar | D27: =VLOOKUP(C27,'DS ST'!A:B,2,0) -> RS4 | E27: 1101366 | F27: BÔNG CẢI XANH ĐÀ LẠT (KG) | G27: KG | H27: 4.2 | I27: 4 | J27: =H27-I27 -> 0.2 | K27: PT1598529 | L27: =K27&E27 -> PT15985291101366 | M27: TO227343 | N27: 0.11 | O27: 0.09 | P27: =H27-I27-N27-O27 -> 0 | Q27: PT1601999 | R27: x | T27: HÌnh kdb | U27: Thiếu Item trong kiện | V27: ST nhập thiếu | W27: =IF(VALUE(N27)<=0,"",IF(TRIM(V27)="Hao hụt","Hao hụt","Hao hụt")) -> Hao hụt | X27: =IF(AND(N(O27)>0,OR(V27="DC giao bù",V27="VT giao sai điểm",V27="ST nhập thiếu",V27="DC pick sai",V27="ST kiểm sai QT",V27="ST thông tin sai")),"Siêu thị","") -> Siêu thị | Y27: Kho rau | Z27: Hoàn Thành | AF27: {=xlookup($E:$E,'CLV2'!$A:$A,'CLV2'!E:E)} -> 2.VEGETABLES | AG27: =if(G27="KG","KG","Pack") -> KG | AH27: =J27/H27 -> 0.047619048 | AI27: {=XLOOKUP(E27,'Đơn giá'!A:A,'Đơn giá'!D:D)} -> 55000 | AJ27: =AI27*J27 -> 11000 | AK27: =IF($W:$W="Hao hụt", AI27*N27, 0) -> 6050 | AL27: =IF($X:$X="Siêu thị", AI27*O27, 0) -> 4950 | AM27: =IF($Y:$Y="Kho rau", AI27*P27, 0) -> 0 | AN27: =IF($Y:$Y="Chưa xác định", AI27*P27, 0) -> 0 | AO27: {=XLOOKUP($D:$D,'DS ST'!$J:$J,'DS ST'!K:K)} -> SC005375 - Trần Văn Hiếu | AP27: {=XLOOKUP($D:$D,'DS ST'!$J:$J,'DS ST'!L:L)} -> Võ Thị Huệ | AQ27: {=XLOOKUP($D:$D,'DS ST'!$J:$J,'DS ST'!M:M)} -> HCM 014 | AT27: {=xlookup($E:$E,'CLV2'!$A:$A,'CLV2'!$F:$F)} -> 3.LEAFY VEGGIES | AU27: {=xlookup($E:$E,'CLV2'!$A:$A,'CLV2'!$G:$G)} -> 4.Rau Ăn Bông
A28: Như | B28: 46235 | C28: KFM_HCM_TPH - RS4 Richstar | D28: =VLOOKUP(C28,'DS ST'!A:B,2,0) -> RS4 | E28: 8936192440282 | F28: VFARM - TRỨNG GÀ LÒNG ĐỎ ĐẬM MÀU (VỈ 10 QUẢ) | G28: VỈ | H28: 8 | I28: 4 | J28: =H28-I28 -> 4 | K28: PT1598529 | L28: =K28&E28 -> PT15985298936192440282 | M28: TO227343 | P28: =H28-I28-N28-O28 -> 4 | R28: x | T28: HÌnh kdb | U28: Thiếu Item trong kiện | V28: DC giao thiếu | W28: =IF(VALUE(N28)<=0,"",IF(TRIM(V28)="Hao hụt","Hao hụt","Hao hụt")) | X28: =IF(AND(N(O28)>0,OR(V28="DC giao bù",V28="VT giao sai điểm",V28="ST nhập thiếu",V28="DC pick sai",V28="ST kiểm sai QT",V28="ST thông tin sai")),"Siêu thị","") | Y28: =IF(N(P28)<=0,"",IF(OR(T28="Hình KDB",T28="Hình tele",ISNUMBER(SEARCH("Hình KDB",T28)),ISNUMBER(SEARCH("Hình tele",T28)),ISNUMBER(SEARCH("sai code",T28)),ISNUMBER(SEARCH("Thiếu kiện",U28))),"Kho rau",IF(AND(T28<>"Hình KDB",T28<>"Hình tele"),"Chưa xác định",IF(N(O28)>0,IF(OR(T28="Hình KDB",T28="Hình tele",ISNUMBER(SEARCH("Hình KDB",T28)),ISNUMBER(SEARCH("Hình tele",T28)),ISNUMBER(SEARCH("sai code",T28)),ISNUMBER(SEARCH("Thiếu kiện",U28))),"Kho rau","Chưa xác định"),IF(OR(T28="Hình KDB",T28="Hình tele",ISNUMBER(SEARCH("Hình KDB",T28)),ISNUMBER(SEARCH("Hình tele",T28)),ISNUMBER(SEARCH("sai code",T28)),ISNUMBER(SEARCH("Thiếu kiện",U28))),"Kho rau",IF(V28="Chưa xác định","Chưa xác định",IF(OR(V28="DC giao thiếu",V28="TX giao thiếu kiện",V28="Hàng không đạt CL"),"Kho rau",""))))))) -> Kho rau | Z28: Hoàn Thành | AB28: Đồng ý claim | AF28: {=xlookup($E:$E,'CLV2'!$A:$A,'CLV2'!E:E)} -> 2.EGGS | AG28: =if(G28="KG","KG","Pack") -> Pack | AH28: =J28/H28 -> 0.5 | AI28: {=XLOOKUP(E28,'Đơn giá'!A:A,'Đơn giá'!D:D)} -> 29043 | AJ28: =AI28*J28 -> 116172 | AK28: =IF($W:$W="Hao hụt", AI28*N28, 0) -> 0 | AL28: =IF($X:$X="Siêu thị", AI28*O28, 0) -> 0 | AM28: =IF($Y:$Y="Kho rau", AI28*P28, 0) -> 116172 | AN28: =IF($Y:$Y="Chưa xác định", AI28*P28, 0) -> 0 | AO28: {=XLOOKUP($D:$D,'DS ST'!$J:$J,'DS ST'!K:K)} -> SC005375 - Trần Văn Hiếu | AP28: {=XLOOKUP($D:$D,'DS ST'!$J:$J,'DS ST'!L:L)} -> Võ Thị Huệ | AQ28: {=XLOOKUP($D:$D,'DS ST'!$J:$J,'DS ST'!M:M)} -> HCM 014 | AT28: {=xlookup($E:$E,'CLV2'!$A:$A,'CLV2'!$F:$F)} -> 3.FRESH EGGS | AU28: {=xlookup($E:$E,'CLV2'!$A:$A,'CLV2'!$G:$G)} -> 4.Trứng Gà Khác
B29: 46235 | C29: KFM_HCM_BTH - 61 Bùi Đình Túy | D29: =VLOOKUP(C29,'DS ST'!A:B,2,0) -> A192 | E29: 1101062 | F29: CHUỐI LABA ĐÀ LẠT | G29: KG | H29: 10.1 | I29: 10.06 | J29: =H29-I29 -> 0.04 | K29: PT1598524 | L29: =K29&E29 -> PT15985241101062 | M29: TO227159 | O29: 0.04 | P29: =H29-I29-N29-O29 -> 0 | Q29: PT1605691 | U29: Thiếu Item trong kiện | V29: ST kiểm sai QT | W29: =IF(VALUE(N29)<=0,"",IF(TRIM(V29)="Hao hụt","Hao hụt","Hao hụt")) | X29: Siêu thị | Z29: Hoàn Thành | AF29: {=xlookup($E:$E,'CLV2'!$A:$A,'CLV2'!E:E)} -> 2.FRUITS | AG29: =if(G29="KG","KG","Pack") -> KG | AH29: =J29/H29 -> 0.003960396 | AI29: {=XLOOKUP(E29,'Đơn giá'!A:A,'Đơn giá'!D:D)} -> 23000 | AJ29: =AI29*J29 -> 920 | AK29: =IF($W:$W="Hao hụt", AI29*N29, 0) -> 0 | AL29: =IF($X:$X="Siêu thị", AI29*O29, 0) -> 920 | AM29: =IF($Y:$Y="Kho rau", AI29*P29, 0) -> 0 | AN29: =IF($Y:$Y="Chưa xác định", AI29*P29, 0) -> 0 | AO29: {=XLOOKUP($D:$D,'DS ST'!$J:$J,'DS ST'!K:K)} -> SC009915 - Đoàn Ngọc Thịnh | AP29: {=XLOOKUP($D:$D,'DS ST'!$J:$J,'DS ST'!L:L)} -> Nguyễn Thị Cà | AQ29: {=XLOOKUP($D:$D,'DS ST'!$J:$J,'DS ST'!M:M)} -> HCM 025 | AT29: {=xlookup($E:$E,'CLV2'!$A:$A,'CLV2'!$F:$F)} -> 3.LOCAL FRUITS | AU29: {=xlookup($E:$E,'CLV2'!$A:$A,'CLV2'!$G:$G)} -> 4.Chuối
B30: 46235 | C30: KFM_HCM_TPH - 83 Khuông Việt | D30: =VLOOKUP(C30,'DS ST'!A:B,2,0) -> A143 | E30: 1100917 | F30: BÍ ĐỎ TRÒN | G30: KG | H30: 7.1 | I30: 6.96 | J30: =H30-I30 -> 0.14 | K30: PT1598522 | L30: =K30&E30 -> PT15985221100917 | M30: TO227201 | N30: 0.14 | P30: =H30-I30-N30-O30 -> 0 | T30: hình kdb | U30: Thiếu Item trong kiện | V30: Hao hụt | W30: =IF(VALUE(N30)<=0,"",IF(TRIM(V30)="Hao hụt","Hao hụt","Hao hụt")) -> Hao hụt | X30: =IF(AND(N(O30)>0,OR(V30="DC giao bù",V30="VT giao sai điểm",V30="ST nhập thiếu",V30="DC pick sai",V30="ST kiểm sai QT",V30="ST thông tin sai")),"Siêu thị","") | Y30: Kho rau | Z30: Hoàn Thành | AF30: {=xlookup($E:$E,'CLV2'!$A:$A,'CLV2'!E:E)} -> 2.VEGETABLES | AG30: =if(G30="KG","KG","Pack") -> KG | AH30: =J30/H30 -> 0.01971831 | AI30: {=XLOOKUP(E30,'Đơn giá'!A:A,'Đơn giá'!D:D)} -> 24500 | AJ30: =AI30*J30 -> 3430 | AK30: =IF($W:$W="Hao hụt", AI30*N30, 0) -> 3430 | AL30: =IF($X:$X="Siêu thị", AI30*O30, 0) -> 0 | AM30: =IF($Y:$Y="Kho rau", AI30*P30, 0) -> 0 | AN30: =IF($Y:$Y="Chưa xác định", AI30*P30, 0) -> 0 | AO30: {=XLOOKUP($D:$D,'DS ST'!$J:$J,'DS ST'!K:K)} -> SC003733 - Trần Huỳnh Thơ | AP30: {=XLOOKUP($D:$D,'DS ST'!$J:$J,'DS ST'!L:L)} -> Võ Thị Huệ | AQ30: {=XLOOKUP($D:$D,'DS ST'!$J:$J,'DS ST'!M:M)} -> HCM 013 | AT30: {=xlookup($E:$E,'CLV2'!$A:$A,'CLV2'!$F:$F)} -> 3.FRUIT VEGGIES | AU30: {=xlookup($E:$E,'CLV2'!$A:$A,'CLV2'!$G:$G)} -> 4.Bầu, Bí, Mướp
B31: 46235 | C31: KFM_HCM_TPH - 83 Khuông Việt | D31: =VLOOKUP(C31,'DS ST'!A:B,2,0) -> A143 | E31: 1101366 | F31: BÔNG CẢI XANH ĐÀ LẠT (KG) | G31: KG | H31: 4 | I31: 3.98 | J31: =H31-I31 -> 0.02 | K31: PT1598522 | L31: =K31&E31 -> PT15985221101366 | M31: TO227201 | N31: 0.02 | P31: =H31-I31-N31-O31 -> 0 | T31: hình kdb | U31: Thiếu Item trong kiện | V31: Hao hụt | W31: =IF(VALUE(N31)<=0,"",IF(TRIM(V31)="Hao hụt","Hao hụt","Hao hụt")) -> Hao hụt | X31: =IF(AND(N(O31)>0,OR(V31="DC giao bù",V31="VT giao sai điểm",V31="ST nhập thiếu",V31="DC pick sai",V31="ST kiểm sai QT",V31="ST thông tin sai")),"Siêu thị","") | Y31: Kho rau | Z31: Hoàn Thành | AF31: {=xlookup($E:$E,'CLV2'!$A:$A,'CLV2'!E:E)} -> 2.VEGETABLES | AG31: =if(G31="KG","KG","Pack") -> KG | AH31: =J31/H31 -> 0.005 | AI31: {=XLOOKUP(E31,'Đơn giá'!A:A,'Đơn giá'!D:D)} -> 55000 | AJ31: =AI31*J31 -> 1100 | AK31: =IF($W:$W="Hao hụt", AI31*N31, 0) -> 1100 | AL31: =IF($X:$X="Siêu thị", AI31*O31, 0) -> 0 | AM31: =IF($Y:$Y="Kho rau", AI31*P31, 0) -> 0 | AN31: =IF($Y:$Y="Chưa xác định", AI31*P31, 0) -> 0 | AO31: {=XLOOKUP($D:$D,'DS ST'!$J:$J,'DS ST'!K:K)} -> SC003733 - Trần Huỳnh Thơ | AP31: {=XLOOKUP($D:$D,'DS ST'!$J:$J,'DS ST'!L:L)} -> Võ Thị Huệ | AQ31: {=XLOOKUP($D:$D,'DS ST'!$J:$J,'DS ST'!M:M)} -> HCM 013 | AT31: {=xlookup($E:$E,'CLV2'!$A:$A,'CLV2'!$F:$F)} -> 3.LEAFY VEGGIES | AU31: {=xlookup($E:$E,'CLV2'!$A:$A,'CLV2'!$G:$G)} -> 4.Rau Ăn Bông
B32: 46235 | C32: KFM_HCM_Q08 - 296 Hoàng Ngân | D32: =VLOOKUP(C32,'DS ST'!A:B,2,0) -> HNN | E32: 10901 | F32: CẢI NGỌT VIETGAP 300G | G32: GÓI | H32: 4 | I32: 3 | J32: =H32-I32 -> 1 | K32: PT1598521 | L32: =K32&E32 -> PT159852110901 | M32: TO227291 | P32: =H32-I32-N32-O32 -> 1 | T32: hình tele | U32: Thiếu Item trong kiện | V32: DC giao thiếu | W32: =IF(VALUE(N32)<=0,"",IF(TRIM(V32)="Hao hụt","Hao hụt","Hao hụt")) | X32: =IF(AND(N(O32)>0,OR(V32="DC giao bù",V32="VT giao sai điểm",V32="ST nhập thiếu",V32="DC pick sai",V32="ST kiểm sai QT",V32="ST thông tin sai")),"Siêu thị","") | Y32: =IF(N(P32)<=0,"",IF(OR(T32="Hình KDB",T32="Hình tele",ISNUMBER(SEARCH("Hình KDB",T32)),ISNUMBER(SEARCH("Hình tele",T32)),ISNUMBER(SEARCH("sai code",T32)),ISNUMBER(SEARCH("Thiếu kiện",U32))),"Kho rau",IF(AND(T32<>"Hình KDB",T32<>"Hình tele"),"Chưa xác định",IF(N(O32)>0,IF(OR(T32="Hình KDB",T32="Hình tele",ISNUMBER(SEARCH("Hình KDB",T32)),ISNUMBER(SEARCH("Hình tele",T32)),ISNUMBER(SEARCH("sai code",T32)),ISNUMBER(SEARCH("Thiếu kiện",U32))),"Kho rau","Chưa xác định"),IF(OR(T32="Hình KDB",T32="Hình tele",ISNUMBER(SEARCH("Hình KDB",T32)),ISNUMBER(SEARCH("Hình tele",T32)),ISNUMBER(SEARCH("sai code",T32)),ISNUMBER(SEARCH("Thiếu kiện",U32))),"Kho rau",IF(V32="Chưa xác định","Chưa xác định",IF(OR(V32="DC giao thiếu",V32="TX giao thiếu kiện",V32="Hàng không đạt CL"),"Kho rau",""))))))) -> Kho rau | Z32: Hoàn Thành | AF32: {=xlookup($E:$E,'CLV2'!$A:$A,'CLV2'!E:E)} -> 2.VEGETABLES | AG32: =if(G32="KG","KG","Pack") -> Pack | AH32: =J32/H32 -> 0.25 | AI32: {=XLOOKUP(E32,'Đơn giá'!A:A,'Đơn giá'!D:D)} -> 9000 | AJ32: =AI32*J32 -> 9000 | AK32: =IF($W:$W="Hao hụt", AI32*N32, 0) -> 0 | AL32: =IF($X:$X="Siêu thị", AI32*O32, 0) -> 0 | AM32: =IF($Y:$Y="Kho rau", AI32*P32, 0) -> 9000 | AN32: =IF($Y:$Y="Chưa xác định", AI32*P32, 0) -> 0 | AO32: {=XLOOKUP($D:$D,'DS ST'!$J:$J,'DS ST'!K:K)} -> SC003943 - Lâm Văn Tú | AP32: {=XLOOKUP($D:$D,'DS ST'!$J:$J,'DS ST'!L:L)} -> Võ Thị Huệ | AQ32: {=XLOOKUP($D:$D,'DS ST'!$J:$J,'DS ST'!M:M)} -> HCM 011 | AT32: {=xlookup($E:$E,'CLV2'!$A:$A,'CLV2'!$F:$F)} -> 3.LEAFY VEGGIES | AU32: {=xlookup($E:$E,'CLV2'!$A:$A,'CLV2'!$G:$G)} -> 4.Rau Cải
B33: 46235 | C33: KFM_HCM_Q08 - 296 Hoàng Ngân | D33: =VLOOKUP(C33,'DS ST'!A:B,2,0) -> HNN | E33: 11024 | F33: LÁ VỪNG (LÁ MÈ) 50G | G33: GÓI | H33: 2 | I33: 1 | J33: =H33-I33 -> 1 | K33: PT1598521 | L33: =K33&E33 -> PT159852111024 | M33: TO227291 | P33: =H33-I33-N33-O33 -> 1 | T33: hình tele | U33: Thiếu Item trong kiện | V33: DC giao thiếu | W33: =IF(VALUE(N33)<=0,"",IF(TRIM(V33)="Hao hụt","Hao hụt","Hao hụt")) | X33: =IF(AND(N(O33)>0,OR(V33="DC giao bù",V33="VT giao sai điểm",V33="ST nhập thiếu",V33="DC pick sai",V33="ST kiểm sai QT",V33="ST thông tin sai")),"Siêu thị","") | Y33: =IF(N(P33)<=0,"",IF(OR(T33="Hình KDB",T33="Hình tele",ISNUMBER(SEARCH("Hình KDB",T33)),ISNUMBER(SEARCH("Hình tele",T33)),ISNUMBER(SEARCH("sai code",T33)),ISNUMBER(SEARCH("Thiếu kiện",U33))),"Kho rau",IF(AND(T33<>"Hình KDB",T33<>"Hình tele"),"Chưa xác định",IF(N(O33)>0,IF(OR(T33="Hình KDB",T33="Hình tele",ISNUMBER(SEARCH("Hình KDB",T33)),ISNUMBER(SEARCH("Hình tele",T33)),ISNUMBER(SEARCH("sai code",T33)),ISNUMBER(SEARCH("Thiếu kiện",U33))),"Kho rau","Chưa xác định"),IF(OR(T33="Hình KDB",T33="Hình tele",ISNUMBER(SEARCH("Hình KDB",T33)),ISNUMBER(SEARCH("Hình tele",T33)),ISNUMBER(SEARCH("sai code",T33)),ISNUMBER(SEARCH("Thiếu kiện",U33))),"Kho rau",IF(V33="Chưa xác định","Chưa xác định",IF(OR(V33="DC giao thiếu",V33="TX giao thiếu kiện",V33="Hàng không đạt CL"),"Kho rau",""))))))) -> Kho rau | Z33: Hoàn Thành | AF33: {=xlookup($E:$E,'CLV2'!$A:$A,'CLV2'!E:E)} -> 2.VEGETABLES | AG33: =if(G33="KG","KG","Pack") -> Pack | AH33: =J33/H33 -> 0.5 | AI33: {=XLOOKUP(E33,'Đơn giá'!A:A,'Đơn giá'!D:D)} -> 8000 | AJ33: =AI33*J33 -> 8000 | AK33: =IF($W:$W="Hao hụt", AI33*N33, 0) -> 0 | AL33: =IF($X:$X="Siêu thị", AI33*O33, 0) -> 0 | AM33: =IF($Y:$Y="Kho rau", AI33*P33, 0) -> 8000 | AN33: =IF($Y:$Y="Chưa xác định", AI33*P33, 0) -> 0 | AO33: {=XLOOKUP($D:$D,'DS ST'!$J:$J,'DS ST'!K:K)} -> SC003943 - Lâm Văn Tú | AP33: {=XLOOKUP($D:$D,'DS ST'!$J:$J,'DS ST'!L:L)} -> Võ Thị Huệ | AQ33: {=XLOOKUP($D:$D,'DS ST'!$J:$J,'DS ST'!M:M)} -> HCM 011 | AT33: {=xlookup($E:$E,'CLV2'!$A:$A,'CLV2'!$F:$F)} -> 3.HERBS | AU33: {=xlookup($E:$E,'CLV2'!$A:$A,'CLV2'!$G:$G)} -> 4.Rau Thơm, Rau Nêm
B34: 46235 | C34: KFM_HCM_Q08 - 296 Hoàng Ngân | D34: =VLOOKUP(C34,'DS ST'!A:B,2,0) -> HNN | E34: 11375 | F34: RAU BỒ NGÓT VIETGAP 300G | G34: GÓI | H34: 4 | I34: 2 | J34: =H34-I34 -> 2 | K34: PT1598521 | L34: =K34&E34 -> PT159852111375 | M34: TO227291 | P34: =H34-I34-N34-O34 -> 2 | T34: hình tele | U34: Thiếu Item trong kiện | V34: DC giao thiếu | W34: =IF(VALUE(N34)<=0,"",IF(TRIM(V34)="Hao hụt","Hao hụt","Hao hụt")) | X34: =IF(AND(N(O34)>0,OR(V34="DC giao bù",V34="VT giao sai điểm",V34="ST nhập thiếu",V34="DC pick sai",V34="ST kiểm sai QT",V34="ST thông tin sai")),"Siêu thị","") | Y34: =IF(N(P34)<=0,"",IF(OR(T34="Hình KDB",T34="Hình tele",ISNUMBER(SEARCH("Hình KDB",T34)),ISNUMBER(SEARCH("Hình tele",T34)),ISNUMBER(SEARCH("sai code",T34)),ISNUMBER(SEARCH("Thiếu kiện",U34))),"Kho rau",IF(AND(T34<>"Hình KDB",T34<>"Hình tele"),"Chưa xác định",IF(N(O34)>0,IF(OR(T34="Hình KDB",T34="Hình tele",ISNUMBER(SEARCH("Hình KDB",T34)),ISNUMBER(SEARCH("Hình tele",T34)),ISNUMBER(SEARCH("sai code",T34)),ISNUMBER(SEARCH("Thiếu kiện",U34))),"Kho rau","Chưa xác định"),IF(OR(T34="Hình KDB",T34="Hình tele",ISNUMBER(SEARCH("Hình KDB",T34)),ISNUMBER(SEARCH("Hình tele",T34)),ISNUMBER(SEARCH("sai code",T34)),ISNUMBER(SEARCH("Thiếu kiện",U34))),"Kho rau",IF(V34="Chưa xác định","Chưa xác định",IF(OR(V34="DC giao thiếu",V34="TX giao thiếu kiện",V34="Hàng không đạt CL"),"Kho rau",""))))))) -> Kho rau | Z34: Hoàn Thành | AF34: {=xlookup($E:$E,'CLV2'!$A:$A,'CLV2'!E:E)} -> 2.VEGETABLES | AG34: =if(G34="KG","KG","Pack") -> Pack | AH34: =J34/H34 -> 0.5 | AI34: {=XLOOKUP(E34,'Đơn giá'!A:A,'Đơn giá'!D:D)} -> 13000 | AJ34: =AI34*J34 -> 26000 | AK34: =IF($W:$W="Hao hụt", AI34*N34, 0) -> 0 | AL34: =IF($X:$X="Siêu thị", AI34*O34, 0) -> 0 | AM34: =IF($Y:$Y="Kho rau", AI34*P34, 0) -> 26000 | AN34: =IF($Y:$Y="Chưa xác định", AI34*P34, 0) -> 0 | AO34: {=XLOOKUP($D:$D,'DS ST'!$J:$J,'DS ST'!K:K)} -> SC003943 - Lâm Văn Tú | AP34: {=XLOOKUP($D:$D,'DS ST'!$J:$J,'DS ST'!L:L)} -> Võ Thị Huệ | AQ34: {=XLOOKUP($D:$D,'DS ST'!$J:$J,'DS ST'!M:M)} -> HCM 011 | AT34: {=xlookup($E:$E,'CLV2'!$A:$A,'CLV2'!$F:$F)} -> 3.LEAFY VEGGIES | AU34: {=xlookup($E:$E,'CLV2'!$A:$A,'CLV2'!$G:$G)} -> 4.Rau Ăn Lá Thông Dụng
