Workbook

Sheet Chênh lệch ST
I1: =SUBTOTAL(9,I3:I4599) -> 28074.3 | J1: =SUBTOTAL(9,J3:J4599) -> 5503.478 | K1: =SUBTOTAL(9,K3:K4599) -> 22570.822 | O1: =SUBTOTAL(9,O3:O4599) -> 30.767 | P1: =SUBTOTAL(9,P3:P4599) -> 7482.2 | Q1: =SUBTOTAL(9,Q3:Q4599) -> 15057.855 | Z1: Nơi nhận | AC1: DC phản hồi | AE1: KFM THÔNG TIN | AK1: =SUBTOTAL(9,AK3:AK4599) -> 11805904 | AL1: =SUBTOTAL(9,AL3:AL4599) -> 6.9520452e+08 | AM1: =SUBTOTAL(9,AM3:AM4599) -> 4193087.5 | AN1: =SUBTOTAL(9,AN3:AN4599) -> 1.7319732e+08 | AO1: =SUBTOTAL(9,AO3:AO4599) -> 4.7642772e+08 | AP1: =SUBTOTAL(9,AP3:AP4599) -> 40696169 | AQ1: =SUBTOTAL(9,#REF!) -> #VALUE! | AR1: =SUBTOTAL(9,AR4600:AR126849) -> #VALUE!
A2: Ngày | B2: Thời gian kiểm | C2: Chi nhánh nhận | D2: ID ST | E2: Nhóm hàng | F2: Mã hàng | G2: Tên SP | H2: ĐVT | I2: Số lượng chuyển | J2: Số lượng nhận | K2: Chênh lệch | L2: PT chuyển hàng | M2: Mã thùng | N2: TO | O2: Hạo hụt tự nhiên | P2: SL trả tồn về ST | Q2: SL chênh lệch CXD | R2: PT Trả tồn về ST | S2: PT trả tồn về DC | T2: PT DC pick dư | U2: NOTE | V2: Trạng thái | W2: Lỗi | X2: Hao hụt | Y2: Siêu thị | Z2: Kho ĐÔNG MÁT | AA2: Xử lý | AB2: Link hình ảnh | AC2: DC xác nhận | AD2: NOTE 2 | AE2: KFM phản hồi | AF2: NOTE 3 | AG2: CLV2 | AH2: CLV3 | AI2: Loại hàng | AJ2: % Hao hụt | AK2: Giá nhập ( -VAT) | AL2: Tổng GT | AM2: Tổng hao hụt | AN2: Tổng ST | AO2: Tổng kho | AP2: Tổng chưa xác định | AQ2: GSM phụ trách | AR2: RSM phụ trách
A3: 46231 | B3: 0.41666667 | C3: KFM_BDU_DAN - 01-06 TMDV Him Lam Phú Đông | D3: {=XLOOKUP(C3,'DS ST'!A:A,'DS ST'!B:B)} -> HPD | E3: {=XLOOKUP($F3,'GIÁ'!$A:$A,'GIÁ'!$E:$E)} -> MÁT | F3: 10610 | G3: ZESPRI - HỘP KIWI VÀNG CHÍN 4 QUẢ | H3: HỘP | I3: 1 | J3: 0 | K3: =I3-J3 -> 1 | L3: PT1580356 | M3: TRBHPD002 | N3: TO223985 | P3: 1 | Q3: =I3-J3-O3-P3 -> 0 | R3: PT1595852 | V3: Thiếu Item trong kiện | W3: ST nhập thiếu | X3: =IF(VALUE(O3)<=0,"",IF(TRIM(W3)="Hao hụt","Hao hụt","Hao hụt")) | Y3: =IF(AND(N(P3)>0,OR(W3="DC giao bù",W3="VT giao sai điểm",W3="ST nhập thiếu",W3="DC pick sai",W3="ST kiểm sai QT",W3="ST thông tin sai/không phản hồi",W3="DC thao tác sai")),"Siêu thị","") -> Siêu thị | Z3: Kho đông mát | AA3: Hoàn Thành | AB3: HPD.mp4 | AC3: Kiểm tra lại | AE3: DONE | AG3: {=XLOOKUP(F3,'CLV2'!A:A,'CLV2'!E:E)} -> 2.FRUITS | AH3: {=XLOOKUP(F3,'CLV2'!A:A,'CLV2'!F:F)} -> 3.IMPORT FRUITS | AI3: =if(H3="KG","KG","Pack") -> Pack | AJ3: =K3/I3 -> 1 | AK3: {=XLOOKUP(F3,'GIÁ'!A:A,'GIÁ'!D:D)} -> 72259.15 | AL3: =VALUE(SUBSTITUTE(AK3, ".", ","))*K3 -> 72259.15 | AM3: =IF($X:$X="Hao hụt", VALUE(SUBSTITUTE($AK3, ".", ","))*O3, 0) -> 0 | AN3: =IF($Y:$Y="Siêu thị", VALUE(SUBSTITUTE(AK3, ".", ","))*P3, 0) -> 72259.15 | AO3: =IF($Z:$Z="Kho đông mát", VALUE(SUBSTITUTE(AK3, ".", ","))*Q3, 0) -> 0 | AP3: =IF($Z:$Z="Chưa xác định", VALUE(SUBSTITUTE(AK3, ".", ","))*Q3, 0) -> 0
A4: 46231 | B4: 0.41666667 | C4: KFM_BDU_DAN - 01-06 TMDV Him Lam Phú Đông | D4: {=XLOOKUP(C4,'DS ST'!A:A,'DS ST'!B:B)} -> HPD | E4: {=XLOOKUP($F4,'GIÁ'!$A:$A,'GIÁ'!$E:$E)} -> MÁT | F4: 8936176751014 | G4: TNT - CHÈ MÔN 140G | H4: LY | I4: 1 | J4: 0 | K4: =I4-J4 -> 1 | L4: PT1580356 | M4: TRBHPD002 | N4: TO223985 | P4: 1 | Q4: =I4-J4-O4-P4 -> 0 | R4: PT1595852 | V4: Thiếu Item trong kiện | W4: ST nhập thiếu | X4: =IF(VALUE(O4)<=0,"",IF(TRIM(W4)="Hao hụt","Hao hụt","Hao hụt")) | Y4: =IF(AND(N(P4)>0,OR(W4="DC giao bù",W4="VT giao sai điểm",W4="ST nhập thiếu",W4="DC pick sai",W4="ST kiểm sai QT",W4="ST thông tin sai/không phản hồi",W4="DC thao tác sai")),"Siêu thị","") -> Siêu thị | Z4: Kho đông mát | AA4: Hoàn Thành | AB4: HPD.mp4 | AC4: Kiểm tra lại | AE4: DONE | AG4: {=XLOOKUP(F4,'CLV2'!A:A,'CLV2'!E:E)} -> 2.DELICA | AH4: {=XLOOKUP(F4,'CLV2'!A:A,'CLV2'!F:F)} -> 3.DESSERTS | AI4: =if(H4="KG","KG","Pack") -> Pack | AJ4: =K4/I4 -> 1 | AK4: {=XLOOKUP(F4,'GIÁ'!A:A,'GIÁ'!D:D)} -> 6650.00 | AL4: =VALUE(SUBSTITUTE(AK4, ".", ","))*K4 -> 6650 | AM4: =IF($X:$X="Hao hụt", VALUE(SUBSTITUTE($AK4, ".", ","))*O4, 0) -> 0 | AN4: =IF($Y:$Y="Siêu thị", VALUE(SUBSTITUTE(AK4, ".", ","))*P4, 0) -> 6650 | AO4: =IF($Z:$Z="Kho đông mát", VALUE(SUBSTITUTE(AK4, ".", ","))*Q4, 0) -> 0 | AP4: =IF($Z:$Z="Chưa xác định", VALUE(SUBSTITUTE(AK4, ".", ","))*Q4, 0) -> 0
A5: 46231 | B5: 0.41666667 | C5: KFM_BDU_DAN - 01-06 TMDV Him Lam Phú Đông | D5: {=XLOOKUP(C5,'DS ST'!A:A,'DS ST'!B:B)} -> HPD | E5: {=XLOOKUP($F5,'GIÁ'!$A:$A,'GIÁ'!$E:$E)} -> MÁT | F5: 11751 | G5: TÁO RED FUJI NAM PHI TÚI 950G UP | H5: TÚI | I5: 1 | J5: 0 | K5: =I5-J5 -> 1 | L5: PT1580356 | M5: TRBHPD002 | N5: TO223985 | Q5: =I5-J5-O5-P5 -> 1 | V5: Thiếu Item trong kiện | W5: DC giao thiếu | X5: =IF(VALUE(O5)<=0,"",IF(TRIM(W5)="Hao hụt","Hao hụt","Hao hụt")) | Y5: =IF(AND(N(P5)>0,OR(W5="DC giao bù",W5="VT giao sai điểm",W5="ST nhập thiếu",W5="DC pick sai",W5="ST kiểm sai QT",W5="ST thông tin sai/không phản hồi",W5="DC thao tác sai")),"Siêu thị","") | Z5: Kho đông mát | AA5: Hoàn Thành | AB5: HPD.mp4 | AC5: Đồng ý claim | AG5: {=XLOOKUP(F5,'CLV2'!A:A,'CLV2'!E:E)} -> 2.FRUITS | AH5: {=XLOOKUP(F5,'CLV2'!A:A,'CLV2'!F:F)} -> 3.IMPORT FRUITS | AI5: =if(H5="KG","KG","Pack") -> Pack | AJ5: =K5/I5 -> 1 | AK5: {=XLOOKUP(F5,'GIÁ'!A:A,'GIÁ'!D:D)} -> 64445.12 | AL5: =VALUE(SUBSTITUTE(AK5, ".", ","))*K5 -> 64445.12 | AM5: =IF($X:$X="Hao hụt", VALUE(SUBSTITUTE($AK5, ".", ","))*O5, 0) -> 0 | AN5: =IF($Y:$Y="Siêu thị", VALUE(SUBSTITUTE(AK5, ".", ","))*P5, 0) -> 0 | AO5: =IF($Z:$Z="Kho đông mát", VALUE(SUBSTITUTE(AK5, ".", ","))*Q5, 0) -> 64445.12 | AP5: =IF($Z:$Z="Chưa xác định", VALUE(SUBSTITUTE(AK5, ".", ","))*Q5, 0) -> 0
A6: 46231 | B6: 0.41666667 | C6: KFM_BDU_DAN - 01-06 TMDV Him Lam Phú Đông | D6: {=XLOOKUP(C6,'DS ST'!A:A,'DS ST'!B:B)} -> HPD | E6: {=XLOOKUP($F6,'GIÁ'!$A:$A,'GIÁ'!$E:$E)} -> MÁT | F6: 11550 | G6: TỎI HẢI DƯƠNG XAY 50G | H6: HỘP | I6: 5 | J6: 3 | K6: =I6-J6 -> 2 | L6: PT1580356 | M6: TRBHPD4024 | N6: TO223967 | Q6: =I6-J6-O6-P6 -> 2 | V6: Thiếu Item trong kiện | W6: DC giao thiếu | X6: =IF(VALUE(O6)<=0,"",IF(TRIM(W6)="Hao hụt","Hao hụt","Hao hụt")) | Y6: =IF(AND(N(P6)>0,OR(W6="DC giao bù",W6="VT giao sai điểm",W6="ST nhập thiếu",W6="DC pick sai",W6="ST kiểm sai QT",W6="ST thông tin sai/không phản hồi",W6="DC thao tác sai")),"Siêu thị","") | Z6: Kho đông mát | AA6: Hoàn Thành | AB6: HPD.mp4 | AC6: Đồng ý claim | AG6: {=XLOOKUP(F6,'CLV2'!A:A,'CLV2'!E:E)} -> 2.VEGETABLES | AH6: {=XLOOKUP(F6,'CLV2'!A:A,'CLV2'!F:F)} -> 3.PROCESSED VEGGIES | AI6: =if(H6="KG","KG","Pack") -> Pack | AJ6: =K6/I6 -> 0.4 | AK6: {=XLOOKUP(F6,'GIÁ'!A:A,'GIÁ'!D:D)} -> 10364.97 | AL6: =VALUE(SUBSTITUTE(AK6, ".", ","))*K6 -> 20729.94 | AM6: =IF($X:$X="Hao hụt", VALUE(SUBSTITUTE($AK6, ".", ","))*O6, 0) -> 0 | AN6: =IF($Y:$Y="Siêu thị", VALUE(SUBSTITUTE(AK6, ".", ","))*P6, 0) -> 0 | AO6: =IF($Z:$Z="Kho đông mát", VALUE(SUBSTITUTE(AK6, ".", ","))*Q6, 0) -> 20729.94 | AP6: =IF($Z:$Z="Chưa xác định", VALUE(SUBSTITUTE(AK6, ".", ","))*Q6, 0) -> 0
A7: 46231 | B7: 0.40416667 | C7: KFM_BDU_DAN - 145B Lê Trọng Tấn | D7: {=XLOOKUP(C7,'DS ST'!A:A,'DS ST'!B:B)} -> A209 | E7: {=XLOOKUP($F7,'GIÁ'!$A:$A,'GIÁ'!$E:$E)} -> MÁT | F7: 11589 | G7: MÍT GIỐNG THÁI LỘT SẴN HỘP 350G | H7: HỘP | I7: 1 | J7: 0 | K7: =I7-J7 -> 1 | L7: PT1580307 | M7: TRBA2095039 | N7: TO223974 | Q7: =I7-J7-O7-P7 -> 1 | U7: pick sai code: 11742 - 4 | V7: Thiếu Item trong kiện | W7: DC giao thiếu | X7: =IF(VALUE(O7)<=0,"",IF(TRIM(W7)="Hao hụt","Hao hụt","Hao hụt")) | Y7: =IF(AND(N(P7)>0,OR(W7="DC giao bù",W7="VT giao sai điểm",W7="ST nhập thiếu",W7="DC pick sai",W7="ST kiểm sai QT",W7="ST thông tin sai/không phản hồi",W7="DC thao tác sai")),"Siêu thị","") | Z7: =IF(N(Q7)<=0,"",IF(ISNUMBER(SEARCH("Thiếu kiện",V7)),"Kho đông mát",IF(AND(N(Q7)>0,N(P7)>0,OR(ISNUMBER(SEARCH("Hình KDB",U7)),ISNUMBER(SEARCH("Hình tele",U7)),ISNUMBER(SEARCH("sai code",U7)),ISNUMBER(SEARCH("ST nhận",U7)))),"Kho đông mát",IF(AND(W7="DC giao thiếu",OR(ISNUMBER(SEARCH("Hình KDB",U7)),ISNUMBER(SEARCH("Hình tele",U7)),ISNUMBER(SEARCH("sai code",U7)))),"Kho đông mát",IF(W7="DC giao thiếu","Chưa xác định",IF(AND(W7="DC pick sai",OR(ISNUMBER(SEARCH("Hình KDB",U7)),ISNUMBER(SEARCH("Hình tele",U7)),ISNUMBER(SEARCH("sai code",U7)),ISNUMBER(SEARCH("ST nhận",U7)))),"Kho đông mát",IF(W7="DC pick sai","Chưa xác định",IF(AND(W7="Hao hụt",N(O7)>0,OR(ISNUMBER(SEARCH("Hình KDB",U7)),ISNUMBER(SEARCH("Hình tele",U7)),ISNUMBER(SEARCH("sai code",U7)),ISNUMBER(SEARCH("ST nhận",U7)))),"Kho đông mát",IF(W7="Hao hụt","Chưa xác định",IF(OR(W7="VT giao sai điểm",W7="Không đạt nhiệt độ",W7="TX giao thiếu kiện",W7="Hàng không đạt CL"),"Kho đông mát",IF(W7="Chưa xác định","Chưa xác định",IF(N(P7)>0,"Chưa xác định","")))))))))))) -> Kho đông mát | AA7: Hoàn Thành | AC7: Đồng ý claim | AG7: {=XLOOKUP(F7,'CLV2'!A:A,'CLV2'!E:E)} -> 2.FRUITS | AH7: {=XLOOKUP(F7,'CLV2'!A:A,'CLV2'!F:F)} -> 3.CUTTING FRUITS | AI7: =if(H7="KG","KG","Pack") -> Pack | AJ7: =K7/I7 -> 1 | AK7: {=XLOOKUP(F7,'GIÁ'!A:A,'GIÁ'!D:D)} -> 22122.55 | AL7: =VALUE(SUBSTITUTE(AK7, ".", ","))*K7 -> 22122.55 | AM7: =IF($X:$X="Hao hụt", VALUE(SUBSTITUTE($AK7, ".", ","))*O7, 0) -> 0 | AN7: =IF($Y:$Y="Siêu thị", VALUE(SUBSTITUTE(AK7, ".", ","))*P7, 0) -> 0 | AO7: =IF($Z:$Z="Kho đông mát", VALUE(SUBSTITUTE(AK7, ".", ","))*Q7, 0) -> 22122.55 | AP7: =IF($Z:$Z="Chưa xác định", VALUE(SUBSTITUTE(AK7, ".", ","))*Q7, 0) -> 0
A8: 46231 | B8: 0.40416667 | C8: KFM_BDU_DAN - 145B Lê Trọng Tấn | D8: {=XLOOKUP(C8,'DS ST'!A:A,'DS ST'!B:B)} -> A209 | E8: {=XLOOKUP($F8,'GIÁ'!$A:$A,'GIÁ'!$E:$E)} -> MÁT | F8: 8936176751021 | G8: TNT - CHÈ BẮP 140G | H8: LY | I8: 8 | J8: 5 | K8: =I8-J8 -> 3 | L8: PT1580307 | M8: TRBA2095047 | N8: TO223974 | Q8: =I8-J8-O8-P8 -> 3 | U8: pick sai code: 8936176751007 - 3 | V8: Thiếu Item trong kiện | W8: DC giao thiếu | X8: =IF(VALUE(O8)<=0,"",IF(TRIM(W8)="Hao hụt","Hao hụt","Hao hụt")) | Y8: =IF(AND(N(P8)>0,OR(W8="DC giao bù",W8="VT giao sai điểm",W8="ST nhập thiếu",W8="DC pick sai",W8="ST kiểm sai QT",W8="ST thông tin sai/không phản hồi",W8="DC thao tác sai")),"Siêu thị","") | Z8: =IF(N(Q8)<=0,"",IF(ISNUMBER(SEARCH("Thiếu kiện",V8)),"Kho đông mát",IF(AND(N(Q8)>0,N(P8)>0,OR(ISNUMBER(SEARCH("Hình KDB",U8)),ISNUMBER(SEARCH("Hình tele",U8)),ISNUMBER(SEARCH("sai code",U8)),ISNUMBER(SEARCH("ST nhận",U8)))),"Kho đông mát",IF(AND(W8="DC giao thiếu",OR(ISNUMBER(SEARCH("Hình KDB",U8)),ISNUMBER(SEARCH("Hình tele",U8)),ISNUMBER(SEARCH("sai code",U8)))),"Kho đông mát",IF(W8="DC giao thiếu","Chưa xác định",IF(AND(W8="DC pick sai",OR(ISNUMBER(SEARCH("Hình KDB",U8)),ISNUMBER(SEARCH("Hình tele",U8)),ISNUMBER(SEARCH("sai code",U8)),ISNUMBER(SEARCH("ST nhận",U8)))),"Kho đông mát",IF(W8="DC pick sai","Chưa xác định",IF(AND(W8="Hao hụt",N(O8)>0,OR(ISNUMBER(SEARCH("Hình KDB",U8)),ISNUMBER(SEARCH("Hình tele",U8)),ISNUMBER(SEARCH("sai code",U8)),ISNUMBER(SEARCH("ST nhận",U8)))),"Kho đông mát",IF(W8="Hao hụt","Chưa xác định",IF(OR(W8="VT giao sai điểm",W8="Không đạt nhiệt độ",W8="TX giao thiếu kiện",W8="Hàng không đạt CL"),"Kho đông mát",IF(W8="Chưa xác định","Chưa xác định",IF(N(P8)>0,"Chưa xác định","")))))))))))) -> Kho đông mát | AA8: Hoàn Thành | AC8: Đồng ý claim | AG8: {=XLOOKUP(F8,'CLV2'!A:A,'CLV2'!E:E)} -> 2.DELICA | AH8: {=XLOOKUP(F8,'CLV2'!A:A,'CLV2'!F:F)} -> 3.DESSERTS | AI8: =if(H8="KG","KG","Pack") -> Pack | AJ8: =K8/I8 -> 0.375 | AK8: {=XLOOKUP(F8,'GIÁ'!A:A,'GIÁ'!D:D)} -> 6650.00 | AL8: =VALUE(SUBSTITUTE(AK8, ".", ","))*K8 -> 19950 | AM8: =IF($X:$X="Hao hụt", VALUE(SUBSTITUTE($AK8, ".", ","))*O8, 0) -> 0 | AN8: =IF($Y:$Y="Siêu thị", VALUE(SUBSTITUTE(AK8, ".", ","))*P8, 0) -> 0 | AO8: =IF($Z:$Z="Kho đông mát", VALUE(SUBSTITUTE(AK8, ".", ","))*Q8, 0) -> 19950 | AP8: =IF($Z:$Z="Chưa xác định", VALUE(SUBSTITUTE(AK8, ".", ","))*Q8, 0) -> 0
A9: 46231 | B9: 0.40416667 | C9: KFM_BDU_DAN - 145B Lê Trọng Tấn | D9: {=XLOOKUP(C9,'DS ST'!A:A,'DS ST'!B:B)} -> A209 | E9: {=XLOOKUP($F9,'GIÁ'!$A:$A,'GIÁ'!$E:$E)} -> MÁT | F9: 8936176751175 | G9: TNT - CHÈ DỪA NON KIỂU THÁI 140G | H9: LY | I9: 5 | J9: 4 | K9: =I9-J9 -> 1 | L9: PT1580307 | M9: TRBA2095047 | N9: TO223974 | Q9: =I9-J9-O9-P9 -> 1 | U9: pick sai code: 8936176751182 - 3 | V9: Thiếu Item trong kiện | W9: DC giao thiếu | X9: =IF(VALUE(O9)<=0,"",IF(TRIM(W9)="Hao hụt","Hao hụt","Hao hụt")) | Y9: =IF(AND(N(P9)>0,OR(W9="DC giao bù",W9="VT giao sai điểm",W9="ST nhập thiếu",W9="DC pick sai",W9="ST kiểm sai QT",W9="ST thông tin sai/không phản hồi",W9="DC thao tác sai")),"Siêu thị","") | Z9: =IF(N(Q9)<=0,"",IF(ISNUMBER(SEARCH("Thiếu kiện",V9)),"Kho đông mát",IF(AND(N(Q9)>0,N(P9)>0,OR(ISNUMBER(SEARCH("Hình KDB",U9)),ISNUMBER(SEARCH("Hình tele",U9)),ISNUMBER(SEARCH("sai code",U9)),ISNUMBER(SEARCH("ST nhận",U9)))),"Kho đông mát",IF(AND(W9="DC giao thiếu",OR(ISNUMBER(SEARCH("Hình KDB",U9)),ISNUMBER(SEARCH("Hình tele",U9)),ISNUMBER(SEARCH("sai code",U9)))),"Kho đông mát",IF(W9="DC giao thiếu","Chưa xác định",IF(AND(W9="DC pick sai",OR(ISNUMBER(SEARCH("Hình KDB",U9)),ISNUMBER(SEARCH("Hình tele",U9)),ISNUMBER(SEARCH("sai code",U9)),ISNUMBER(SEARCH("ST nhận",U9)))),"Kho đông mát",IF(W9="DC pick sai","Chưa xác định",IF(AND(W9="Hao hụt",N(O9)>0,OR(ISNUMBER(SEARCH("Hình KDB",U9)),ISNUMBER(SEARCH("Hình tele",U9)),ISNUMBER(SEARCH("sai code",U9)),ISNUMBER(SEARCH("ST nhận",U9)))),"Kho đông mát",IF(W9="Hao hụt","Chưa xác định",IF(OR(W9="VT giao sai điểm",W9="Không đạt nhiệt độ",W9="TX giao thiếu kiện",W9="Hàng không đạt CL"),"Kho đông mát",IF(W9="Chưa xác định","Chưa xác định",IF(N(P9)>0,"Chưa xác định","")))))))))))) -> Kho đông mát | AA9: Hoàn Thành | AC9: Đồng ý claim | AG9: {=XLOOKUP(F9,'CLV2'!A:A,'CLV2'!E:E)} -> 2.DELICA | AH9: {=XLOOKUP(F9,'CLV2'!A:A,'CLV2'!F:F)} -> 3.DESSERTS | AI9: =if(H9="KG","KG","Pack") -> Pack | AJ9: =K9/I9 -> 0.2 | AK9: {=XLOOKUP(F9,'GIÁ'!A:A,'GIÁ'!D:D)} -> 6744.99 | AL9: =VALUE(SUBSTITUTE(AK9, ".", ","))*K9 -> 6744.99 | AM9: =IF($X:$X="Hao hụt", VALUE(SUBSTITUTE($AK9, ".", ","))*O9, 0) -> 0 | AN9: =IF($Y:$Y="Siêu thị", VALUE(SUBSTITUTE(AK9, ".", ","))*P9, 0) -> 0 | AO9: =IF($Z:$Z="Kho đông mát", VALUE(SUBSTITUTE(AK9, ".", ","))*Q9, 0) -> 6744.99 | AP9: =IF($Z:$Z="Chưa xác định", VALUE(SUBSTITUTE(AK9, ".", ","))*Q9, 0) -> 0
A10: 46231 | B10: 0.40416667 | C10: KFM_BDU_DAN - 145B Lê Trọng Tấn | D10: {=XLOOKUP(C10,'DS ST'!A:A,'DS ST'!B:B)} -> A209 | E10: {=XLOOKUP($F10,'GIÁ'!$A:$A,'GIÁ'!$E:$E)} -> MÁT | F10: 3184030003617 | G10: PAYSAN BRETON - PHÔ MAI SỢI EMMENTAL 70G | H10: GÓI | I10: 2 | J10: 0 | K10: =I10-J10 -> 2 | L10: PT1580307 | M10: TRBA2095049 | N10: TO223974 | Q10: =I10-J10-O10-P10 -> 2 | V10: Thiếu Item trong kiện | W10: DC giao thiếu | X10: =IF(VALUE(O10)<=0,"",IF(TRIM(W10)="Hao hụt","Hao hụt","Hao hụt")) | Y10: =IF(AND(N(P10)>0,OR(W10="DC giao bù",W10="VT giao sai điểm",W10="ST nhập thiếu",W10="DC pick sai",W10="ST kiểm sai QT",W10="ST thông tin sai/không phản hồi",W10="DC thao tác sai")),"Siêu thị","") | Z10: Kho đông mát | AA10: Hoàn Thành | AB10: A209.mp4 | AC10: Đồng ý claim | AG10: {=XLOOKUP(F10,'CLV2'!A:A,'CLV2'!E:E)} -> 2.DAIRY | AH10: {=XLOOKUP(F10,'CLV2'!A:A,'CLV2'!F:F)} -> 3.BUTTER AND CHEESE | AI10: =if(H10="KG","KG","Pack") -> Pack | AJ10: =K10/I10 -> 1 | AK10: {=XLOOKUP(F10,'GIÁ'!A:A,'GIÁ'!D:D)} -> 41960.14 | AL10: =VALUE(SUBSTITUTE(AK10, ".", ","))*K10 -> 83920.28 | AM10: =IF($X:$X="Hao hụt", VALUE(SUBSTITUTE($AK10, ".", ","))*O10, 0) -> 0 | AN10: =IF($Y:$Y="Siêu thị", VALUE(SUBSTITUTE(AK10, ".", ","))*P10, 0) -> 0 | AO10: =IF($Z:$Z="Kho đông mát", VALUE(SUBSTITUTE(AK10, ".", ","))*Q10, 0) -> 83920.28 | AP10: =IF($Z:$Z="Chưa xác định", VALUE(SUBSTITUTE(AK10, ".", ","))*Q10, 0) -> 0
A11: 46231 | B11: 0.4875 | C11: KFM_BDU_DAN - 9 Đường M, Khu Phố Nhị Đồng 2 | D11: {=XLOOKUP(C11,'DS ST'!A:A,'DS ST'!B:B)} -> A189 | E11: {=XLOOKUP($F11,'GIÁ'!$A:$A,'GIÁ'!$E:$E)} -> MÁT | F11: 11751 | G11: TÁO RED FUJI NAM PHI TÚI 950G UP | H11: TÚI | I11: 1 | J11: 0 | K11: =I11-J11 -> 1 | L11: PT1580392 | M11: TRBA1894008 | N11: TO224177 | Q11: =I11-J11-O11-P11 -> 1 | S11: x | T11: PT1581784 | U11: Pick sai code: TÁO GALA NEW ZEALAND TÚI 950G UP - 1 | V11: Thiếu Item trong kiện | W11: DC pick sai | X11: =IF(VALUE(O11)<=0,"",IF(TRIM(W11)="Hao hụt","Hao hụt","Hao hụt")) | Y11: =IF(AND(N(P11)>0,OR(W11="DC giao bù",W11="VT giao sai điểm",W11="ST nhập thiếu",W11="DC pick sai",W11="ST kiểm sai QT",W11="ST thông tin sai/không phản hồi",W11="DC thao tác sai")),"Siêu thị","") | Z11: =IF(N(Q11)<=0,"",IF(ISNUMBER(SEARCH("Thiếu kiện",V11)),"Kho đông mát",IF(AND(N(Q11)>0,N(P11)>0,OR(ISNUMBER(SEARCH("Hình KDB",U11)),ISNUMBER(SEARCH("Hình tele",U11)),ISNUMBER(SEARCH("sai code",U11)),ISNUMBER(SEARCH("ST nhận",U11)))),"Kho đông mát",IF(AND(W11="DC giao thiếu",OR(ISNUMBER(SEARCH("Hình KDB",U11)),ISNUMBER(SEARCH("Hình tele",U11)),ISNUMBER(SEARCH("sai code",U11)))),"Kho đông mát",IF(W11="DC giao thiếu","Chưa xác định",IF(AND(W11="DC pick sai",OR(ISNUMBER(SEARCH("Hình KDB",U11)),ISNUMBER(SEARCH("Hình tele",U11)),ISNUMBER(SEARCH("sai code",U11)),ISNUMBER(SEARCH("ST nhận",U11)))),"Kho đông mát",IF(W11="DC pick sai","Chưa xác định",IF(AND(W11="Hao hụt",N(O11)>0,OR(ISNUMBER(SEARCH("Hình KDB",U11)),ISNUMBER(SEARCH("Hình tele",U11)),ISNUMBER(SEARCH("sai code",U11)),ISNUMBER(SEARCH("ST nhận",U11)))),"Kho đông mát",IF(W11="Hao hụt","Chưa xác định",IF(OR(W11="VT giao sai điểm",W11="Không đạt nhiệt độ",W11="TX giao thiếu kiện",W11="Hàng không đạt CL"),"Kho đông mát",IF(W11="Chưa xác định","Chưa xác định",IF(N(P11)>0,"Chưa xác định","")))))))))))) -> Kho đông mát | AA11: Hoàn Thành | AG11: {=XLOOKUP(F11,'CLV2'!A:A,'CLV2'!E:E)} -> 2.FRUITS | AH11: {=XLOOKUP(F11,'CLV2'!A:A,'CLV2'!F:F)} -> 3.IMPORT FRUITS | AI11: =if(H11="KG","KG","Pack") -> Pack | AJ11: =K11/I11 -> 1 | AK11: {=XLOOKUP(F11,'GIÁ'!A:A,'GIÁ'!D:D)} -> 64445.12 | AL11: =VALUE(SUBSTITUTE(AK11, ".", ","))*K11 -> 64445.12 | AM11: =IF($X:$X="Hao hụt", VALUE(SUBSTITUTE($AK11, ".", ","))*O11, 0) -> 0 | AN11: =IF($Y:$Y="Siêu thị", VALUE(SUBSTITUTE(AK11, ".", ","))*P11, 0) -> 0 | AO11: =IF($Z:$Z="Kho đông mát", VALUE(SUBSTITUTE(AK11, ".", ","))*Q11, 0) -> 64445.12 | AP11: =IF($Z:$Z="Chưa xác định", VALUE(SUBSTITUTE(AK11, ".", ","))*Q11, 0) -> 0
A12: 46231 | B12: 0.4875 | C12: KFM_BDU_DAN - 9 Đường M, Khu Phố Nhị Đồng 2 | D12: {=XLOOKUP(C12,'DS ST'!A:A,'DS ST'!B:B)} -> A189 | E12: {=XLOOKUP($F12,'GIÁ'!$A:$A,'GIÁ'!$E:$E)} -> MÁT | F12: 8938528582574 | G12: NGỌC TÚ - BÁNH GIÒ THỊT HEO TRỨNG CÚT 160G | H12: GÓI | I12: 4 | J12: 2 | K12: =I12-J12 -> 2 | L12: PT1580392 | M12: TRBA1894024 | N12: TO224162 | P12: 2 | Q12: =I12-J12-O12-P12 -> 0 | R12: PT1581784 | V12: Thiếu Item trong kiện | W12: DC thao tác sai | X12: =IF(VALUE(O12)<=0,"",IF(TRIM(W12)="Hao hụt","Hao hụt","Hao hụt")) | Y12: =IF(AND(N(P12)>0,OR(W12="DC giao bù",W12="VT giao sai điểm",W12="ST nhập thiếu",W12="DC pick sai",W12="ST kiểm sai QT",W12="ST thông tin sai/không phản hồi",W12="DC thao tác sai")),"Siêu thị","") -> Siêu thị | Z12: =IF(N(Q12)<=0,"",IF(ISNUMBER(SEARCH("Thiếu kiện",V12)),"Kho đông mát",IF(AND(N(Q12)>0,N(P12)>0,OR(ISNUMBER(SEARCH("Hình KDB",U12)),ISNUMBER(SEARCH("Hình tele",U12)),ISNUMBER(SEARCH("sai code",U12)),ISNUMBER(SEARCH("ST nhận",U12)))),"Kho đông mát",IF(AND(W12="DC giao thiếu",OR(ISNUMBER(SEARCH("Hình KDB",U12)),ISNUMBER(SEARCH("Hình tele",U12)),ISNUMBER(SEARCH("sai code",U12)))),"Kho đông mát",IF(W12="DC giao thiếu","Chưa xác định",IF(AND(W12="DC pick sai",OR(ISNUMBER(SEARCH("Hình KDB",U12)),ISNUMBER(SEARCH("Hình tele",U12)),ISNUMBER(SEARCH("sai code",U12)),ISNUMBER(SEARCH("ST nhận",U12)))),"Kho đông mát",IF(W12="DC pick sai","Chưa xác định",IF(AND(W12="Hao hụt",N(O12)>0,OR(ISNUMBER(SEARCH("Hình KDB",U12)),ISNUMBER(SEARCH("Hình tele",U12)),ISNUMBER(SEARCH("sai code",U12)),ISNUMBER(SEARCH("ST nhận",U12)))),"Kho đông mát",IF(W12="Hao hụt","Chưa xác định",IF(OR(W12="VT giao sai điểm",W12="Không đạt nhiệt độ",W12="TX giao thiếu kiện",W12="Hàng không đạt CL"),"Kho đông mát",IF(W12="Chưa xác định","Chưa xác định",IF(N(P12)>0,"Chưa xác định","")))))))))))) | AA12: Hoàn Thành | AG12: {=XLOOKUP(F12,'CLV2'!A:A,'CLV2'!E:E)} -> 2.CHILLED FOODS | AH12: {=XLOOKUP(F12,'CLV2'!A:A,'CLV2'!F:F)} -> 3.OTHER CHILLED PRODUCTS | AI12: =if(H12="KG","KG","Pack") -> Pack | AJ12: =K12/I12 -> 0.5 | AK12: {=XLOOKUP(F12,'GIÁ'!A:A,'GIÁ'!D:D)} -> 10450.00 | AL12: =VALUE(SUBSTITUTE(AK12, ".", ","))*K12 -> 20900 | AM12: =IF($X:$X="Hao hụt", VALUE(SUBSTITUTE($AK12, ".", ","))*O12, 0) -> 0 | AN12: =IF($Y:$Y="Siêu thị", VALUE(SUBSTITUTE(AK12, ".", ","))*P12, 0) -> 20900 | AO12: =IF($Z:$Z="Kho đông mát", VALUE(SUBSTITUTE(AK12, ".", ","))*Q12, 0) -> 0 | AP12: =IF($Z:$Z="Chưa xác định", VALUE(SUBSTITUTE(AK12, ".", ","))*Q12, 0) -> 0
A13: 46231 | B13: 0.39375 | C13: KFM_BDU_DAN - B2.01.05 Tháp B Opal Boulevard | D13: {=XLOOKUP(C13,'DS ST'!A:A,'DS ST'!B:B)} -> A164 | E13: {=XLOOKUP($F13,'GIÁ'!$A:$A,'GIÁ'!$E:$E)} -> MÁT | F13: 8938562884405 | G13: MINH NHẬT - RAU CÂU FLAN PHOMAI CÀ PHÊ 120G | H13: HỘP | I13: 4 | J13: 0 | K13: =I13-J13 -> 4 | L13: PT1580343 | M13: TRBA164651 | N13: TO223935 | Q13: =I13-J13-O13-P13 -> 4 | U13: ST nhận: A189 - PT1581784 - 4/4 thiếu | V13: Thiếu Item trong kiện | W13: DC pick sai | X13: =IF(VALUE(O13)<=0,"",IF(TRIM(W13)="Hao hụt","Hao hụt","Hao hụt")) | Y13: =IF(AND(N(P13)>0,OR(W13="DC giao bù",W13="VT giao sai điểm",W13="ST nhập thiếu",W13="DC pick sai",W13="ST kiểm sai QT",W13="ST thông tin sai/không phản hồi",W13="DC thao tác sai")),"Siêu thị","") | Z13: =IF(N(Q13)<=0,"",IF(ISNUMBER(SEARCH("Thiếu kiện",V13)),"Kho đông mát",IF(AND(N(Q13)>0,N(P13)>0,OR(ISNUMBER(SEARCH("Hình KDB",U13)),ISNUMBER(SEARCH("Hình tele",U13)),ISNUMBER(SEARCH("sai code",U13)),ISNUMBER(SEARCH("ST nhận",U13)))),"Kho đông mát",IF(AND(W13="DC giao thiếu",OR(ISNUMBER(SEARCH("Hình KDB",U13)),ISNUMBER(SEARCH("Hình tele",U13)),ISNUMBER(SEARCH("sai code",U13)))),"Kho đông mát",IF(W13="DC giao thiếu","Chưa xác định",IF(AND(W13="DC pick sai",OR(ISNUMBER(SEARCH("Hình KDB",U13)),ISNUMBER(SEARCH("Hình tele",U13)),ISNUMBER(SEARCH("sai code",U13)),ISNUMBER(SEARCH("ST nhận",U13)))),"Kho đông mát",IF(W13="DC pick sai","Chưa xác định",IF(AND(W13="Hao hụt",N(O13)>0,OR(ISNUMBER(SEARCH("Hình KDB",U13)),ISNUMBER(SEARCH("Hình tele",U13)),ISNUMBER(SEARCH("sai code",U13)),ISNUMBER(SEARCH("ST nhận",U13)))),"Kho đông mát",IF(W13="Hao hụt","Chưa xác định",IF(OR(W13="VT giao sai điểm",W13="Không đạt nhiệt độ",W13="TX giao thiếu kiện",W13="Hàng không đạt CL"),"Kho đông mát",IF(W13="Chưa xác định","Chưa xác định",IF(N(P13)>0,"Chưa xác định","")))))))))))) -> Kho đông mát | AA13: Hoàn Thành | AG13: {=XLOOKUP(F13,'CLV2'!A:A,'CLV2'!E:E)} -> 2.DELICA | AH13: {=XLOOKUP(F13,'CLV2'!A:A,'CLV2'!F:F)} -> 3.DESSERTS | AI13: =if(H13="KG","KG","Pack") -> Pack | AJ13: =K13/I13 -> 1 | AK13: {=XLOOKUP(F13,'GIÁ'!A:A,'GIÁ'!D:D)} -> 9500.00 | AL13: =VALUE(SUBSTITUTE(AK13, ".", ","))*K13 -> 38000 | AM13: =IF($X:$X="Hao hụt", VALUE(SUBSTITUTE($AK13, ".", ","))*O13, 0) -> 0 | AN13: =IF($Y:$Y="Siêu thị", VALUE(SUBSTITUTE(AK13, ".", ","))*P13, 0) -> 0 | AO13: =IF($Z:$Z="Kho đông mát", VALUE(SUBSTITUTE(AK13, ".", ","))*Q13, 0) -> 38000 | AP13: =IF($Z:$Z="Chưa xác định", VALUE(SUBSTITUTE(AK13, ".", ","))*Q13, 0) -> 0
A14: 46231 | B14: 0.53263889 | C14: KFM_BDU_DAN - S01.11 Block A1 Charm Sapphire | D14: {=XLOOKUP(C14,'DS ST'!A:A,'DS ST'!B:B)} -> CHR | E14: {=XLOOKUP($F14,'GIÁ'!$A:$A,'GIÁ'!$E:$E)} -> MÁT | F14: 8936176751090 | G14: TNT - CHUỐI RIM CỐT DỪA 140G | H14: LY | I14: 1 | J14: 0 | K14: =I14-J14 -> 1 | L14: PT1580407 | M14: TRBCHR181 | N14: TO224307 | P14: 1 | Q14: =I14-J14-O14-P14 -> 0 | R14: PT1582229 | V14: Thiếu Item trong kiện | W14: DC thao tác sai | X14: =IF(VALUE(O14)<=0,"",IF(TRIM(W14)="Hao hụt","Hao hụt","Hao hụt")) | Y14: =IF(AND(N(P14)>0,OR(W14="DC giao bù",W14="VT giao sai điểm",W14="ST nhập thiếu",W14="DC pick sai",W14="ST kiểm sai QT",W14="ST thông tin sai/không phản hồi",W14="DC thao tác sai")),"Siêu thị","") -> Siêu thị | Z14: =IF(N(Q14)<=0,"",IF(ISNUMBER(SEARCH("Thiếu kiện",V14)),"Kho đông mát",IF(AND(N(Q14)>0,N(P14)>0,OR(ISNUMBER(SEARCH("Hình KDB",U14)),ISNUMBER(SEARCH("Hình tele",U14)),ISNUMBER(SEARCH("sai code",U14)),ISNUMBER(SEARCH("ST nhận",U14)))),"Kho đông mát",IF(AND(W14="DC giao thiếu",OR(ISNUMBER(SEARCH("Hình KDB",U14)),ISNUMBER(SEARCH("Hình tele",U14)),ISNUMBER(SEARCH("sai code",U14)))),"Kho đông mát",IF(W14="DC giao thiếu","Chưa xác định",IF(AND(W14="DC pick sai",OR(ISNUMBER(SEARCH("Hình KDB",U14)),ISNUMBER(SEARCH("Hình tele",U14)),ISNUMBER(SEARCH("sai code",U14)),ISNUMBER(SEARCH("ST nhận",U14)))),"Kho đông mát",IF(W14="DC pick sai","Chưa xác định",IF(AND(W14="Hao hụt",N(O14)>0,OR(ISNUMBER(SEARCH("Hình KDB",U14)),ISNUMBER(SEARCH("Hình tele",U14)),ISNUMBER(SEARCH("sai code",U14)),ISNUMBER(SEARCH("ST nhận",U14)))),"Kho đông mát",IF(W14="Hao hụt","Chưa xác định",IF(OR(W14="VT giao sai điểm",W14="Không đạt nhiệt độ",W14="TX giao thiếu kiện",W14="Hàng không đạt CL"),"Kho đông mát",IF(W14="Chưa xác định","Chưa xác định",IF(N(P14)>0,"Chưa xác định","")))))))))))) | AA14: Hoàn Thành | AG14: {=XLOOKUP(F14,'CLV2'!A:A,'CLV2'!E:E)} -> 2.DELICA | AH14: {=XLOOKUP(F14,'CLV2'!A:A,'CLV2'!F:F)} -> 3.DESSERTS | AI14: =if(H14="KG","KG","Pack") -> Pack | AJ14: =K14/I14 -> 1 | AK14: {=XLOOKUP(F14,'GIÁ'!A:A,'GIÁ'!D:D)} -> 6650.00 | AL14: =VALUE(SUBSTITUTE(AK14, ".", ","))*K14 -> 6650 | AM14: =IF($X:$X="Hao hụt", VALUE(SUBSTITUTE($AK14, ".", ","))*O14, 0) -> 0 | AN14: =IF($Y:$Y="Siêu thị", VALUE(SUBSTITUTE(AK14, ".", ","))*P14, 0) -> 6650 | AO14: =IF($Z:$Z="Kho đông mát", VALUE(SUBSTITUTE(AK14, ".", ","))*Q14, 0) -> 0 | AP14: =IF($Z:$Z="Chưa xác định", VALUE(SUBSTITUTE(AK14, ".", ","))*Q14, 0) -> 0
A15: 46231 | B15: 0.53263889 | C15: KFM_BDU_DAN - S01.11 Block A1 Charm Sapphire | D15: {=XLOOKUP(C15,'DS ST'!A:A,'DS ST'!B:B)} -> CHR | E15: {=XLOOKUP($F15,'GIÁ'!$A:$A,'GIÁ'!$E:$E)} -> MÁT | F15: 8936076271957 | G15: SAVOURE - BÁNH ỐC KEM 70G | H15: TÚI | I15: 1 | J15: 0 | K15: =I15-J15 -> 1 | L15: PT1580407 | M15: TRBCHR183 | N15: TO224285 | P15: 1 | Q15: =I15-J15-O15-P15 -> 0 | R15: PT1582229 | V15: Thiếu Item trong kiện | W15: DC thao tác sai | X15: =IF(VALUE(O15)<=0,"",IF(TRIM(W15)="Hao hụt","Hao hụt","Hao hụt")) | Y15: =IF(AND(N(P15)>0,OR(W15="DC giao bù",W15="VT giao sai điểm",W15="ST nhập thiếu",W15="DC pick sai",W15="ST kiểm sai QT",W15="ST thông tin sai/không phản hồi",W15="DC thao tác sai")),"Siêu thị","") -> Siêu thị | Z15: =IF(N(Q15)<=0,"",IF(ISNUMBER(SEARCH("Thiếu kiện",V15)),"Kho đông mát",IF(AND(N(Q15)>0,N(P15)>0,OR(ISNUMBER(SEARCH("Hình KDB",U15)),ISNUMBER(SEARCH("Hình tele",U15)),ISNUMBER(SEARCH("sai code",U15)),ISNUMBER(SEARCH("ST nhận",U15)))),"Kho đông mát",IF(AND(W15="DC giao thiếu",OR(ISNUMBER(SEARCH("Hình KDB",U15)),ISNUMBER(SEARCH("Hình tele",U15)),ISNUMBER(SEARCH("sai code",U15)))),"Kho đông mát",IF(W15="DC giao thiếu","Chưa xác định",IF(AND(W15="DC pick sai",OR(ISNUMBER(SEARCH("Hình KDB",U15)),ISNUMBER(SEARCH("Hình tele",U15)),ISNUMBER(SEARCH("sai code",U15)),ISNUMBER(SEARCH("ST nhận",U15)))),"Kho đông mát",IF(W15="DC pick sai","Chưa xác định",IF(AND(W15="Hao hụt",N(O15)>0,OR(ISNUMBER(SEARCH("Hình KDB",U15)),ISNUMBER(SEARCH("Hình tele",U15)),ISNUMBER(SEARCH("sai code",U15)),ISNUMBER(SEARCH("ST nhận",U15)))),"Kho đông mát",IF(W15="Hao hụt","Chưa xác định",IF(OR(W15="VT giao sai điểm",W15="Không đạt nhiệt độ",W15="TX giao thiếu kiện",W15="Hàng không đạt CL"),"Kho đông mát",IF(W15="Chưa xác định","Chưa xác định",IF(N(P15)>0,"Chưa xác định","")))))))))))) | AA15: Hoàn Thành | AG15: {=XLOOKUP(F15,'CLV2'!A:A,'CLV2'!E:E)} -> 2.BAKERY | AH15: {=XLOOKUP(F15,'CLV2'!A:A,'CLV2'!F:F)} -> 3.CAKES | AI15: =if(H15="KG","KG","Pack") -> Pack | AJ15: =K15/I15 -> 1 | AK15: {=XLOOKUP(F15,'GIÁ'!A:A,'GIÁ'!D:D)} -> 8898.99 | AL15: =VALUE(SUBSTITUTE(AK15, ".", ","))*K15 -> 8898.99 | AM15: =IF($X:$X="Hao hụt", VALUE(SUBSTITUTE($AK15, ".", ","))*O15, 0) -> 0 | AN15: =IF($Y:$Y="Siêu thị", VALUE(SUBSTITUTE(AK15, ".", ","))*P15, 0) -> 8898.99 | AO15: =IF($Z:$Z="Kho đông mát", VALUE(SUBSTITUTE(AK15, ".", ","))*Q15, 0) -> 0 | AP15: =IF($Z:$Z="Chưa xác định", VALUE(SUBSTITUTE(AK15, ".", ","))*Q15, 0) -> 0
A16: 46231 | B16: 0.53263889 | C16: KFM_BDU_DAN - S01.11 Block A1 Charm Sapphire | D16: {=XLOOKUP(C16,'DS ST'!A:A,'DS ST'!B:B)} -> CHR | E16: {=XLOOKUP($F16,'GIÁ'!$A:$A,'GIÁ'!$E:$E)} -> MÁT | F16: 8936243700136 | G16: HẢI ĐĂNG - MAKIZUSHI BÒ 163G | H16: HỘP | I16: 1 | J16: 0 | K16: =I16-J16 -> 1 | L16: PT1580407 | M16: TRBCHR183 | N16: TO224285 | P16: 1 | Q16: =I16-J16-O16-P16 -> 0 | R16: PT1582229 | V16: Thiếu Item trong kiện | W16: DC thao tác sai | X16: =IF(VALUE(O16)<=0,"",IF(TRIM(W16)="Hao hụt","Hao hụt","Hao hụt")) | Y16: =IF(AND(N(P16)>0,OR(W16="DC giao bù",W16="VT giao sai điểm",W16="ST nhập thiếu",W16="DC pick sai",W16="ST kiểm sai QT",W16="ST thông tin sai/không phản hồi",W16="DC thao tác sai")),"Siêu thị","") -> Siêu thị | Z16: =IF(N(Q16)<=0,"",IF(ISNUMBER(SEARCH("Thiếu kiện",V16)),"Kho đông mát",IF(AND(N(Q16)>0,N(P16)>0,OR(ISNUMBER(SEARCH("Hình KDB",U16)),ISNUMBER(SEARCH("Hình tele",U16)),ISNUMBER(SEARCH("sai code",U16)),ISNUMBER(SEARCH("ST nhận",U16)))),"Kho đông mát",IF(AND(W16="DC giao thiếu",OR(ISNUMBER(SEARCH("Hình KDB",U16)),ISNUMBER(SEARCH("Hình tele",U16)),ISNUMBER(SEARCH("sai code",U16)))),"Kho đông mát",IF(W16="DC giao thiếu","Chưa xác định",IF(AND(W16="DC pick sai",OR(ISNUMBER(SEARCH("Hình KDB",U16)),ISNUMBER(SEARCH("Hình tele",U16)),ISNUMBER(SEARCH("sai code",U16)),ISNUMBER(SEARCH("ST nhận",U16)))),"Kho đông mát",IF(W16="DC pick sai","Chưa xác định",IF(AND(W16="Hao hụt",N(O16)>0,OR(ISNUMBER(SEARCH("Hình KDB",U16)),ISNUMBER(SEARCH("Hình tele",U16)),ISNUMBER(SEARCH("sai code",U16)),ISNUMBER(SEARCH("ST nhận",U16)))),"Kho đông mát",IF(W16="Hao hụt","Chưa xác định",IF(OR(W16="VT giao sai điểm",W16="Không đạt nhiệt độ",W16="TX giao thiếu kiện",W16="Hàng không đạt CL"),"Kho đông mát",IF(W16="Chưa xác định","Chưa xác định",IF(N(P16)>0,"Chưa xác định","")))))))))))) | AA16: Hoàn Thành | AG16: {=XLOOKUP(F16,'CLV2'!A:A,'CLV2'!E:E)} -> 2.DELICA | AH16: {=XLOOKUP(F16,'CLV2'!A:A,'CLV2'!F:F)} -> 3.COLD AND HOT DELICA | AI16: =if(H16="KG","KG","Pack") -> Pack | AJ16: =K16/I16 -> 1 | AK16: {=XLOOKUP(F16,'GIÁ'!A:A,'GIÁ'!D:D)} -> 21700.00 | AL16: =VALUE(SUBSTITUTE(AK16, ".", ","))*K16 -> 21700 | AM16: =IF($X:$X="Hao hụt", VALUE(SUBSTITUTE($AK16, ".", ","))*O16, 0) -> 0 | AN16: =IF($Y:$Y="Siêu thị", VALUE(SUBSTITUTE(AK16, ".", ","))*P16, 0) -> 21700 | AO16: =IF($Z:$Z="Kho đông mát", VALUE(SUBSTITUTE(AK16, ".", ","))*Q16, 0) -> 0 | AP16: =IF($Z:$Z="Chưa xác định", VALUE(SUBSTITUTE(AK16, ".", ","))*Q16, 0) -> 0
A17: 46231 | B17: 0.53263889 | C17: KFM_BDU_DAN - S01.11 Block A1 Charm Sapphire | D17: {=XLOOKUP(C17,'DS ST'!A:A,'DS ST'!B:B)} -> CHR | E17: {=XLOOKUP($F17,'GIÁ'!$A:$A,'GIÁ'!$E:$E)} -> MÁT | F17: 8936243700174 | G17: HẢI ĐĂNG - CƠM NGHÊU THỊT XÀO CAY 282G | H17: HỘP | I17: 1 | J17: 0 | K17: =I17-J17 -> 1 | L17: PT1580407 | M17: TRBCHR183 | N17: TO224285 | P17: 1 | Q17: =I17-J17-O17-P17 -> 0 | R17: PT1582229 | V17: Thiếu Item trong kiện | W17: DC thao tác sai | X17: =IF(VALUE(O17)<=0,"",IF(TRIM(W17)="Hao hụt","Hao hụt","Hao hụt")) | Y17: =IF(AND(N(P17)>0,OR(W17="DC giao bù",W17="VT giao sai điểm",W17="ST nhập thiếu",W17="DC pick sai",W17="ST kiểm sai QT",W17="ST thông tin sai/không phản hồi",W17="DC thao tác sai")),"Siêu thị","") -> Siêu thị | Z17: =IF(N(Q17)<=0,"",IF(ISNUMBER(SEARCH("Thiếu kiện",V17)),"Kho đông mát",IF(AND(N(Q17)>0,N(P17)>0,OR(ISNUMBER(SEARCH("Hình KDB",U17)),ISNUMBER(SEARCH("Hình tele",U17)),ISNUMBER(SEARCH("sai code",U17)),ISNUMBER(SEARCH("ST nhận",U17)))),"Kho đông mát",IF(AND(W17="DC giao thiếu",OR(ISNUMBER(SEARCH("Hình KDB",U17)),ISNUMBER(SEARCH("Hình tele",U17)),ISNUMBER(SEARCH("sai code",U17)))),"Kho đông mát",IF(W17="DC giao thiếu","Chưa xác định",IF(AND(W17="DC pick sai",OR(ISNUMBER(SEARCH("Hình KDB",U17)),ISNUMBER(SEARCH("Hình tele",U17)),ISNUMBER(SEARCH("sai code",U17)),ISNUMBER(SEARCH("ST nhận",U17)))),"Kho đông mát",IF(W17="DC pick sai","Chưa xác định",IF(AND(W17="Hao hụt",N(O17)>0,OR(ISNUMBER(SEARCH("Hình KDB",U17)),ISNUMBER(SEARCH("Hình tele",U17)),ISNUMBER(SEARCH("sai code",U17)),ISNUMBER(SEARCH("ST nhận",U17)))),"Kho đông mát",IF(W17="Hao hụt","Chưa xác định",IF(OR(W17="VT giao sai điểm",W17="Không đạt nhiệt độ",W17="TX giao thiếu kiện",W17="Hàng không đạt CL"),"Kho đông mát",IF(W17="Chưa xác định","Chưa xác định",IF(N(P17)>0,"Chưa xác định","")))))))))))) | AA17: Hoàn Thành | AG17: {=XLOOKUP(F17,'CLV2'!A:A,'CLV2'!E:E)} -> 2.DELICA | AH17: {=XLOOKUP(F17,'CLV2'!A:A,'CLV2'!F:F)} -> 3.COLD AND HOT DELICA | AI17: =if(H17="KG","KG","Pack") -> Pack | AJ17: =K17/I17 -> 1 | AK17: {=XLOOKUP(F17,'GIÁ'!A:A,'GIÁ'!D:D)} -> 23138.19 | AL17: =VALUE(SUBSTITUTE(AK17, ".", ","))*K17 -> 23138.19 | AM17: =IF($X:$X="Hao hụt", VALUE(SUBSTITUTE($AK17, ".", ","))*O17, 0) -> 0 | AN17: =IF($Y:$Y="Siêu thị", VALUE(SUBSTITUTE(AK17, ".", ","))*P17, 0) -> 23138.19 | AO17: =IF($Z:$Z="Kho đông mát", VALUE(SUBSTITUTE(AK17, ".", ","))*Q17, 0) -> 0 | AP17: =IF($Z:$Z="Chưa xác định", VALUE(SUBSTITUTE(AK17, ".", ","))*Q17, 0) -> 0
A18: 46231 | B18: 0.53263889 | C18: KFM_BDU_DAN - S01.11 Block A1 Charm Sapphire | D18: {=XLOOKUP(C18,'DS ST'!A:A,'DS ST'!B:B)} -> CHR | E18: {=XLOOKUP($F18,'GIÁ'!$A:$A,'GIÁ'!$E:$E)} -> MÁT | F18: 8936243700167 | G18: HẢI ĐĂNG - CƠM CHIÊN TRỨNG CUỘN 269G | H18: HỘP | I18: 1 | J18: 0 | K18: =I18-J18 -> 1 | L18: PT1580407 | M18: TRBCHR184 | N18: TO224294 | P18: 1 | Q18: =I18-J18-O18-P18 -> 0 | R18: PT1582229 | V18: Thiếu Item trong kiện | W18: DC thao tác sai | X18: =IF(VALUE(O18)<=0,"",IF(TRIM(W18)="Hao hụt","Hao hụt","Hao hụt")) | Y18: =IF(AND(N(P18)>0,OR(W18="DC giao bù",W18="VT giao sai điểm",W18="ST nhập thiếu",W18="DC pick sai",W18="ST kiểm sai QT",W18="ST thông tin sai/không phản hồi",W18="DC thao tác sai")),"Siêu thị","") -> Siêu thị | Z18: =IF(N(Q18)<=0,"",IF(ISNUMBER(SEARCH("Thiếu kiện",V18)),"Kho đông mát",IF(AND(N(Q18)>0,N(P18)>0,OR(ISNUMBER(SEARCH("Hình KDB",U18)),ISNUMBER(SEARCH("Hình tele",U18)),ISNUMBER(SEARCH("sai code",U18)),ISNUMBER(SEARCH("ST nhận",U18)))),"Kho đông mát",IF(AND(W18="DC giao thiếu",OR(ISNUMBER(SEARCH("Hình KDB",U18)),ISNUMBER(SEARCH("Hình tele",U18)),ISNUMBER(SEARCH("sai code",U18)))),"Kho đông mát",IF(W18="DC giao thiếu","Chưa xác định",IF(AND(W18="DC pick sai",OR(ISNUMBER(SEARCH("Hình KDB",U18)),ISNUMBER(SEARCH("Hình tele",U18)),ISNUMBER(SEARCH("sai code",U18)),ISNUMBER(SEARCH("ST nhận",U18)))),"Kho đông mát",IF(W18="DC pick sai","Chưa xác định",IF(AND(W18="Hao hụt",N(O18)>0,OR(ISNUMBER(SEARCH("Hình KDB",U18)),ISNUMBER(SEARCH("Hình tele",U18)),ISNUMBER(SEARCH("sai code",U18)),ISNUMBER(SEARCH("ST nhận",U18)))),"Kho đông mát",IF(W18="Hao hụt","Chưa xác định",IF(OR(W18="VT giao sai điểm",W18="Không đạt nhiệt độ",W18="TX giao thiếu kiện",W18="Hàng không đạt CL"),"Kho đông mát",IF(W18="Chưa xác định","Chưa xác định",IF(N(P18)>0,"Chưa xác định","")))))))))))) | AA18: Hoàn Thành | AG18: {=XLOOKUP(F18,'CLV2'!A:A,'CLV2'!E:E)} -> 2.DELICA | AH18: {=XLOOKUP(F18,'CLV2'!A:A,'CLV2'!F:F)} -> 3.COLD AND HOT DELICA | AI18: =if(H18="KG","KG","Pack") -> Pack | AJ18: =K18/I18 -> 1 | AK18: {=XLOOKUP(F18,'GIÁ'!A:A,'GIÁ'!D:D)} -> 20400.00 | AL18: =VALUE(SUBSTITUTE(AK18, ".", ","))*K18 -> 20400 | AM18: =IF($X:$X="Hao hụt", VALUE(SUBSTITUTE($AK18, ".", ","))*O18, 0) -> 0 | AN18: =IF($Y:$Y="Siêu thị", VALUE(SUBSTITUTE(AK18, ".", ","))*P18, 0) -> 20400 | AO18: =IF($Z:$Z="Kho đông mát", VALUE(SUBSTITUTE(AK18, ".", ","))*Q18, 0) -> 0 | AP18: =IF($Z:$Z="Chưa xác định", VALUE(SUBSTITUTE(AK18, ".", ","))*Q18, 0) -> 0
A19: 46231 | B19: 0.53263889 | C19: KFM_BDU_DAN - S01.11 Block A1 Charm Sapphire | D19: {=XLOOKUP(C19,'DS ST'!A:A,'DS ST'!B:B)} -> CHR | E19: {=XLOOKUP($F19,'GIÁ'!$A:$A,'GIÁ'!$E:$E)} -> MÁT | F19: 8938505512211 | G19: SENTA - KHOAI MÔN GỌT VỎ 400G | H19: GÓI | I19: 1 | J19: 0 | K19: =I19-J19 -> 1 | L19: PT1580407 | M19: TRBCHR194 | N19: TO224318 | P19: 1 | Q19: =I19-J19-O19-P19 -> 0 | R19: PT1582196 | V19: Thiếu Item trong kiện | W19: DC thao tác sai | X19: =IF(VALUE(O19)<=0,"",IF(TRIM(W19)="Hao hụt","Hao hụt","Hao hụt")) | Y19: =IF(AND(N(P19)>0,OR(W19="DC giao bù",W19="VT giao sai điểm",W19="ST nhập thiếu",W19="DC pick sai",W19="ST kiểm sai QT",W19="ST thông tin sai/không phản hồi",W19="DC thao tác sai")),"Siêu thị","") -> Siêu thị | Z19: =IF(N(Q19)<=0,"",IF(ISNUMBER(SEARCH("Thiếu kiện",V19)),"Kho đông mát",IF(AND(N(Q19)>0,N(P19)>0,OR(ISNUMBER(SEARCH("Hình KDB",U19)),ISNUMBER(SEARCH("Hình tele",U19)),ISNUMBER(SEARCH("sai code",U19)),ISNUMBER(SEARCH("ST nhận",U19)))),"Kho đông mát",IF(AND(W19="DC giao thiếu",OR(ISNUMBER(SEARCH("Hình KDB",U19)),ISNUMBER(SEARCH("Hình tele",U19)),ISNUMBER(SEARCH("sai code",U19)))),"Kho đông mát",IF(W19="DC giao thiếu","Chưa xác định",IF(AND(W19="DC pick sai",OR(ISNUMBER(SEARCH("Hình KDB",U19)),ISNUMBER(SEARCH("Hình tele",U19)),ISNUMBER(SEARCH("sai code",U19)),ISNUMBER(SEARCH("ST nhận",U19)))),"Kho đông mát",IF(W19="DC pick sai","Chưa xác định",IF(AND(W19="Hao hụt",N(O19)>0,OR(ISNUMBER(SEARCH("Hình KDB",U19)),ISNUMBER(SEARCH("Hình tele",U19)),ISNUMBER(SEARCH("sai code",U19)),ISNUMBER(SEARCH("ST nhận",U19)))),"Kho đông mát",IF(W19="Hao hụt","Chưa xác định",IF(OR(W19="VT giao sai điểm",W19="Không đạt nhiệt độ",W19="TX giao thiếu kiện",W19="Hàng không đạt CL"),"Kho đông mát",IF(W19="Chưa xác định","Chưa xác định",IF(N(P19)>0,"Chưa xác định","")))))))))))) | AA19: Hoàn Thành | AG19: {=XLOOKUP(F19,'CLV2'!A:A,'CLV2'!E:E)} -> 2.VEGETABLES | AH19: {=XLOOKUP(F19,'CLV2'!A:A,'CLV2'!F:F)} -> 3.PROCESSED VEGGIES | AI19: =if(H19="KG","KG","Pack") -> Pack | AJ19: =K19/I19 -> 1 | AK19: {=XLOOKUP(F19,'GIÁ'!A:A,'GIÁ'!D:D)} -> 22493.70 | AL19: =VALUE(SUBSTITUTE(AK19, ".", ","))*K19 -> 22493.7 | AM19: =IF($X:$X="Hao hụt", VALUE(SUBSTITUTE($AK19, ".", ","))*O19, 0) -> 0 | AN19: =IF($Y:$Y="Siêu thị", VALUE(SUBSTITUTE(AK19, ".", ","))*P19, 0) -> 22493.7 | AO19: =IF($Z:$Z="Kho đông mát", VALUE(SUBSTITUTE(AK19, ".", ","))*Q19, 0) -> 0 | AP19: =IF($Z:$Z="Chưa xác định", VALUE(SUBSTITUTE(AK19, ".", ","))*Q19, 0) -> 0
A20: 46231 | B20: 0.53263889 | C20: KFM_BDU_DAN - S01.11 Block A1 Charm Sapphire | D20: {=XLOOKUP(C20,'DS ST'!A:A,'DS ST'!B:B)} -> CHR | E20: {=XLOOKUP($F20,'GIÁ'!$A:$A,'GIÁ'!$E:$E)} -> MÁT | F20: 8935335403443 | G20: THỌ PHÁT - BÁNH BAO GÀ NƯỚNG PHÔ MAI 100G | H20: CÁI | I20: 13 | J20: 0 | K20: =I20-J20 -> 13 | L20: PT1580407 | M20: TRBCHR222 | N20: TO224291 | P20: 13 | Q20: =I20-J20-O20-P20 -> 0 | R20: PT1582138 | V20: Thiếu Item trong kiện | W20: DC thao tác sai | X20: =IF(VALUE(O20)<=0,"",IF(TRIM(W20)="Hao hụt","Hao hụt","Hao hụt")) | Y20: =IF(AND(N(P20)>0,OR(W20="DC giao bù",W20="VT giao sai điểm",W20="ST nhập thiếu",W20="DC pick sai",W20="ST kiểm sai QT",W20="ST thông tin sai/không phản hồi",W20="DC thao tác sai")),"Siêu thị","") -> Siêu thị | Z20: =IF(N(Q20)<=0,"",IF(ISNUMBER(SEARCH("Thiếu kiện",V20)),"Kho đông mát",IF(AND(N(Q20)>0,N(P20)>0,OR(ISNUMBER(SEARCH("Hình KDB",U20)),ISNUMBER(SEARCH("Hình tele",U20)),ISNUMBER(SEARCH("sai code",U20)),ISNUMBER(SEARCH("ST nhận",U20)))),"Kho đông mát",IF(AND(W20="DC giao thiếu",OR(ISNUMBER(SEARCH("Hình KDB",U20)),ISNUMBER(SEARCH("Hình tele",U20)),ISNUMBER(SEARCH("sai code",U20)))),"Kho đông mát",IF(W20="DC giao thiếu","Chưa xác định",IF(AND(W20="DC pick sai",OR(ISNUMBER(SEARCH("Hình KDB",U20)),ISNUMBER(SEARCH("Hình tele",U20)),ISNUMBER(SEARCH("sai code",U20)),ISNUMBER(SEARCH("ST nhận",U20)))),"Kho đông mát",IF(W20="DC pick sai","Chưa xác định",IF(AND(W20="Hao hụt",N(O20)>0,OR(ISNUMBER(SEARCH("Hình KDB",U20)),ISNUMBER(SEARCH("Hình tele",U20)),ISNUMBER(SEARCH("sai code",U20)),ISNUMBER(SEARCH("ST nhận",U20)))),"Kho đông mát",IF(W20="Hao hụt","Chưa xác định",IF(OR(W20="VT giao sai điểm",W20="Không đạt nhiệt độ",W20="TX giao thiếu kiện",W20="Hàng không đạt CL"),"Kho đông mát",IF(W20="Chưa xác định","Chưa xác định",IF(N(P20)>0,"Chưa xác định","")))))))))))) | AA20: Hoàn Thành | AG20: {=XLOOKUP(F20,'CLV2'!A:A,'CLV2'!E:E)} -> 2.DELICA | AH20: {=XLOOKUP(F20,'CLV2'!A:A,'CLV2'!F:F)} -> 3.COLD AND HOT DELICA | AI20: =if(H20="KG","KG","Pack") -> Pack | AJ20: =K20/I20 -> 1 | AK20: {=XLOOKUP(F20,'GIÁ'!A:A,'GIÁ'!D:D)} -> 11574.00 | AL20: =VALUE(SUBSTITUTE(AK20, ".", ","))*K20 -> 150462 | AM20: =IF($X:$X="Hao hụt", VALUE(SUBSTITUTE($AK20, ".", ","))*O20, 0) -> 0 | AN20: =IF($Y:$Y="Siêu thị", VALUE(SUBSTITUTE(AK20, ".", ","))*P20, 0) -> 150462 | AO20: =IF($Z:$Z="Kho đông mát", VALUE(SUBSTITUTE(AK20, ".", ","))*Q20, 0) -> 0 | AP20: =IF($Z:$Z="Chưa xác định", VALUE(SUBSTITUTE(AK20, ".", ","))*Q20, 0) -> 0
A21: 46231 | B21: 0.53263889 | C21: KFM_BDU_DAN - S01.11 Block A1 Charm Sapphire | D21: {=XLOOKUP(C21,'DS ST'!A:A,'DS ST'!B:B)} -> CHR | E21: {=XLOOKUP($F21,'GIÁ'!$A:$A,'GIÁ'!$E:$E)} -> MÁT | F21: 8938511301618 | G21: THƠM - HỒNG TRÀ SỮA BÁ TƯỚC 250ML | H21: CHAI | I21: 3 | J21: 0 | K21: =I21-J21 -> 3 | L21: PT1580407 | M21: TRBCHR222 | N21: TO224291 | P21: 3 | Q21: =I21-J21-O21-P21 -> 0 | R21: PT1582138 | V21: Thiếu Item trong kiện | W21: DC thao tác sai | X21: =IF(VALUE(O21)<=0,"",IF(TRIM(W21)="Hao hụt","Hao hụt","Hao hụt")) | Y21: =IF(AND(N(P21)>0,OR(W21="DC giao bù",W21="VT giao sai điểm",W21="ST nhập thiếu",W21="DC pick sai",W21="ST kiểm sai QT",W21="ST thông tin sai/không phản hồi",W21="DC thao tác sai")),"Siêu thị","") -> Siêu thị | Z21: =IF(N(Q21)<=0,"",IF(ISNUMBER(SEARCH("Thiếu kiện",V21)),"Kho đông mát",IF(AND(N(Q21)>0,N(P21)>0,OR(ISNUMBER(SEARCH("Hình KDB",U21)),ISNUMBER(SEARCH("Hình tele",U21)),ISNUMBER(SEARCH("sai code",U21)),ISNUMBER(SEARCH("ST nhận",U21)))),"Kho đông mát",IF(AND(W21="DC giao thiếu",OR(ISNUMBER(SEARCH("Hình KDB",U21)),ISNUMBER(SEARCH("Hình tele",U21)),ISNUMBER(SEARCH("sai code",U21)))),"Kho đông mát",IF(W21="DC giao thiếu","Chưa xác định",IF(AND(W21="DC pick sai",OR(ISNUMBER(SEARCH("Hình KDB",U21)),ISNUMBER(SEARCH("Hình tele",U21)),ISNUMBER(SEARCH("sai code",U21)),ISNUMBER(SEARCH("ST nhận",U21)))),"Kho đông mát",IF(W21="DC pick sai","Chưa xác định",IF(AND(W21="Hao hụt",N(O21)>0,OR(ISNUMBER(SEARCH("Hình KDB",U21)),ISNUMBER(SEARCH("Hình tele",U21)),ISNUMBER(SEARCH("sai code",U21)),ISNUMBER(SEARCH("ST nhận",U21)))),"Kho đông mát",IF(W21="Hao hụt","Chưa xác định",IF(OR(W21="VT giao sai điểm",W21="Không đạt nhiệt độ",W21="TX giao thiếu kiện",W21="Hàng không đạt CL"),"Kho đông mát",IF(W21="Chưa xác định","Chưa xác định",IF(N(P21)>0,"Chưa xác định","")))))))))))) | AA21: Hoàn Thành | AG21: {=XLOOKUP(F21,'CLV2'!A:A,'CLV2'!E:E)} -> 2.DELICA | AH21: {=XLOOKUP(F21,'CLV2'!A:A,'CLV2'!F:F)} -> 3.DRINKS | AI21: =if(H21="KG","KG","Pack") -> Pack | AJ21: =K21/I21 -> 1 | AK21: {=XLOOKUP(F21,'GIÁ'!A:A,'GIÁ'!D:D)} -> 11687.57 | AL21: =VALUE(SUBSTITUTE(AK21, ".", ","))*K21 -> 35062.71 | AM21: =IF($X:$X="Hao hụt", VALUE(SUBSTITUTE($AK21, ".", ","))*O21, 0) -> 0 | AN21: =IF($Y:$Y="Siêu thị", VALUE(SUBSTITUTE(AK21, ".", ","))*P21, 0) -> 35062.71 | AO21: =IF($Z:$Z="Kho đông mát", VALUE(SUBSTITUTE(AK21, ".", ","))*Q21, 0) -> 0 | AP21: =IF($Z:$Z="Chưa xác định", VALUE(SUBSTITUTE(AK21, ".", ","))*Q21, 0) -> 0
A22: 46231 | B22: 0.53263889 | C22: KFM_BDU_DAN - S01.11 Block A1 Charm Sapphire | D22: {=XLOOKUP(C22,'DS ST'!A:A,'DS ST'!B:B)} -> CHR | E22: {=XLOOKUP($F22,'GIÁ'!$A:$A,'GIÁ'!$E:$E)} -> MÁT | F22: 11542 | G22: HỖN HỢP SU SU VÀ CÀ RỐT 300G | H22: KHAY | I22: 2 | J22: 0 | K22: =I22-J22 -> 2 | L22: PT1580407 | M22: TRBCHR224 | N22: TO224283 | Q22: =I22-J22-O22-P22 -> 2 | V22: Thiếu Item trong kiện | W22: DC giao thiếu | X22: =IF(VALUE(O22)<=0,"",IF(TRIM(W22)="Hao hụt","Hao hụt","Hao hụt")) | Y22: =IF(AND(N(P22)>0,OR(W22="DC giao bù",W22="VT giao sai điểm",W22="ST nhập thiếu",W22="DC pick sai",W22="ST kiểm sai QT",W22="ST thông tin sai/không phản hồi",W22="DC thao tác sai")),"Siêu thị","") | Z22: Kho đông mát | AA22: Hoàn Thành | AB22: CHR.mp4 | AC22: Đồng ý claim | AG22: {=XLOOKUP(F22,'CLV2'!A:A,'CLV2'!E:E)} -> 2.VEGETABLES | AH22: {=XLOOKUP(F22,'CLV2'!A:A,'CLV2'!F:F)} -> 3.PROCESSED VEGGIES | AI22: =if(H22="KG","KG","Pack") -> Pack | AJ22: =K22/I22 -> 1 | AK22: {=XLOOKUP(F22,'GIÁ'!A:A,'GIÁ'!D:D)} -> 14473.30 | AL22: =VALUE(SUBSTITUTE(AK22, ".", ","))*K22 -> 28946.6 | AM22: =IF($X:$X="Hao hụt", VALUE(SUBSTITUTE($AK22, ".", ","))*O22, 0) -> 0 | AN22: =IF($Y:$Y="Siêu thị", VALUE(SUBSTITUTE(AK22, ".", ","))*P22, 0) -> 0 | AO22: =IF($Z:$Z="Kho đông mát", VALUE(SUBSTITUTE(AK22, ".", ","))*Q22, 0) -> 28946.6 | AP22: =IF($Z:$Z="Chưa xác định", VALUE(SUBSTITUTE(AK22, ".", ","))*Q22, 0) -> 0
A23: 46231 | B23: 0.53263889 | C23: KFM_BDU_DAN - S01.11 Block A1 Charm Sapphire | D23: {=XLOOKUP(C23,'DS ST'!A:A,'DS ST'!B:B)} -> CHR | E23: {=XLOOKUP($F23,'GIÁ'!$A:$A,'GIÁ'!$E:$E)} -> MÁT | F23: 8935335403436 | G23: THỌ PHÁT - BÁNH BAO THỊT HEO 2 TRỨNG CÚT 150G | H23: CÁI | I23: 19 | J23: 0 | K23: =I23-J23 -> 19 | L23: PT1580407 | M23: TRBCHR225 | N23: TO224304 | P23: 19 | Q23: =I23-J23-O23-P23 -> 0 | R23: PT1582233 | V23: Thiếu Item trong kiện | W23: DC thao tác sai | X23: =IF(VALUE(O23)<=0,"",IF(TRIM(W23)="Hao hụt","Hao hụt","Hao hụt")) | Y23: =IF(AND(N(P23)>0,OR(W23="DC giao bù",W23="VT giao sai điểm",W23="ST nhập thiếu",W23="DC pick sai",W23="ST kiểm sai QT",W23="ST thông tin sai/không phản hồi",W23="DC thao tác sai")),"Siêu thị","") -> Siêu thị | Z23: =IF(N(Q23)<=0,"",IF(ISNUMBER(SEARCH("Thiếu kiện",V23)),"Kho đông mát",IF(AND(N(Q23)>0,N(P23)>0,OR(ISNUMBER(SEARCH("Hình KDB",U23)),ISNUMBER(SEARCH("Hình tele",U23)),ISNUMBER(SEARCH("sai code",U23)),ISNUMBER(SEARCH("ST nhận",U23)))),"Kho đông mát",IF(AND(W23="DC giao thiếu",OR(ISNUMBER(SEARCH("Hình KDB",U23)),ISNUMBER(SEARCH("Hình tele",U23)),ISNUMBER(SEARCH("sai code",U23)))),"Kho đông mát",IF(W23="DC giao thiếu","Chưa xác định",IF(AND(W23="DC pick sai",OR(ISNUMBER(SEARCH("Hình KDB",U23)),ISNUMBER(SEARCH("Hình tele",U23)),ISNUMBER(SEARCH("sai code",U23)),ISNUMBER(SEARCH("ST nhận",U23)))),"Kho đông mát",IF(W23="DC pick sai","Chưa xác định",IF(AND(W23="Hao hụt",N(O23)>0,OR(ISNUMBER(SEARCH("Hình KDB",U23)),ISNUMBER(SEARCH("Hình tele",U23)),ISNUMBER(SEARCH("sai code",U23)),ISNUMBER(SEARCH("ST nhận",U23)))),"Kho đông mát",IF(W23="Hao hụt","Chưa xác định",IF(OR(W23="VT giao sai điểm",W23="Không đạt nhiệt độ",W23="TX giao thiếu kiện",W23="Hàng không đạt CL"),"Kho đông mát",IF(W23="Chưa xác định","Chưa xác định",IF(N(P23)>0,"Chưa xác định","")))))))))))) | AA23: Hoàn Thành | AG23: {=XLOOKUP(F23,'CLV2'!A:A,'CLV2'!E:E)} -> 2.DELICA | AH23: {=XLOOKUP(F23,'CLV2'!A:A,'CLV2'!F:F)} -> 3.COLD AND HOT DELICA | AI23: =if(H23="KG","KG","Pack") -> Pack | AJ23: =K23/I23 -> 1 | AK23: {=XLOOKUP(F23,'GIÁ'!A:A,'GIÁ'!D:D)} -> 12963.00 | AL23: =VALUE(SUBSTITUTE(AK23, ".", ","))*K23 -> 246297 | AM23: =IF($X:$X="Hao hụt", VALUE(SUBSTITUTE($AK23, ".", ","))*O23, 0) -> 0 | AN23: =IF($Y:$Y="Siêu thị", VALUE(SUBSTITUTE(AK23, ".", ","))*P23, 0) -> 246297 | AO23: =IF($Z:$Z="Kho đông mát", VALUE(SUBSTITUTE(AK23, ".", ","))*Q23, 0) -> 0 | AP23: =IF($Z:$Z="Chưa xác định", VALUE(SUBSTITUTE(AK23, ".", ","))*Q23, 0) -> 0
A24: 46231 | B24: 0.53263889 | C24: KFM_BDU_DAN - S01.11 Block A1 Charm Sapphire | D24: {=XLOOKUP(C24,'DS ST'!A:A,'DS ST'!B:B)} -> CHR | E24: {=XLOOKUP($F24,'GIÁ'!$A:$A,'GIÁ'!$E:$E)} -> MÁT | F24: 8936049693892 | G24: HASFARM - HỖN HỢP XÀ LÁCH BABY 100G ( ĐÃ RỬA SẠCH) | H24: HỘP | I24: 1 | J24: 0 | K24: =I24-J24 -> 1 | L24: PT1580407 | M24: TRBCHR225 | N24: TO224304 | P24: 1 | Q24: =I24-J24-O24-P24 -> 0 | R24: PT1582103 | V24: Thiếu Item trong kiện | W24: DC thao tác sai | X24: =IF(VALUE(O24)<=0,"",IF(TRIM(W24)="Hao hụt","Hao hụt","Hao hụt")) | Y24: =IF(AND(N(P24)>0,OR(W24="DC giao bù",W24="VT giao sai điểm",W24="ST nhập thiếu",W24="DC pick sai",W24="ST kiểm sai QT",W24="ST thông tin sai/không phản hồi",W24="DC thao tác sai")),"Siêu thị","") -> Siêu thị | Z24: =IF(N(Q24)<=0,"",IF(ISNUMBER(SEARCH("Thiếu kiện",V24)),"Kho đông mát",IF(AND(N(Q24)>0,N(P24)>0,OR(ISNUMBER(SEARCH("Hình KDB",U24)),ISNUMBER(SEARCH("Hình tele",U24)),ISNUMBER(SEARCH("sai code",U24)),ISNUMBER(SEARCH("ST nhận",U24)))),"Kho đông mát",IF(AND(W24="DC giao thiếu",OR(ISNUMBER(SEARCH("Hình KDB",U24)),ISNUMBER(SEARCH("Hình tele",U24)),ISNUMBER(SEARCH("sai code",U24)))),"Kho đông mát",IF(W24="DC giao thiếu","Chưa xác định",IF(AND(W24="DC pick sai",OR(ISNUMBER(SEARCH("Hình KDB",U24)),ISNUMBER(SEARCH("Hình tele",U24)),ISNUMBER(SEARCH("sai code",U24)),ISNUMBER(SEARCH("ST nhận",U24)))),"Kho đông mát",IF(W24="DC pick sai","Chưa xác định",IF(AND(W24="Hao hụt",N(O24)>0,OR(ISNUMBER(SEARCH("Hình KDB",U24)),ISNUMBER(SEARCH("Hình tele",U24)),ISNUMBER(SEARCH("sai code",U24)),ISNUMBER(SEARCH("ST nhận",U24)))),"Kho đông mát",IF(W24="Hao hụt","Chưa xác định",IF(OR(W24="VT giao sai điểm",W24="Không đạt nhiệt độ",W24="TX giao thiếu kiện",W24="Hàng không đạt CL"),"Kho đông mát",IF(W24="Chưa xác định","Chưa xác định",IF(N(P24)>0,"Chưa xác định","")))))))))))) | AA24: Hoàn Thành | AG24: {=XLOOKUP(F24,'CLV2'!A:A,'CLV2'!E:E)} -> 2.VEGETABLES | AH24: {=XLOOKUP(F24,'CLV2'!A:A,'CLV2'!F:F)} -> 3.LETTUCE, SNACKABLES | AI24: =if(H24="KG","KG","Pack") -> Pack | AJ24: =K24/I24 -> 1 | AK24: {=XLOOKUP(F24,'GIÁ'!A:A,'GIÁ'!D:D)} -> 20378.31 | AL24: =VALUE(SUBSTITUTE(AK24, ".", ","))*K24 -> 20378.31 | AM24: =IF($X:$X="Hao hụt", VALUE(SUBSTITUTE($AK24, ".", ","))*O24, 0) -> 0 | AN24: =IF($Y:$Y="Siêu thị", VALUE(SUBSTITUTE(AK24, ".", ","))*P24, 0) -> 20378.31 | AO24: =IF($Z:$Z="Kho đông mát", VALUE(SUBSTITUTE(AK24, ".", ","))*Q24, 0) -> 0 | AP24: =IF($Z:$Z="Chưa xác định", VALUE(SUBSTITUTE(AK24, ".", ","))*Q24, 0) -> 0
A25: 46231 | B25: 0.53263889 | C25: KFM_BDU_DAN - S01.11 Block A1 Charm Sapphire | D25: {=XLOOKUP(C25,'DS ST'!A:A,'DS ST'!B:B)} -> CHR | E25: {=XLOOKUP($F25,'GIÁ'!$A:$A,'GIÁ'!$E:$E)} -> MÁT | F25: 8936049694271 | G25: HỖN HỢP BẮP CẢI TRẮNG VÀ CÀ RỐT THÁI SỢI (ĐÃ RỬA SẠCH) 200G | H25: PACK | I25: 1 | J25: 0 | K25: =I25-J25 -> 1 | L25: PT1580407 | M25: TRBCHR225 | N25: TO224304 | P25: 1 | Q25: =I25-J25-O25-P25 -> 0 | R25: PT1582103 | V25: Thiếu Item trong kiện | W25: DC thao tác sai | X25: =IF(VALUE(O25)<=0,"",IF(TRIM(W25)="Hao hụt","Hao hụt","Hao hụt")) | Y25: =IF(AND(N(P25)>0,OR(W25="DC giao bù",W25="VT giao sai điểm",W25="ST nhập thiếu",W25="DC pick sai",W25="ST kiểm sai QT",W25="ST thông tin sai/không phản hồi",W25="DC thao tác sai")),"Siêu thị","") -> Siêu thị | Z25: =IF(N(Q25)<=0,"",IF(ISNUMBER(SEARCH("Thiếu kiện",V25)),"Kho đông mát",IF(AND(N(Q25)>0,N(P25)>0,OR(ISNUMBER(SEARCH("Hình KDB",U25)),ISNUMBER(SEARCH("Hình tele",U25)),ISNUMBER(SEARCH("sai code",U25)),ISNUMBER(SEARCH("ST nhận",U25)))),"Kho đông mát",IF(AND(W25="DC giao thiếu",OR(ISNUMBER(SEARCH("Hình KDB",U25)),ISNUMBER(SEARCH("Hình tele",U25)),ISNUMBER(SEARCH("sai code",U25)))),"Kho đông mát",IF(W25="DC giao thiếu","Chưa xác định",IF(AND(W25="DC pick sai",OR(ISNUMBER(SEARCH("Hình KDB",U25)),ISNUMBER(SEARCH("Hình tele",U25)),ISNUMBER(SEARCH("sai code",U25)),ISNUMBER(SEARCH("ST nhận",U25)))),"Kho đông mát",IF(W25="DC pick sai","Chưa xác định",IF(AND(W25="Hao hụt",N(O25)>0,OR(ISNUMBER(SEARCH("Hình KDB",U25)),ISNUMBER(SEARCH("Hình tele",U25)),ISNUMBER(SEARCH("sai code",U25)),ISNUMBER(SEARCH("ST nhận",U25)))),"Kho đông mát",IF(W25="Hao hụt","Chưa xác định",IF(OR(W25="VT giao sai điểm",W25="Không đạt nhiệt độ",W25="TX giao thiếu kiện",W25="Hàng không đạt CL"),"Kho đông mát",IF(W25="Chưa xác định","Chưa xác định",IF(N(P25)>0,"Chưa xác định","")))))))))))) | AA25: Hoàn Thành | AG25: {=XLOOKUP(F25,'CLV2'!A:A,'CLV2'!E:E)} -> 2.VEGETABLES | AH25: {=XLOOKUP(F25,'CLV2'!A:A,'CLV2'!F:F)} -> 3.PROCESSED VEGGIES | AI25: =if(H25="KG","KG","Pack") -> Pack | AJ25: =K25/I25 -> 1 | AK25: {=XLOOKUP(F25,'GIÁ'!A:A,'GIÁ'!D:D)} -> 14698.02 | AL25: =VALUE(SUBSTITUTE(AK25, ".", ","))*K25 -> 14698.02 | AM25: =IF($X:$X="Hao hụt", VALUE(SUBSTITUTE($AK25, ".", ","))*O25, 0) -> 0 | AN25: =IF($Y:$Y="Siêu thị", VALUE(SUBSTITUTE(AK25, ".", ","))*P25, 0) -> 14698.02 | AO25: =IF($Z:$Z="Kho đông mát", VALUE(SUBSTITUTE(AK25, ".", ","))*Q25, 0) -> 0 | AP25: =IF($Z:$Z="Chưa xác định", VALUE(SUBSTITUTE(AK25, ".", ","))*Q25, 0) -> 0
A26: 46231 | B26: 0.53263889 | C26: KFM_BDU_DAN - S01.11 Block A1 Charm Sapphire | D26: {=XLOOKUP(C26,'DS ST'!A:A,'DS ST'!B:B)} -> CHR | E26: {=XLOOKUP($F26,'GIÁ'!$A:$A,'GIÁ'!$E:$E)} -> MÁT | F26: 8935019503216 | G26: LEGOURMET - XÚC XÍCH VƯỜN BIA 10CM, 200G | H26: GÓI | I26: 2 | J26: 0 | K26: =I26-J26 -> 2 | L26: PT1580407 | M26: TRBCHR225 | N26: TO224304 | P26: 2 | Q26: =I26-J26-O26-P26 -> 0 | R26: PT1582103 | V26: Thiếu Item trong kiện | W26: DC thao tác sai | X26: =IF(VALUE(O26)<=0,"",IF(TRIM(W26)="Hao hụt","Hao hụt","Hao hụt")) | Y26: =IF(AND(N(P26)>0,OR(W26="DC giao bù",W26="VT giao sai điểm",W26="ST nhập thiếu",W26="DC pick sai",W26="ST kiểm sai QT",W26="ST thông tin sai/không phản hồi",W26="DC thao tác sai")),"Siêu thị","") -> Siêu thị | Z26: =IF(N(Q26)<=0,"",IF(ISNUMBER(SEARCH("Thiếu kiện",V26)),"Kho đông mát",IF(AND(N(Q26)>0,N(P26)>0,OR(ISNUMBER(SEARCH("Hình KDB",U26)),ISNUMBER(SEARCH("Hình tele",U26)),ISNUMBER(SEARCH("sai code",U26)),ISNUMBER(SEARCH("ST nhận",U26)))),"Kho đông mát",IF(AND(W26="DC giao thiếu",OR(ISNUMBER(SEARCH("Hình KDB",U26)),ISNUMBER(SEARCH("Hình tele",U26)),ISNUMBER(SEARCH("sai code",U26)))),"Kho đông mát",IF(W26="DC giao thiếu","Chưa xác định",IF(AND(W26="DC pick sai",OR(ISNUMBER(SEARCH("Hình KDB",U26)),ISNUMBER(SEARCH("Hình tele",U26)),ISNUMBER(SEARCH("sai code",U26)),ISNUMBER(SEARCH("ST nhận",U26)))),"Kho đông mát",IF(W26="DC pick sai","Chưa xác định",IF(AND(W26="Hao hụt",N(O26)>0,OR(ISNUMBER(SEARCH("Hình KDB",U26)),ISNUMBER(SEARCH("Hình tele",U26)),ISNUMBER(SEARCH("sai code",U26)),ISNUMBER(SEARCH("ST nhận",U26)))),"Kho đông mát",IF(W26="Hao hụt","Chưa xác định",IF(OR(W26="VT giao sai điểm",W26="Không đạt nhiệt độ",W26="TX giao thiếu kiện",W26="Hàng không đạt CL"),"Kho đông mát",IF(W26="Chưa xác định","Chưa xác định",IF(N(P26)>0,"Chưa xác định","")))))))))))) | AA26: Hoàn Thành | AG26: {=XLOOKUP(F26,'CLV2'!A:A,'CLV2'!E:E)} -> 2.CHILLED FOODS | AH26: {=XLOOKUP(F26,'CLV2'!A:A,'CLV2'!F:F)} -> 3.HAM AND SAUSAGES | AI26: =if(H26="KG","KG","Pack") -> Pack | AJ26: =K26/I26 -> 1 | AK26: {=XLOOKUP(F26,'GIÁ'!A:A,'GIÁ'!D:D)} -> 30395.96 | AL26: =VALUE(SUBSTITUTE(AK26, ".", ","))*K26 -> 60791.92 | AM26: =IF($X:$X="Hao hụt", VALUE(SUBSTITUTE($AK26, ".", ","))*O26, 0) -> 0 | AN26: =IF($Y:$Y="Siêu thị", VALUE(SUBSTITUTE(AK26, ".", ","))*P26, 0) -> 60791.92 | AO26: =IF($Z:$Z="Kho đông mát", VALUE(SUBSTITUTE(AK26, ".", ","))*Q26, 0) -> 0 | AP26: =IF($Z:$Z="Chưa xác định", VALUE(SUBSTITUTE(AK26, ".", ","))*Q26, 0) -> 0
A27: 46231 | B27: 0.53263889 | C27: KFM_BDU_DAN - S01.11 Block A1 Charm Sapphire | D27: {=XLOOKUP(C27,'DS ST'!A:A,'DS ST'!B:B)} -> CHR | E27: {=XLOOKUP($F27,'GIÁ'!$A:$A,'GIÁ'!$E:$E)} -> MÁT | F27: 8888319823099 | G27: HAND & HAND - NẤM HỖN HỢP HQ 300G | H27: HỘP | I27: 1 | J27: 0 | K27: =I27-J27 -> 1 | L27: PT1580407 | M27: TRBCHR225 | N27: TO224304 | P27: 1 | Q27: =I27-J27-O27-P27 -> 0 | R27: PT1582103 | V27: Thiếu Item trong kiện | W27: DC thao tác sai | X27: =IF(VALUE(O27)<=0,"",IF(TRIM(W27)="Hao hụt","Hao hụt","Hao hụt")) | Y27: =IF(AND(N(P27)>0,OR(W27="DC giao bù",W27="VT giao sai điểm",W27="ST nhập thiếu",W27="DC pick sai",W27="ST kiểm sai QT",W27="ST thông tin sai/không phản hồi",W27="DC thao tác sai")),"Siêu thị","") -> Siêu thị | Z27: =IF(N(Q27)<=0,"",IF(ISNUMBER(SEARCH("Thiếu kiện",V27)),"Kho đông mát",IF(AND(N(Q27)>0,N(P27)>0,OR(ISNUMBER(SEARCH("Hình KDB",U27)),ISNUMBER(SEARCH("Hình tele",U27)),ISNUMBER(SEARCH("sai code",U27)),ISNUMBER(SEARCH("ST nhận",U27)))),"Kho đông mát",IF(AND(W27="DC giao thiếu",OR(ISNUMBER(SEARCH("Hình KDB",U27)),ISNUMBER(SEARCH("Hình tele",U27)),ISNUMBER(SEARCH("sai code",U27)))),"Kho đông mát",IF(W27="DC giao thiếu","Chưa xác định",IF(AND(W27="DC pick sai",OR(ISNUMBER(SEARCH("Hình KDB",U27)),ISNUMBER(SEARCH("Hình tele",U27)),ISNUMBER(SEARCH("sai code",U27)),ISNUMBER(SEARCH("ST nhận",U27)))),"Kho đông mát",IF(W27="DC pick sai","Chưa xác định",IF(AND(W27="Hao hụt",N(O27)>0,OR(ISNUMBER(SEARCH("Hình KDB",U27)),ISNUMBER(SEARCH("Hình tele",U27)),ISNUMBER(SEARCH("sai code",U27)),ISNUMBER(SEARCH("ST nhận",U27)))),"Kho đông mát",IF(W27="Hao hụt","Chưa xác định",IF(OR(W27="VT giao sai điểm",W27="Không đạt nhiệt độ",W27="TX giao thiếu kiện",W27="Hàng không đạt CL"),"Kho đông mát",IF(W27="Chưa xác định","Chưa xác định",IF(N(P27)>0,"Chưa xác định","")))))))))))) | AA27: Hoàn Thành | AG27: {=XLOOKUP(F27,'CLV2'!A:A,'CLV2'!E:E)} -> 2.VEGETABLES | AH27: {=XLOOKUP(F27,'CLV2'!A:A,'CLV2'!F:F)} -> 3.MUSHROOM | AI27: =if(H27="KG","KG","Pack") -> Pack | AJ27: =K27/I27 -> 1 | AK27: {=XLOOKUP(F27,'GIÁ'!A:A,'GIÁ'!D:D)} -> 41000.00 | AL27: =VALUE(SUBSTITUTE(AK27, ".", ","))*K27 -> 41000 | AM27: =IF($X:$X="Hao hụt", VALUE(SUBSTITUTE($AK27, ".", ","))*O27, 0) -> 0 | AN27: =IF($Y:$Y="Siêu thị", VALUE(SUBSTITUTE(AK27, ".", ","))*P27, 0) -> 41000 | AO27: =IF($Z:$Z="Kho đông mát", VALUE(SUBSTITUTE(AK27, ".", ","))*Q27, 0) -> 0 | AP27: =IF($Z:$Z="Chưa xác định", VALUE(SUBSTITUTE(AK27, ".", ","))*Q27, 0) -> 0
A28: 46231 | B28: 0.53263889 | C28: KFM_BDU_DAN - S01.11 Block A1 Charm Sapphire | D28: {=XLOOKUP(C28,'DS ST'!A:A,'DS ST'!B:B)} -> CHR | E28: {=XLOOKUP($F28,'GIÁ'!$A:$A,'GIÁ'!$E:$E)} -> MÁT | F28: 8938502525351 | G28: THỌ PHÁT - BÁNH BAO THỊT HEO TRỨNG MUỐI 4X170G | H28: GÓI | I28: 3 | J28: 0 | K28: =I28-J28 -> 3 | L28: PT1580407 | M28: TRBCHR225 | N28: TO224304 | P28: 3 | Q28: =I28-J28-O28-P28 -> 0 | R28: PT1582233 | V28: Thiếu Item trong kiện | W28: DC thao tác sai | X28: =IF(VALUE(O28)<=0,"",IF(TRIM(W28)="Hao hụt","Hao hụt","Hao hụt")) | Y28: =IF(AND(N(P28)>0,OR(W28="DC giao bù",W28="VT giao sai điểm",W28="ST nhập thiếu",W28="DC pick sai",W28="ST kiểm sai QT",W28="ST thông tin sai/không phản hồi",W28="DC thao tác sai")),"Siêu thị","") -> Siêu thị | Z28: =IF(N(Q28)<=0,"",IF(ISNUMBER(SEARCH("Thiếu kiện",V28)),"Kho đông mát",IF(AND(N(Q28)>0,N(P28)>0,OR(ISNUMBER(SEARCH("Hình KDB",U28)),ISNUMBER(SEARCH("Hình tele",U28)),ISNUMBER(SEARCH("sai code",U28)),ISNUMBER(SEARCH("ST nhận",U28)))),"Kho đông mát",IF(AND(W28="DC giao thiếu",OR(ISNUMBER(SEARCH("Hình KDB",U28)),ISNUMBER(SEARCH("Hình tele",U28)),ISNUMBER(SEARCH("sai code",U28)))),"Kho đông mát",IF(W28="DC giao thiếu","Chưa xác định",IF(AND(W28="DC pick sai",OR(ISNUMBER(SEARCH("Hình KDB",U28)),ISNUMBER(SEARCH("Hình tele",U28)),ISNUMBER(SEARCH("sai code",U28)),ISNUMBER(SEARCH("ST nhận",U28)))),"Kho đông mát",IF(W28="DC pick sai","Chưa xác định",IF(AND(W28="Hao hụt",N(O28)>0,OR(ISNUMBER(SEARCH("Hình KDB",U28)),ISNUMBER(SEARCH("Hình tele",U28)),ISNUMBER(SEARCH("sai code",U28)),ISNUMBER(SEARCH("ST nhận",U28)))),"Kho đông mát",IF(W28="Hao hụt","Chưa xác định",IF(OR(W28="VT giao sai điểm",W28="Không đạt nhiệt độ",W28="TX giao thiếu kiện",W28="Hàng không đạt CL"),"Kho đông mát",IF(W28="Chưa xác định","Chưa xác định",IF(N(P28)>0,"Chưa xác định","")))))))))))) | AA28: Hoàn Thành | AG28: {=XLOOKUP(F28,'CLV2'!A:A,'CLV2'!E:E)} -> 2.DELICA | AH28: {=XLOOKUP(F28,'CLV2'!A:A,'CLV2'!F:F)} -> 3.COLD AND HOT DELICA | AI28: =if(H28="KG","KG","Pack") -> Pack | AJ28: =K28/I28 -> 1 | AK28: {=XLOOKUP(F28,'GIÁ'!A:A,'GIÁ'!D:D)} -> 77776.00 | AL28: =VALUE(SUBSTITUTE(AK28, ".", ","))*K28 -> 233328 | AM28: =IF($X:$X="Hao hụt", VALUE(SUBSTITUTE($AK28, ".", ","))*O28, 0) -> 0 | AN28: =IF($Y:$Y="Siêu thị", VALUE(SUBSTITUTE(AK28, ".", ","))*P28, 0) -> 233328 | AO28: =IF($Z:$Z="Kho đông mát", VALUE(SUBSTITUTE(AK28, ".", ","))*Q28, 0) -> 0 | AP28: =IF($Z:$Z="Chưa xác định", VALUE(SUBSTITUTE(AK28, ".", ","))*Q28, 0) -> 0
